Workbook

Sheet Employee Master
A1: Employee ID | B1: Employee Name | C1: Designation | D1: Joining Date | E1: Salary Type | F1: Salary Rate | G1: Contact | H1: Active | I1: OT Rate/Hour | J1: Exit Date | AA1: Payroll Calculation Rule
A2: EMP001 | B2: Ravi | C2: Machine Operator | D2: 46199 | E2: Monthly | F2: 40000 | G2: 7585825160 | H2: Yes | I2: 110
A3: EMP002 | B3: Raju | C3: Mixer Man | D3: 46199 | E3: Monthly | F3: 19000 | G3: 7501663268 | H3: Yes | I3: 53
A4: EMP003 | B4: Sattu | C4: Helper | D4: 46199 | E4: Monthly | F4: 16000 | G4: 9875641363 | H4: No | I4: 0 | J4: 46228
A5: EMP004 | B5: Shah Jahan | C5: Roll Man | D5: 46220 | E5: Monthly | F5: 17000 | G5: 6201471029 | H5: Yes | I5: 47
A6: EMP005 | B6: Shanti Devi | C6: Pipe Cutting | D6: 46238 | E6: Daily | F6: 400 | G6: 9001311441 | H6: Yes | I6: 0 | AA6: Present Days Only
A7: EMP006 | B7: Manisha | C7: Pipe Cutting | D7: 46239 | E7: Daily | F7: 400 | G7: 7483944538 | H7: No | I7: 0 | J7: 46290 | AA7: Present Days Only
A8: EMP007 | B8: Muttalib Ansari | C8: Helper | D8: 46283 | E8: Monthly | F8: 17000 | G8: 7870666535 | H8: Yes | I8: 47
A9: EMP008 | B9: Debashis Munda | C9: Mixer Man | D9: 46286 | E9: Monthly | F9: 19000 | G9: 7477651481 | H9: Yes | I9: 53
A10: EMP009 | B10: Moumita Sardar | C10: Pipe Cutting | D10: 46286 | E10: Monthly | F10: 11000 | G10: 7477651481 | H10: Yes | I10: 0
A11: EMP010 | B11: Rina Sardar | C11: Pipe Cutting | D11: 46288 | E11: Monthly | F11: 10000 | G11: 7585825160 | H11: No | I11: 0 | J11: 46293

Sheet Expense Register
A1: Date | B1: Category | C1: Description | D1: Amount | E1: Payment mode | F1: Applicable To | H1: PAYROLL AUTOMATION NOTE
A2: 46197 | B2: Travel Expense | C2: Train Ticket | D2: 4000 | E2: online | F2: Ravi and Raju | H2: For future automatic deductions, add one employee per row using Employee ID in a dedicated column.
A3: 46199 | B3: Vegetables | C3: Food | D3: 590 | E3: online | F3: Ravi, Raju and Sattu
A4: 46205 | B4: Vegetables | C4: Food | D4: 640 | E4: online | F4: Ravi, Raju and Sattu
A5: 46205 | B5: Grocery | C5: Kitchen | D5: 1280 | E5: online | F5: Ravi, Raju and Sattu
A6: 46210 | B6: Advance Salary | C6: Advance | D6: 500 | E6: online | F6: Ravi
A7: 46213 | B7: Advance Salary | C7: Advance | D7: 500 | E7: online | F7: Ravi
A8: 46216 | B8: Advance Salary | C8: Advance | D8: 2000 | E8: online | F8: Sattu
A9: 46216 | B9: Advance Salary | C9: Advance | D9: 3000 | E9: online | F9: Raju
A10: 46216 | B10: Advance Salary | C10: Advance | D10: 5000 | E10: online | F10: Ravi
A11: 46216 | B11: Advance Salary | C11: Advance | D11: 3000 | E11: online | F11: Raju
A12: 46231 | B12: Advance Salary | C12: Advance | D12: 500 | E12: online | F12: Ravi
A13: 46254 | B13: Advance Salary | C13: Advance | D13: 5000 | E13: online | F13: Ravi
A14: 46254 | B14: Advance Salary | C14: Advance | D14: 3000 | E14: online | F14: Raju
... A21: 46290 | B21: Advance Salary | C21: Advance | D21: 1500 | E21: online | F21: Mutallib Ansari

Sheet Attendance
A1: ATTENDANCE REGISTER | J1: Attendance Month | K1: 46296
A2: Enter only Date, Employee ID, Status and OT Hours. Payroll will read this register automatically. | J2: Use first day of month
A4: Date | B4: Employee ID | C4: Employee Name | D4: Designation | E4: Salary Type | F4: Status | G4: OT Hours | H4: Remarks | J4: MONTHLY ATTENDANCE SUMMARY
A5: 46296 | B5: {=IFERROR(INDEX('Employee Master'!$A$2:$A$500,1),"")} -> EMP001 | C5: {=IFERROR(_xlfn.XLOOKUP(B5,'Employee Master'!$A$2:$A$500,'Employee Master'!$B$2:$B$500,""),"")} -> Ravi | D5: {=IFERROR(_xlfn.XLOOKUP(B5,'Employee Master'!$A$2:$A$500,'Employee Master'!$C$2:$C$500,""),"")} -> Machine Operator | E5: {=IFERROR(_xlfn.XLOOKUP(B5,'Employee Master'!$A$2:$A$500,'Employee Master'!$E$2:$E$500,""),"")} -> Monthly | F5: P | J5: Employee ID | K5: Employee | L5: Salary Type | M5: Working Days | N5: Present | O5: Absent | P5: Half Day | Q5: Leave | R5: Weekly Off | S5: Worked Days | T5: OT Hours | U5: Joining Date
A6: 46296 | B6: {=IFERROR(INDEX('Employee Master'!$A$2:$A$500,2),"")} -> EMP002 | C6: {=IFERROR(_xlfn.XLOOKUP(B6,'Employee Master'!$A$2:$A$500,'Employee Master'!$B$2:$B$500,""),"")} -> Raju | D6: {=IFERROR(_xlfn.XLOOKUP(B6,'Employee Master'!$A$2:$A$500,'Employee Master'!$C$2:$C$500,""),"")} -> Mixer Man | E6: {=IFERROR(_xlfn.XLOOKUP(B6,'Employee Master'!$A$2:$A$500,'Employee Master'!$E$2:$E$500,""),"")} -> Monthly | F6: P | J6: {=IFERROR(INDEX('Employee Master'!$A$2:$A$500,1),"")} -> EMP001 | K6: {=IFERROR(_xlfn.XLOOKUP(J6,'Employee Master'!$A$2:$A$500,'Employee Master'!$B$2:$B$500,""),"")} -> Ravi | L6: {=IFERROR(_xlfn.XLOOKUP(J6,'Employee Master'!$A$2:$A$500,'Employee Master'!$E$2:$E$500,""),"")} -> Monthly | M6: =DAY(EOMONTH($K$1,0)) -> 31 | N6: =COUNTIFS($B$5:$B$504,J6,$F$5:$F$504,"P",$A$5:$A$504,">="&$K$1,$A$5:$A$504,"<="&EOMONTH($K$1,0)) -> 4 | O6: =COUNTIFS($B$5:$B$504,J6,$F$5:$F$504,"A",$A$5:$A$504,">="&$K$1,$A$5:$A$504,"<="&EOMONTH($K$1,0)) -> 0 | P6: =COUNTIFS($B$5:$B$504,J6,$F$5:$F$504,"HD",$A$5:$A$504,">="&$K$1,$A$5:$A$504,"<="&EOMONTH($K$1,0)) -> 0 | Q6: =COUNTIFS($B$5:$B$504,J6,$F$5:$F$504,"L",$A$5:$A$504,">="&$K$1,$A$5:$A$504,"<="&EOMONTH($K$1,0)) -> 1 | R6: =COUNTIFS($B$5:$B$504,J6,$F$5:$F$504,"WO",$A$5:$A$504,">="&$K$1,$A$5:$A$504,"<="&EOMONTH($K$1,0)) -> 1 | S6: =N6+P6*0.5 -> 4 | T6: =SUMIFS($G$5:$G$504,$B$5:$B$504,J6,$A$5:$A$504,">="&$K$1,$A$5:$A$504,"<="&EOMONTH($K$1,0)) -> 0 | U6: {=IFERROR(_xlfn.XLOOKUP(J6,'Employee Master'!$A$2:$A$500,'Employee Master'!$D$2:$D$500,""),"")} -> 46199
A7: 46296 | B7: {=IFERROR(INDEX('Employee Master'!$A$2:$A$500,4),"")} -> EMP004 | C7: {=IFERROR(_xlfn.XLOOKUP(B7,'Employee Master'!$A$2:$A$500,'Employee Master'!$B$2:$B$500,""),"")} -> Shah Jahan | D7: {=IFERROR(_xlfn.XLOOKUP(B7,'Employee Master'!$A$2:$A$500,'Employee Master'!$C$2:$C$500,""),"")} -> Roll Man | E7: {=IFERROR(_xlfn.XLOOKUP(B7,'Employee Master'!$A$2:$A$500,'Employee Master'!$E$2:$E$500,""),"")} -> Monthly | F7: P | J7: {=IFERROR(INDEX('Employee Master'!$A$2:$A$500,2),"")} -> EMP002 | K7: {=IFERROR(_xlfn.XLOOKUP(J7,'Employee Master'!$A$2:$A$500,'Employee Master'!$B$2:$B$500,""),"")} -> Raju | L7: {=IFERROR(_xlfn.XLOOKUP(J7,'Employee Master'!$A$2:$A$500,'Employee Master'!$E$2:$E$500,""),"")} -> Monthly | M7: =DAY(EOMONTH($K$1,0)) -> 31 | N7: =COUNTIFS($B$5:$B$504,J7,$F$5:$F$504,"P",$A$5:$A$504,">="&$K$1,$A$5:$A$504,"<="&EOMONTH($K$1,0)) -> 4 | O7: =COUNTIFS($B$5:$B$504,J7,$F$5:$F$504,"A",$A$5:$A$504,">="&$K$1,$A$5:$A$504,"<="&EOMONTH($K$1,0)) -> 0 | P7: =COUNTIFS($B$5:$B$504,J7,$F$5:$F$504,"HD",$A$5:$A$504,">="&$K$1,$A$5:$A$504,"<="&EOMONTH($K$1,0)) -> 0 | Q7: =COUNTIFS($B$5:$B$504,J7,$F$5:$F$504,"L",$A$5:$A$504,">="&$K$1,$A$5:$A$504,"<="&EOMONTH($K$1,0)) -> 1 | R7: =COUNTIFS($B$5:$B$504,J7,$F$5:$F$504,"WO",$A$5:$A$504,">="&$K$1,$A$5:$A$504,"<="&EOMONTH($K$1,0)) -> 1 | S7: =N7+P7*0.5 -> 4 | T7: =SUMIFS($G$5:$G$504,$B$5:$B$504,J7,$A$5:$A$504,">="&$K$1,$A$5:$A$504,"<="&EOMONTH($K$1,0)) -> 0 | U7: {=IFERROR(_xlfn.XLOOKUP(J7,'Employee Master'!$A$2:$A$500,'Employee Master'!$D$2:$D$500,""),"")} -> 46199
A8: 46296 | B8: {=IFERROR(INDEX('Employee Master'!$A$2:$A$500,5),"")} -> EMP005 | C8: {=IFERROR(_xlfn.XLOOKUP(B8,'Employee Master'!$A$2:$A$500,'Employee Master'!$B$2:$B$500,""),"")} -> Shanti Devi | D8: {=IFERROR(_xlfn.XLOOKUP(B8,'Employee Master'!$A$2:$A$500,'Employee Master'!$C$2:$C$500,""),"")} -> Pipe Cutting | E8: {=IFERROR(_xlfn.XLOOKUP(B8,'Employee Master'!$A$2:$A$500,'Employee Master'!$E$2:$E$500,""),"")} -> Daily | F8: P | J8: {=IFERROR(INDEX('Employee Master'!$A$2:$A$500,3),"")} -> EMP003 | K8: {=IFERROR(_xlfn.XLOOKUP(J8,'Employee Master'!$A$2:$A$500,'Employee Master'!$B$2:$B$500,""),"")} -> Sattu | L8: {=IFERROR(_xlfn.XLOOKUP(J8,'Employee Master'!$A$2:$A$500,'Employee Master'!$E$2:$E$500,""),"")} -> Monthly | M8: =DAY(EOMONTH($K$1,0)) -> 31 | N8: =COUNTIFS($B$5:$B$504,J8,$F$5:$F$504,"P",$A$5:$A$504,">="&$K$1,$A$5:$A$504,"<="&EOMONTH($K$1,0)) -> 0 | O8: =COUNTIFS($B$5:$B$504,J8,$F$5:$F$504,"A",$A$5:$A$504,">="&$K$1,$A$5:$A$504,"<="&EOMONTH($K$1,0)) -> 0 | P8: =COUNTIFS($B$5:$B$504,J8,$F$5:$F$504,"HD",$A$5:$A$504,">="&$K$1,$A$5:$A$504,"<="&EOMONTH($K$1,0)) -> 0 | Q8: =COUNTIFS($B$5:$B$504,J8,$F$5:$F$504,"L",$A$5:$A$504,">="&$K$1,$A$5:$A$504,"<="&EOMONTH($K$1,0)) -> 0 | R8: =COUNTIFS($B$5:$B$504,J8,$F$5:$F$504,"WO",$A$5:$A$504,">="&$K$1,$A$5:$A$504,"<="&EOMONTH($K$1,0)) -> 0 | S8: =N8+P8*0.5 -> 0 | T8: =SUMIFS($G$5:$G$504,$B$5:$B$504,J8,$A$5:$A$504,">="&$K$1,$A$5:$A$504,"<="&EOMONTH($K$1,0)) -> 0 | U8: {=IFERROR(_xlfn.XLOOKUP(J8,'Employee Master'!$A$2:$A$500,'Employee Master'!$D$2:$D$500,""),"")} -> 46199
A9: 46296 | B9: {=IFERROR(INDEX('Employee Master'!$A$2:$A$500,7),"")} -> EMP007 | C9: {=IFERROR(_xlfn.XLOOKUP(B9,'Employee Master'!$A$2:$A$500,'Employee Master'!$B$2:$B$500,""),"")} -> Muttalib Ansari | D9: {=IFERROR(_xlfn.XLOOKUP(B9,'Employee Master'!$A$2:$A$500,'Employee Master'!$C$2:$C$500,""),"")} -> Helper | E9: {=IFERROR(_xlfn.XLOOKUP(B9,'Employee Master'!$A$2:$A$500,'Employee Master'!$E$2:$E$500,""),"")} -> Monthly | F9: P | J9: {=IFERROR(INDEX('Employee Master'!$A$2:$A$500,4),"")} -> EMP004 | K9: {=IFERROR(_xlfn.XLOOKUP(J9,'Employee Master'!$A$2:$A$500,'Employee Master'!$B$2:$B$500,""),"")} -> Shah Jahan | L9: {=IFERROR(_xlfn.XLOOKUP(J9,'Employee Master'!$A$2:$A$500,'Employee Master'!$E$2:$E$500,""),"")} -> Monthly | M9: =DAY(EOMONTH($K$1,0)) -> 31 | N9: =COUNTIFS($B$5:$B$504,J9,$F$5:$F$504,"P",$A$5:$A$504,">="&$K$1,$A$5:$A$504,"<="&EOMONTH($K$1,0)) -> 4 | O9: =COUNTIFS($B$5:$B$504,J9,$F$5:$F$504,"A",$A$5:$A$504,">="&$K$1,$A$5:$A$504,"<="&EOMONTH($K$1,0)) -> 0 | P9: =COUNTIFS($B$5:$B$504,J9,$F$5:$F$504,"HD",$A$5:$A$504,">="&$K$1,$A$5:$A$504,"<="&EOMONTH($K$1,0)) -> 0 | Q9: =COUNTIFS($B$5:$B$504,J9,$F$5:$F$504,"L",$A$5:$A$504,">="&$K$1,$A$5:$A$504,"<="&EOMONTH($K$1,0)) -> 1 | R9: =COUNTIFS($B$5:$B$504,J9,$F$5:$F$504,"WO",$A$5:$A$504,">="&$K$1,$A$5:$A$504,"<="&EOMONTH($K$1,0)) -> 1 | S9: =N9+P9*0.5 -> 4 | T9: =SUMIFS($G$5:$G$504,$B$5:$B$504,J9,$A$5:$A$504,">="&$K$1,$A$5:$A$504,"<="&EOMONTH($K$1,0)) -> 0 | U9: {=IFERROR(_xlfn.XLOOKUP(J9,'Employee Master'!$A$2:$A$500,'Employee Master'!$D$2:$D$500,""),"")} -> 46220
A10: 46296 | B10: {=IFERROR(INDEX('Employee Master'!$A$2:$A$500,8),"")} -> EMP008 | C10: {=IFERROR(_xlfn.XLOOKUP(B10,'Employee Master'!$A$2:$A$500,'Employee Master'!$B$2:$B$500,""),"")} -> Debashis Munda | D10: {=IFERROR(_xlfn.XLOOKUP(B10,'Employee Master'!$A$2:$A$500,'Employee Master'!$C$2:$C$500,""),"")} -> Mixer Man | E10: {=IFERROR(_xlfn.XLOOKUP(B10,'Employee Master'!$A$2:$A$500,'Employee Master'!$E$2:$E$500,""),"")} -> Monthly | F10: P | J10: {=IFERROR(INDEX('Employee Master'!$A$2:$A$500,5),"")} -> EMP005 | K10: {=IFERROR(_xlfn.XLOOKUP(J10,'Employee Master'!$A$2:$A$500,'Employee Master'!$B$2:$B$500,""),"")} -> Shanti Devi | L10: {=IFERROR(_xlfn.XLOOKUP(J10,'Employee Master'!$A$2:$A$500,'Employee Master'!$E$2:$E$500,""),"")} -> Daily | M10: =DAY(EOMONTH($K$1,0)) -> 31 | N10: =COUNTIFS($B$5:$B$504,J10,$F$5:$F$504,"P",$A$5:$A$504,">="&$K$1,$A$5:$A$504,"<="&EOMONTH($K$1,0)) -> 3 | O10: =COUNTIFS($B$5:$B$504,J10,$F$5:$F$504,"A",$A$5:$A$504,">="&$K$1,$A$5:$A$504,"<="&EOMONTH($K$1,0)) -> 1 | P10: =COUNTIFS($B$5:$B$504,J10,$F$5:$F$504,"HD",$A$5:$A$504,">="&$K$1,$A$5:$A$504,"<="&EOMONTH($K$1,0)) -> 0 | Q10: =COUNTIFS($B$5:$B$504,J10,$F$5:$F$504,"L",$A$5:$A$504,">="&$K$1,$A$5:$A$504,"<="&EOMONTH($K$1,0)) -> 1 | R10: =COUNTIFS($B$5:$B$504,J10,$F$5:$F$504,"WO",$A$5:$A$504,">="&$K$1,$A$5:$A$504,"<="&EOMONTH($K$1,0)) -> 1 | S10: =N10+P10*0.5 -> 3 | T10: =SUMIFS($G$5:$G$504,$B$5:$B$504,J10,$A$5:$A$504,">="&$K$1,$A$5:$A$504,"<="&EOMONTH($K$1,0)) -> 0 | U10: {=IFERROR(_xlfn.XLOOKUP(J10,'Employee Master'!$A$2:$A$500,'Employee Master'!$D$2:$D$500,""),"")} -> 46238
A11: 46296 | B11: {=IFERROR(INDEX('Employee Master'!$A$2:$A$500,9),"")} -> EMP009 | C11: {=IFERROR(_xlfn.XLOOKUP(B11,'Employee Master'!$A$2:$A$500,'Employee Master'!$B$2:$B$500,""),"")} -> Moumita Sardar | D11: {=IFERROR(_xlfn.XLOOKUP(B11,'Employee Master'!$A$2:$A$500,'Employee Master'!$C$2:$C$500,""),"")} -> Pipe Cutting | E11: {=IFERROR(_xlfn.XLOOKUP(B11,'Employee Master'!$A$2:$A$500,'Employee Master'!$E$2:$E$500,""),"")} -> Monthly | F11: P | J11: {=IFERROR(INDEX('Employee Master'!$A$2:$A$500,6),"")} -> EMP006 | K11: {=IFERROR(_xlfn.XLOOKUP(J11,'Employee Master'!$A$2:$A$500,'Employee Master'!$B$2:$B$500,""),"")} -> Manisha | L11: {=IFERROR(_xlfn.XLOOKUP(J11,'Employee Master'!$A$2:$A$500,'Employee Master'!$E$2:$E$500,""),"")} -> Daily | M11: =DAY(EOMONTH($K$1,0)) -> 31 | N11: =COUNTIFS($B$5:$B$504,J11,$F$5:$F$504,"P",$A$5:$A$504,">="&$K$1,$A$5:$A$504,"<="&EOMONTH($K$1,0)) -> 0 | O11: =COUNTIFS($B$5:$B$504,J11,$F$5:$F$504,"A",$A$5:$A$504,">="&$K$1,$A$5:$A$504,"<="&EOMONTH($K$1,0)) -> 0 | P11: =COUNTIFS($B$5:$B$504,J11,$F$5:$F$504,"HD",$A$5:$A$504,">="&$K$1,$A$5:$A$504,"<="&EOMONTH($K$1,0)) -> 0 | Q11: =COUNTIFS($B$5:$B$504,J11,$F$5:$F$504,"L",$A$5:$A$504,">="&$K$1,$A$5:$A$504,"<="&EOMONTH($K$1,0)) -> 0 | R11: =COUNTIFS($B$5:$B$504,J11,$F$5:$F$504,"WO",$A$5:$A$504,">="&$K$1,$A$5:$A$504,"<="&EOMONTH($K$1,0)) -> 0 | S11: =N11+P11*0.5 -> 0 | T11: =SUMIFS($G$5:$G$504,$B$5:$B$504,J11,$A$5:$A$504,">="&$K$1,$A$5:$A$504,"<="&EOMONTH($K$1,0)) -> 0 | U11: {=IFERROR(_xlfn.XLOOKUP(J11,'Employee Master'!$A$2:$A$500,'Employee Master'!$D$2:$D$500,""),"")} -> 46239
A12: 46297 | B12: {=IFERROR(INDEX('Employee Master'!$A$2:$A$500,1),"")} -> EMP001 | C12: {=IFERROR(_xlfn.XLOOKUP(B12,'Employee Master'!$A$2:$A$500,'Employee Master'!$B$2:$B$500,""),"")} -> Ravi | D12: {=IFERROR(_xlfn.XLOOKUP(B12,'Employee Master'!$A$2:$A$500,'Employee Master'!$C$2:$C$500,""),"")} -> Machine Operator | E12: {=IFERROR(_xlfn.XLOOKUP(B12,'Employee Master'!$A$2:$A$500,'Employee Master'!$E$2:$E$500,""),"")} -> Monthly | F12: L | J12: {=IFERROR(INDEX('Employee Master'!$A$2:$A$500,7),"")} -> EMP007 | K12: {=IFERROR(_xlfn.XLOOKUP(J12,'Employee Master'!$A$2:$A$500,'Employee Master'!$B$2:$B$500,""),"")} -> Muttalib Ansari | L12: {=IFERROR(_xlfn.XLOOKUP(J12,'Employee Master'!$A$2:$A$500,'Employee Master'!$E$2:$E$500,""),"")} -> Monthly | M12: =DAY(EOMONTH($K$1,0)) -> 31 | N12: =COUNTIFS($B$5:$B$504,J12,$F$5:$F$504,"P",$A$5:$A$504,">="&$K$1,$A$5:$A$504,"<="&EOMONTH($K$1,0)) -> 4 | O12: =COUNTIFS($B$5:$B$504,J12,$F$5:$F$504,"A",$A$5:$A$504,">="&$K$1,$A$5:$A$504,"<="&EOMONTH($K$1,0)) -> 0 | P12: =COUNTIFS($B$5:$B$504,J12,$F$5:$F$504,"HD",$A$5:$A$504,">="&$K$1,$A$5:$A$504,"<="&EOMONTH($K$1,0)) -> 0 | Q12: =COUNTIFS($B$5:$B$504,J12,$F$5:$F$504,"L",$A$5:$A$504,">="&$K$1,$A$5:$A$504,"<="&EOMONTH($K$1,0)) -> 1 | R12: =COUNTIFS($B$5:$B$504,J12,$F$5:$F$504,"WO",$A$5:$A$504,">="&$K$1,$A$5:$A$504,"<="&EOMONTH($K$1,0)) -> 1 | S12: =N12+P12*0.5 -> 4 | T12: =SUMIFS($G$5:$G$504,$B$5:$B$504,J12,$A$5:$A$504,">="&$K$1,$A$5:$A$504,"<="&EOMONTH($K$1,0)) -> 0 | U12: {=IFERROR(_xlfn.XLOOKUP(J12,'Employee Master'!$A$2:$A$500,'Employee Master'!$D$2:$D$500,""),"")} -> 46283
A13: 46297 | B13: {=IFERROR(INDEX('Employee Master'!$A$2:$A$500,2),"")} -> EMP002 | C13: {=IFERROR(_xlfn.XLOOKUP(B13,'Employee Master'!$A$2:$A$500,'Employee Master'!$B$2:$B$500,""),"")} -> Raju | D13: {=IFERROR(_xlfn.XLOOKUP(B13,'Employee Master'!$A$2:$A$500,'Employee Master'!$C$2:$C$500,""),"")} -> Mixer Man | E13: {=IFERROR(_xlfn.XLOOKUP(B13,'Employee Master'!$A$2:$A$500,'Employee Master'!$E$2:$E$500,""),"")} -> Monthly | F13: L | J13: {=IFERROR(INDEX('Employee Master'!$A$2:$A$500,8),"")} -> EMP008 | K13: {=IFERROR(_xlfn.XLOOKUP(J13,'Employee Master'!$A$2:$A$500,'Employee Master'!$B$2:$B$500,""),"")} -> Debashis Munda | L13: {=IFERROR(_xlfn.XLOOKUP(J13,'Employee Master'!$A$2:$A$500,'Employee Master'!$E$2:$E$500,""),"")} -> Monthly | M13: =DAY(EOMONTH($K$1,0)) -> 31 | N13: =COUNTIFS($B$5:$B$504,J13,$F$5:$F$504,"P",$A$5:$A$504,">="&$K$1,$A$5:$A$504,"<="&EOMONTH($K$1,0)) -> 4 | O13: =COUNTIFS($B$5:$B$504,J13,$F$5:$F$504,"A",$A$5:$A$504,">="&$K$1,$A$5:$A$504,"<="&EOMONTH($K$1,0)) -> 0 | P13: =COUNTIFS($B$5:$B$504,J13,$F$5:$F$504,"HD",$A$5:$A$504,">="&$K$1,$A$5:$A$504,"<="&EOMONTH($K$1,0)) -> 0 | Q13: =COUNTIFS($B$5:$B$504,J13,$F$5:$F$504,"L",$A$5:$A$504,">="&$K$1,$A$5:$A$504,"<="&EOMONTH($K$1,0)) -> 1 | R13: =COUNTIFS($B$5:$B$504,J13,$F$5:$F$504,"WO",$A$5:$A$504,">="&$K$1,$A$5:$A$504,"<="&EOMONTH($K$1,0)) -> 1 | S13: =N13+P13*0.5 -> 4 | T13: =SUMIFS($G$5:$G$504,$B$5:$B$504,J13,$A$5:$A$504,">="&$K$1,$A$5:$A$504,"<="&EOMONTH($K$1,0)) -> 0 | U13: {=IFERROR(_xlfn.XLOOKUP(J13,'Employee Master'!$A$2:$A$500,'Employee Master'!$D$2:$D$500,""),"")} -> 46286
A14: 46297 | B14: {=IFERROR(INDEX('Employee Master'!$A$2:$A$500,4),"")} -> EMP004 | C14: {=IFERROR(_xlfn.XLOOKUP(B14,'Employee Master'!$A$2:$A$500,'Employee Master'!$B$2:$B$500,""),"")} -> Shah Jahan | D14: {=IFERROR(_xlfn.XLOOKUP(B14,'Employee Master'!$A$2:$A$500,'Employee Master'!$C$2:$C$500,""),"")} -> Roll Man | E14: {=IFERROR(_xlfn.XLOOKUP(B14,'Employee Master'!$A$2:$A$500,'Employee Master'!$E$2:$E$500,""),"")} -> Monthly | F14: L | J14: {=IFERROR(INDEX('Employee Master'!$A$2:$A$500,9),"")} -> EMP009 | K14: {=IFERROR(_xlfn.XLOOKUP(J14,'Employee Master'!$A$2:$A$500,'Employee Master'!$B$2:$B$500,""),"")} -> Moumita Sardar | L14: {=IFERROR(_xlfn.XLOOKUP(J14,'Employee Master'!$A$2:$A$500,'Employee Master'!$E$2:$E$500,""),"")} -> Monthly | M14: =DAY(EOMONTH($K$1,0)) -> 31 | N14: =COUNTIFS($B$5:$B$504,J14,$F$5:$F$504,"P",$A$5:$A$504,">="&$K$1,$A$5:$A$504,"<="&EOMONTH($K$1,0)) -> 4 | O14: =COUNTIFS($B$5:$B$504,J14,$F$5:$F$504,"A",$A$5:$A$504,">="&$K$1,$A$5:$A$504,"<="&EOMONTH($K$1,0)) -> 0 | P14: =COUNTIFS($B$5:$B$504,J14,$F$5:$F$504,"HD",$A$5:$A$504,">="&$K$1,$A$5:$A$504,"<="&EOMONTH($K$1,0)) -> 0 | Q14: =COUNTIFS($B$5:$B$504,J14,$F$5:$F$504,"L",$A$5:$A$504,">="&$K$1,$A$5:$A$504,"<="&EOMONTH($K$1,0)) -> 1 | R14: =COUNTIFS($B$5:$B$504,J14,$F$5:$F$504,"WO",$A$5:$A$504,">="&$K$1,$A$5:$A$504,"<="&EOMONTH($K$1,0)) -> 1 | S14: =N14+P14*0.5 -> 4 | T14: =SUMIFS($G$5:$G$504,$B$5:$B$504,J14,$A$5:$A$504,">="&$K$1,$A$5:$A$504,"<="&EOMONTH($K$1,0)) -> 0 | U14: {=IFERROR(_xlfn.XLOOKUP(J14,'Employee Master'!$A$2:$A$500,'Employee Master'!$D$2:$D$500,""),"")} -> 46286
A15: 46297 | B15: {=IFERROR(INDEX('Employee Master'!$A$2:$A$500,5),"")} -> EMP005 | C15: {=IFERROR(_xlfn.XLOOKUP(B15,'Employee Master'!$A$2:$A$500,'Employee Master'!$B$2:$B$500,""),"")} -> Shanti Devi | D15: {=IFERROR(_xlfn.XLOOKUP(B15,'Employee Master'!$A$2:$A$500,'Employee Master'!$C$2:$C$500,""),"")} -> Pipe Cutting | E15: {=IFERROR(_xlfn.XLOOKUP(B15,'Employee Master'!$A$2:$A$500,'Employee Master'!$E$2:$E$500,""),"")} -> Daily | F15: L | J15: {=IFERROR(INDEX('Employee Master'!$A$2:$A$500,10),"")} -> EMP010 | K15: {=IFERROR(_xlfn.XLOOKUP(J15,'Employee Master'!$A$2:$A$500,'Employee Master'!$B$2:$B$500,""),"")} -> Rina Sardar | L15: {=IFERROR(_xlfn.XLOOKUP(J15,'Employee Master'!$A$2:$A$500,'Employee Master'!$E$2:$E$500,""),"")} -> Monthly | M15: =DAY(EOMONTH($K$1,0)) -> 31 | N15: =COUNTIFS($B$5:$B$504,J15,$F$5:$F$504,"P",$A$5:$A$504,">="&$K$1,$A$5:$A$504,"<="&EOMONTH($K$1,0)) -> 0 | O15: =COUNTIFS($B$5:$B$504,J15,$F$5:$F$504,"A",$A$5:$A$504,">="&$K$1,$A$5:$A$504,"<="&EOMONTH($K$1,0)) -> 0 | P15: =COUNTIFS($B$5:$B$504,J15,$F$5:$F$504,"HD",$A$5:$A$504,">="&$K$1,$A$5:$A$504,"<="&EOMONTH($K$1,0)) -> 0 | Q15: =COUNTIFS($B$5:$B$504,J15,$F$5:$F$504,"L",$A$5:$A$504,">="&$K$1,$A$5:$A$504,"<="&EOMONTH($K$1,0)) -> 0 | R15: =COUNTIFS($B$5:$B$504,J15,$F$5:$F$504,"WO",$A$5:$A$504,">="&$K$1,$A$5:$A$504,"<="&EOMONTH($K$1,0)) -> 0 | S15: =N15+P15*0.5 -> 0 | T15: =SUMIFS($G$5:$G$504,$B$5:$B$504,J15,$A$5:$A$504,">="&$K$1,$A$5:$A$504,"<="&EOMONTH($K$1,0)) -> 0 | U15: {=IFERROR(_xlfn.XLOOKUP(J15,'Employee Master'!$A$2:$A$500,'Employee Master'!$D$2:$D$500,""),"")} -> 46288
A16: 46297 | B16: {=IFERROR(INDEX('Employee Master'!$A$2:$A$500,7),"")} -> EMP007 | C16: {=IFERROR(_xlfn.XLOOKUP(B16,'Employee Master'!$A$2:$A$500,'Employee Master'!$B$2:$B$500,""),"")} -> Muttalib Ansari | D16: {=IFERROR(_xlfn.XLOOKUP(B16,'Employee Master'!$A$2:$A$500,'Employee Master'!$C$2:$C$500,""),"")} -> Helper | E16: {=IFERROR(_xlfn.XLOOKUP(B16,'Employee Master'!$A$2:$A$500,'Employee Master'!$E$2:$E$500,""),"")} -> Monthly | F16: L
A17: 46297 | B17: {=IFERROR(INDEX('Employee Master'!$A$2:$A$500,8),"")} -> EMP008 | C17: {=IFERROR(_xlfn.XLOOKUP(B17,'Employee Master'!$A$2:$A$500,'Employee Master'!$B$2:$B$500,""),"")} -> Debashis Munda | D17: {=IFERROR(_xlfn.XLOOKUP(B17,'Employee Master'!$A$2:$A$500,'Employee Master'!$C$2:$C$500,""),"")} -> Mixer Man | E17: {=IFERROR(_xlfn.XLOOKUP(B17,'Employee Master'!$A$2:$A$500,'Employee Master'!$E$2:$E$500,""),"")} -> Monthly | F17: L | J17: Worked Days = Present + (Half Day × 0.5). Paid leave, weekly off and other salary rules will be handled in the Payroll sheet.
A18: 46297 | B18: {=IFERROR(INDEX('Employee Master'!$A$2:$A$500,9),"")} -> EMP009 | C18: {=IFERROR(_xlfn.XLOOKUP(B18,'Employee Master'!$A$2:$A$500,'Employee Master'!$B$2:$B$500,""),"")} -> Moumita Sardar | D18: {=IFERROR(_xlfn.XLOOKUP(B18,'Employee Master'!$A$2:$A$500,'Employee Master'!$C$2:$C$500,""),"")} -> Pipe Cutting | E18: {=IFERROR(_xlfn.XLOOKUP(B18,'Employee Master'!$A$2:$A$500,'Employee Master'!$E$2:$E$500,""),"")} -> Monthly | F18: L
A19: 46298 | B19: {=IFERROR(INDEX('Employee Master'!$A$2:$A$500,1),"")} -> EMP001 | C19: {=IFERROR(_xlfn.XLOOKUP(B19,'Employee Master'!$A$2:$A$500,'Employee Master'!$B$2:$B$500,""),"")} -> Ravi | D19: {=IFERROR(_xlfn.XLOOKUP(B19,'Employee Master'!$A$2:$A$500,'Employee Master'!$C$2:$C$500,""),"")} -> Machine Operator | E19: {=IFERROR(_xlfn.XLOOKUP(B19,'Employee Master'!$A$2:$A$500,'Employee Master'!$E$2:$E$500,""),"")} -> Monthly | F19: P
A20: 46298 | B20: {=IFERROR(INDEX('Employee Master'!$A$2:$A$500,2),"")} -> EMP002 | C20: {=IFERROR(_xlfn.XLOOKUP(B20,'Employee Master'!$A$2:$A$500,'Employee Master'!$B$2:$B$500,""),"")} -> Raju | D20: {=IFERROR(_xlfn.XLOOKUP(B20,'Employee Master'!$A$2:$A$500,'Employee Master'!$C$2:$C$500,""),"")} -> Mixer Man | E20: {=IFERROR(_xlfn.XLOOKUP(B20,'Employee Master'!$A$2:$A$500,'Employee Master'!$E$2:$E$500,""),"")} -> Monthly | F20: P
A21: 46298 | B21: {=IFERROR(INDEX('Employee Master'!$A$2:$A$500,4),"")} -> EMP004 | C21: {=IFERROR(_xlfn.XLOOKUP(B21,'Employee Master'!$A$2:$A$500,'Employee Master'!$B$2:$B$500,""),"")} -> Shah Jahan | D21: {=IFERROR(_xlfn.XLOOKUP(B21,'Employee Master'!$A$2:$A$500,'Employee Master'!$C$2:$C$500,""),"")} -> Roll Man | E21: {=IFERROR(_xlfn.XLOOKUP(B21,'Employee Master'!$A$2:$A$500,'Employee Master'!$E$2:$E$500,""),"")} -> Monthly | F21: P
A22: 46298 | B22: {=IFERROR(INDEX('Employee Master'!$A$2:$A$500,5),"")} -> EMP005 | C22: {=IFERROR(_xlfn.XLOOKUP(B22,'Employee Master'!$A$2:$A$500,'Employee Master'!$B$2:$B$500,""),"")} -> Shanti Devi | D22: {=IFERROR(_xlfn.XLOOKUP(B22,'Employee Master'!$A$2:$A$500,'Employee Master'!$C$2:$C$500,""),"")} -> Pipe Cutting | E22: {=IFERROR(_xlfn.XLOOKUP(B22,'Employee Master'!$A$2:$A$500,'Employee Master'!$E$2:$E$500,""),"")} -> Daily | F22: A
A23: 46298 | B23: {=IFERROR(INDEX('Employee Master'!$A$2:$A$500,7),"")} -> EMP007 | C23: {=IFERROR(_xlfn.XLOOKUP(B23,'Employee Master'!$A$2:$A$500,'Employee Master'!$B$2:$B$500,""),"")} -> Muttalib Ansari | D23: {=IFERROR(_xlfn.XLOOKUP(B23,'Employee Master'!$A$2:$A$500,'Employee Master'!$C$2:$C$500,""),"")} -> Helper | E23: {=IFERROR(_xlfn.XLOOKUP(B23,'Employee Master'!$A$2:$A$500,'Employee Master'!$E$2:$E$500,""),"")} -> Monthly | F23: P
A24: 46298 | B24: {=IFERROR(INDEX('Employee Master'!$A$2:$A$500,8),"")} -> EMP008 | C24: {=IFERROR(_xlfn.XLOOKUP(B24,'Employee Master'!$A$2:$A$500,'Employee Master'!$B$2:$B$500,""),"")} -> Debashis Munda | D24: {=IFERROR(_xlfn.XLOOKUP(B24,'Employee Master'!$A$2:$A$500,'Employee Master'!$C$2:$C$500,""),"")} -> Mixer Man | E24: {=IFERROR(_xlfn.XLOOKUP(B24,'Employee Master'!$A$2:$A$500,'Employee Master'!$E$2:$E$500,""),"")} -> Monthly | F24: P
A25: 46298 | B25: {=IFERROR(INDEX('Employee Master'!$A$2:$A$500,9),"")} -> EMP009 | C25: {=IFERROR(_xlfn.XLOOKUP(B25,'Employee Master'!$A$2:$A$500,'Employee Master'!$B$2:$B$500,""),"")} -> Moumita Sardar | D25: {=IFERROR(_xlfn.XLOOKUP(B25,'Employee Master'!$A$2:$A$500,'Employee Master'!$C$2:$C$500,""),"")} -> Pipe Cutting | E25: {=IFERROR(_xlfn.XLOOKUP(B25,'Employee Master'!$A$2:$A$500,'Employee Master'!$E$2:$E$500,""),"")} -> Monthly | F25: P
A26: 46299 | B26: {=IFERROR(INDEX('Employee Master'!$A$2:$A$500,1),"")} -> EMP001 | C26: {=IFERROR(_xlfn.XLOOKUP(B26,'Employee Master'!$A$2:$A$500,'Employee Master'!$B$2:$B$500,""),"")} -> Ravi | D26: {=IFERROR(_xlfn.XLOOKUP(B26,'Employee Master'!$A$2:$A$500,'Employee Master'!$C$2:$C$500,""),"")} -> Machine Operator | E26: {=IFERROR(_xlfn.XLOOKUP(B26,'Employee Master'!$A$2:$A$500,'Employee Master'!$E$2:$E$500,""),"")} -> Monthly | F26: WO
A27: 46299 | B27: {=IFERROR(INDEX('Employee Master'!$A$2:$A$500,2),"")} -> EMP002 | C27: {=IFERROR(_xlfn.XLOOKUP(B27,'Employee Master'!$A$2:$A$500,'Employee Master'!$B$2:$B$500,""),"")} -> Raju | D27: {=IFERROR(_xlfn.XLOOKUP(B27,'Employee Master'!$A$2:$A$500,'Employee Master'!$C$2:$C$500,""),"")} -> Mixer Man | E27: {=IFERROR(_xlfn.XLOOKUP(B27,'Employee Master'!$A$2:$A$500,'Employee Master'!$E$2:$E$500,""),"")} -> Monthly | F27: WO
A28: 46299 | B28: {=IFERROR(INDEX('Employee Master'!$A$2:$A$500,4),"")} -> EMP004 | C28: {=IFERROR(_xlfn.XLOOKUP(B28,'Employee Master'!$A$2:$A$500,'Employee Master'!$B$2:$B$500,""),"")} -> Shah Jahan | D28: {=IFERROR(_xlfn.XLOOKUP(B28,'Employee Master'!$A$2:$A$500,'Employee Master'!$C$2:$C$500,""),"")} -> Roll Man | E28: {=IFERROR(_xlfn.XLOOKUP(B28,'Employee Master'!$A$2:$A$500,'Employee Master'!$E$2:$E$500,""),"")} -> Monthly | F28: WO
A29: 46299 | B29: {=IFERROR(INDEX('Employee Master'!$A$2:$A$500,5),"")} -> EMP005 | C29: {=IFERROR(_xlfn.XLOOKUP(B29,'Employee Master'!$A$2:$A$500,'Employee Master'!$B$2:$B$500,""),"")} -> Shanti Devi | D29: {=IFERROR(_xlfn.XLOOKUP(B29,'Employee Master'!$A$2:$A$500,'Employee Master'!$C$2:$C$500,""),"")} -> Pipe Cutting | E29: {=IFERROR(_xlfn.XLOOKUP(B29,'Employee Master'!$A$2:$A$500,'Employee Master'!$E$2:$E$500,""),"")} -> Daily | F29: WO
A30: 46299 | B30: {=IFERROR(INDEX('Employee Master'!$A$2:$A$500,7),"")} -> EMP007 | C30: {=IFERROR(_xlfn.XLOOKUP(B30,'Employee Master'!$A$2:$A$500,'Employee Master'!$B$2:$B$500,""),"")} -> Muttalib Ansari | D30: {=IFERROR(_xlfn.XLOOKUP(B30,'Employee Master'!$A$2:$A$500,'Employee Master'!$C$2:$C$500,""),"")} -> Helper | E30: {=IFERROR(_xlfn.XLOOKUP(B30,'Employee Master'!$A$2:$A$500,'Employee Master'!$E$2:$E$500,""),"")} -> Monthly | F30: WO
A31: 46299 | B31: {=IFERROR(INDEX('Employee Master'!$A$2:$A$500,8),"")} -> EMP008 | C31: {=IFERROR(_xlfn.XLOOKUP(B31,'Employee Master'!$A$2:$A$500,'Employee Master'!$B$2:$B$500,""),"")} -> Debashis Munda | D31: {=IFERROR(_xlfn.XLOOKUP(B31,'Employee Master'!$A$2:$A$500,'Employee Master'!$C$2:$C$500,""),"")} -> Mixer Man | E31: {=IFERROR(_xlfn.XLOOKUP(B31,'Employee Master'!$A$2:$A$500,'Employee Master'!$E$2:$E$500,""),"")} -> Monthly | F31: WO
A32: 46299 | B32: {=IFERROR(INDEX('Employee Master'!$A$2:$A$500,9),"")} -> EMP009 | C32: {=IFERROR(_xlfn.XLOOKUP(B32,'Employee Master'!$A$2:$A$500,'Employee Master'!$B$2:$B$500,""),"")} -> Moumita Sardar | D32: {=IFERROR(_xlfn.XLOOKUP(B32,'Employee Master'!$A$2:$A$500,'Employee Master'!$C$2:$C$500,""),"")} -> Pipe Cutting | E32: {=IFERROR(_xlfn.XLOOKUP(B32,'Employee Master'!$A$2:$A$500,'Employee Master'!$E$2:$E$500,""),"")} -> Monthly | F32: WO
A33: 46300 | B33: {=IFERROR(INDEX('Employee Master'!$A$2:$A$500,1),"")} -> EMP001 | C33: {=IFERROR(_xlfn.XLOOKUP(B33,'Employee Master'!$A$2:$A$500,'Employee Master'!$B$2:$B$500,""),"")} -> Ravi | D33: {=IFERROR(_xlfn.XLOOKUP(B33,'Employee Master'!$A$2:$A$500,'Employee Master'!$C$2:$C$500,""),"")} -> Machine Operator | E33: {=IFERROR(_xlfn.XLOOKUP(B33,'Employee Master'!$A$2:$A$500,'Employee Master'!$E$2:$E$500,""),"")} -> Monthly | F33: P
A34: 46300 | B34: {=IFERROR(INDEX('Employee Master'!$A$2:$A$500,2),"")} -> EMP002 | C34: {=IFERROR(_xlfn.XLOOKUP(B34,'Employee Master'!$A$2:$A$500,'Employee Master'!$B$2:$B$500,""),"")} -> Raju | D34: {=IFERROR(_xlfn.XLOOKUP(B34,'Employee Master'!$A$2:$A$500,'Employee Master'!$C$2:$C$500,""),"")} -> Mixer Man | E34: {=IFERROR(_xlfn.XLOOKUP(B34,'Employee Master'!$A$2:$A$500,'Employee Master'!$E$2:$E$500,""),"")} -> Monthly | F34: P
A35: 46300 | B35: {=IFERROR(INDEX('Employee Master'!$A$2:$A$500,4),"")} -> EMP004 | C35: {=IFERROR(_xlfn.XLOOKUP(B35,'Employee Master'!$A$2:$A$500,'Employee Master'!$B$2:$B$500,""),"")} -> Shah Jahan | D35: {=IFERROR(_xlfn.XLOOKUP(B35,'Employee Master'!$A$2:$A$500,'Employee Master'!$C$2:$C$500,""),"")} -> Roll Man | E35: {=IFERROR(_xlfn.XLOOKUP(B35,'Employee Master'!$A$2:$A$500,'Employee Master'!$E$2:$E$500,""),"")} -> Monthly | F35: P
A36: 46300 | B36: {=IFERROR(INDEX('Employee Master'!$A$2:$A$500,5),"")} -> EMP005 | C36: {=IFERROR(_xlfn.XLOOKUP(B36,'Employee Master'!$A$2:$A$500,'Employee Master'!$B$2:$B$500,""),"")} -> Shanti Devi | D36: {=IFERROR(_xlfn.XLOOKUP(B36,'Employee Master'!$A$2:$A$500,'Employee Master'!$C$2:$C$500,""),"")} -> Pipe Cutting | E36: {=IFERROR(_xlfn.XLOOKUP(B36,'Employee Master'!$A$2:$A$500,'Employee Master'!$E$2:$E$500,""),"")} -> Daily | F36: P
A37: 46300 | B37: {=IFERROR(INDEX('Employee Master'!$A$2:$A$500,7),"")} -> EMP007 | C37: {=IFERROR(_xlfn.XLOOKUP(B37,'Employee Master'!$A$2:$A$500,'Employee Master'!$B$2:$B$500,""),"")} -> Muttalib Ansari | D37: {=IFERROR(_xlfn.XLOOKUP(B37,'Employee Master'!$A$2:$A$500,'Employee Master'!$C$2:$C$500,""),"")} -> Helper | E37: {=IFERROR(_xlfn.XLOOKUP(B37,'Employee Master'!$A$2:$A$500,'Employee Master'!$E$2:$E$500,""),"")} -> Monthly | F37: P
A38: 46300 | B38: {=IFERROR(INDEX('Employee Master'!$A$2:$A$500,8),"")} -> EMP008 | C38: {=IFERROR(_xlfn.XLOOKUP(B38,'Employee Master'!$A$2:$A$500,'Employee Master'!$B$2:$B$500,""),"")} -> Debashis Munda | D38: {=IFERROR(_xlfn.XLOOKUP(B38,'Employee Master'!$A$2:$A$500,'Employee Master'!$C$2:$C$500,""),"")} -> Mixer Man | E38: {=IFERROR(_xlfn.XLOOKUP(B38,'Employee Master'!$A$2:$A$500,'Employee Master'!$E$2:$E$500,""),"")} -> Monthly | F38: P
A39: 46300 | B39: {=IFERROR(INDEX('Employee Master'!$A$2:$A$500,9),"")} -> EMP009 | C39: {=IFERROR(_xlfn.XLOOKUP(B39,'Employee Master'!$A$2:$A$500,'Employee Master'!$B$2:$B$500,""),"")} -> Moumita Sardar | D39: {=IFERROR(_xlfn.XLOOKUP(B39,'Employee Master'!$A$2:$A$500,'Employee Master'!$C$2:$C$500,""),"")} -> Pipe Cutting | E39: {=IFERROR(_xlfn.XLOOKUP(B39,'Employee Master'!$A$2:$A$500,'Employee Master'!$E$2:$E$500,""),"")} -> Monthly | F39: P
A40: 46301 | B40: {=IFERROR(INDEX('Employee Master'!$A$2:$A$500,1),"")} -> EMP001 | C40: {=IFERROR(_xlfn.XLOOKUP(B40,'Employee Master'!$A$2:$A$500,'Employee Master'!$B$2:$B$500,""),"")} -> Ravi | D40: {=IFERROR(_xlfn.XLOOKUP(B40,'Employee Master'!$A$2:$A$500,'Employee Master'!$C$2:$C$500,""),"")} -> Machine Operator | E40: {=IFERROR(_xlfn.XLOOKUP(B40,'Employee Master'!$A$2:$A$500,'Employee Master'!$E$2:$E$500,""),"")} -> Monthly | F40: P
A41: 46301 | B41: {=IFERROR(INDEX('Employee Master'!$A$2:$A$500,2),"")} -> EMP002 | C41: {=IFERROR(_xlfn.XLOOKUP(B41,'Employee Master'!$A$2:$A$500,'Employee Master'!$B$2:$B$500,""),"")} -> Raju | D41: {=IFERROR(_xlfn.XLOOKUP(B41,'Employee Master'!$A$2:$A$500,'Employee Master'!$C$2:$C$500,""),"")} -> Mixer Man | E41: {=IFERROR(_xlfn.XLOOKUP(B41,'Employee Master'!$A$2:$A$500,'Employee Master'!$E$2:$E$500,""),"")} -> Monthly | F41: P
...

Sheet Payroll Settings
A1: PAYROLL SETTINGS
A2: Payroll Month | B2: 01-Oct-2026 | C2: First day of payroll month
A3: Salary Divisor | B3: Calendar Days | C3: Monthly salary divided by actual days in month
A4: Paid Leave? | B4: Yes | C4: Yes = leave counts as paid day
A5: Paid Weekly Off? | B5: Yes | C5: Yes = WO counts as paid day
A6: Half Day Factor | B6: 0.5 | C6: Half day salary factor
A7: OT Applicable? | B7: Yes | C7: Yes = OT hours × OT rate
A8: Payroll Start Date | B8: =B2 -> 01-Oct-2026 | C8: Calculated
A9: Payroll End Date | B9: =EOMONTH(B2,0) -> 46326 | C9: Calculated
A10: Days in Month | B10: =DAY(B8) -> 1 | C10: Calculated
A12: Daily Labour Rule | B12: EMP005 Shanti Devi and EMP006 Manisha: salary = Daily Rate × Present (P) Days only. Leave, Absent and Weekly Off are unpaid.

Sheet Payroll
A1: AUTOMATIC MONTHLY PAYROLL | AA1: Payroll Calculation Rule
A2: Payroll Month | B2: ='Payroll Settings'!B2 -> 01-Oct-2026 | D2: Period | E2: ='Payroll Settings'!B8 -> 01-Oct-2026 | F2: ='Payroll Settings'!B9 -> 46326
A4: Employee ID | B4: Employee Name | C4: Designation | D4: Salary Type | E4: Rate | F4: Working Days | G4: Present | H4: Absent | I4: Half Day | J4: Leave | K4: Weekly Off | L4: Paid Days | M4: OT Hours | N4: OT Rate | O4: OT Amount | P4: Basic/Gross Salary | Q4: Total Earnings | R4: Advance | S4: Travel | T4: Food/Grocery | U4: Other Deduction | V4: Total Deduction | W4: Net Salary | X4: Payment Status | AA4: Payroll Calculation Rule
A5: EMP001 | B5: =IFERROR(VLOOKUP($A5,'Employee Master'!$A:$I,2,FALSE),"") -> Ravi | C5: =IFERROR(VLOOKUP($A5,'Employee Master'!$A:$I,3,FALSE),"") -> Machine Operator | D5: =IFERROR(VLOOKUP($A5,'Employee Master'!$A:$I,5,FALSE),"") -> Monthly | E5: =IFERROR(VLOOKUP($A5,'Employee Master'!$A:$I,6,FALSE),0) -> 40000 | F5: =MAX(0,'Payroll Settings'!$B$9-MAX('Payroll Settings'!$B$8,IFERROR(VLOOKUP($A5,'Employee Master'!$A:$I,4,FALSE),'Payroll Settings'!$B$8))+1) -> 128 | G5: =COUNTIFS(Attendance!$B$5:$B$1000,$A5,Attendance!$F$5:$F$1000,"P",Attendance!$A$5:$A$1000,">="&'Payroll Settings'!$B$8,Attendance!$A$5:$A$1000,"<="&'Payroll Settings'!$B$9) -> 4 | H5: =COUNTIFS(Attendance!$B$5:$B$1000,$A5,Attendance!$F$5:$F$1000,"A",Attendance!$A$5:$A$1000,">="&'Payroll Settings'!$B$8,Attendance!$A$5:$A$1000,"<="&'Payroll Settings'!$B$9) -> 0 | I5: =COUNTIFS(Attendance!$B$5:$B$1000,$A5,Attendance!$F$5:$F$1000,"HD",Attendance!$A$5:$A$1000,">="&'Payroll Settings'!$B$8,Attendance!$A$5:$A$1000,"<="&'Payroll Settings'!$B$9) -> 0 | J5: =COUNTIFS(Attendance!$B$5:$B$1000,$A5,Attendance!$F$5:$F$1000,"L",Attendance!$A$5:$A$1000,">="&'Payroll Settings'!$B$8,Attendance!$A$5:$A$1000,"<="&'Payroll Settings'!$B$9) -> 1 | K5: =COUNTIFS(Attendance!$B$5:$B$1000,$A5,Attendance!$F$5:$F$1000,"WO",Attendance!$A$5:$A$1000,">="&'Payroll Settings'!$B$8,Attendance!$A$5:$A$1000,"<="&'Payroll Settings'!$B$9) -> 1 | L5: =IF(OR($A5="EMP005",$A5="EMP006"),G5,G5+I5*'Payroll Settings'!$B$6+IF('Payroll Settings'!$B$4="Yes",J5,0)+IF('Payroll Settings'!$B$5="Yes",K5,0)) -> 6 | M5: =SUMIFS(Attendance!$G$5:$G$1000,Attendance!$B$5:$B$1000,$A5,Attendance!$A$5:$A$1000,">="&'Payroll Settings'!$B$8,Attendance!$A$5:$A$1000,"<="&'Payroll Settings'!$B$9) -> 0 | N5: =IFERROR(VLOOKUP($A5,'Employee Master'!$A:$I,9,FALSE),0) -> 110 | O5: =IF('Payroll Settings'!$B$7="Yes",M5*N5,0) -> 0 | P5: =IF(OR($A5="EMP005",$A5="EMP006"),E5*G5,IF(D5="Monthly",E5/IF('Payroll Settings'!$B$3="30 Days",30,DAY('Payroll Settings'!$B$9))*L5,E5*L5)) -> 7741.9355 | Q5: =P5+O5 -> 7741.9355 | R5: =SUMIFS('Expense Register'!$D:$D,'Expense Register'!$B:$B,"Advance Salary",'Expense Register'!$A:$A,">="&'Payroll Settings'!$B$8,'Expense Register'!$A:$A,"<="&'Payroll Settings'!$B$9,'Expense Register'!$F:$F,"*"&B5&"*") -> 0 | S5: =SUMIFS('Expense Register'!$D:$D,'Expense Register'!$B:$B,"Travel Expense",'Expense Register'!$A:$A,">="&'Payroll Settings'!$B$8,'Expense Register'!$A:$A,"<="&'Payroll Settings'!$B$9,'Expense Register'!$F:$F,"*"&B5&"*") -> 0 | T5: =SUM(SUMIFS('Expense Register'!$D:$D,'Expense Register'!$B:$B,"Vegetables",'Expense Register'!$A:$A,">="&'Payroll Settings'!$B$8,'Expense Register'!$A:$A,"<="&'Payroll Settings'!$B$9,'Expense Register'!$F:$F,"*"&B5&"*"),SUMIFS('Expense Register'!$D:$D,'Expense Register'!$B:$B,"Grocery",'Expense Register'!$A:$A,">="&'Payroll Settings'!$B$8,'Expense Register'!$A:$A,"<="&'Payroll Settings'!$B$9,'Expense Register'!$F:$F,"*"&B5&"*")) -> 0 | U5: 0 | V5: =SUM(R5:U5) -> 0 | W5: =Q5-V5 -> 7741.9355 | X5: Pending
A6: EMP002 | B6: =IFERROR(VLOOKUP($A6,'Employee Master'!$A:$I,2,FALSE),"") -> Raju | C6: =IFERROR(VLOOKUP($A6,'Employee Master'!$A:$I,3,FALSE),"") -> Mixer Man | D6: =IFERROR(VLOOKUP($A6,'Employee Master'!$A:$I,5,FALSE),"") -> Monthly | E6: =IFERROR(VLOOKUP($A6,'Employee Master'!$A:$I,6,FALSE),0) -> 19000 | F6: =MAX(0,'Payroll Settings'!$B$9-MAX('Payroll Settings'!$B$8,IFERROR(VLOOKUP($A6,'Employee Master'!$A:$I,4,FALSE),'Payroll Settings'!$B$8))+1) -> 128 | G6: =COUNTIFS(Attendance!$B$5:$B$1000,$A6,Attendance!$F$5:$F$1000,"P",Attendance!$A$5:$A$1000,">="&'Payroll Settings'!$B$8,Attendance!$A$5:$A$1000,"<="&'Payroll Settings'!$B$9) -> 4 | H6: =COUNTIFS(Attendance!$B$5:$B$1000,$A6,Attendance!$F$5:$F$1000,"A",Attendance!$A$5:$A$1000,">="&'Payroll Settings'!$B$8,Attendance!$A$5:$A$1000,"<="&'Payroll Settings'!$B$9) -> 0 | I6: =COUNTIFS(Attendance!$B$5:$B$1000,$A6,Attendance!$F$5:$F$1000,"HD",Attendance!$A$5:$A$1000,">="&'Payroll Settings'!$B$8,Attendance!$A$5:$A$1000,"<="&'Payroll Settings'!$B$9) -> 0 | J6: =COUNTIFS(Attendance!$B$5:$B$1000,$A6,Attendance!$F$5:$F$1000,"L",Attendance!$A$5:$A$1000,">="&'Payroll Settings'!$B$8,Attendance!$A$5:$A$1000,"<="&'Payroll Settings'!$B$9) -> 1 | K6: =COUNTIFS(Attendance!$B$5:$B$1000,$A6,Attendance!$F$5:$F$1000,"WO",Attendance!$A$5:$A$1000,">="&'Payroll Settings'!$B$8,Attendance!$A$5:$A$1000,"<="&'Payroll Settings'!$B$9) -> 1 | L6: =IF(OR($A6="EMP005",$A6="EMP006"),G6,G6+I6*'Payroll Settings'!$B$6+IF('Payroll Settings'!$B$4="Yes",J6,0)+IF('Payroll Settings'!$B$5="Yes",K6,0)) -> 6 | M6: =SUMIFS(Attendance!$G$5:$G$1000,Attendance!$B$5:$B$1000,$A6,Attendance!$A$5:$A$1000,">="&'Payroll Settings'!$B$8,Attendance!$A$5:$A$1000,"<="&'Payroll Settings'!$B$9) -> 0 | N6: =IFERROR(VLOOKUP($A6,'Employee Master'!$A:$I,9,FALSE),0) -> 53 | O6: =IF('Payroll Settings'!$B$7="Yes",M6*N6,0) -> 0 | P6: =IF(OR($A6="EMP005",$A6="EMP006"),E6*G6,IF(D6="Monthly",E6/IF('Payroll Settings'!$B$3="30 Days",30,DAY('Payroll Settings'!$B$9))*L6,E6*L6)) -> 3677.4194 | Q6: =P6+O6 -> 3677.4194 | R6: =SUMIFS('Expense Register'!$D:$D,'Expense Register'!$B:$B,"Advance Salary",'Expense Register'!$A:$A,">="&'Payroll Settings'!$B$8,'Expense Register'!$A:$A,"<="&'Payroll Settings'!$B$9,'Expense Register'!$F:$F,"*"&B6&"*") -> 0 | S6: =SUMIFS('Expense Register'!$D:$D,'Expense Register'!$B:$B,"Travel Expense",'Expense Register'!$A:$A,">="&'Payroll Settings'!$B$8,'Expense Register'!$A:$A,"<="&'Payroll Settings'!$B$9,'Expense Register'!$F:$F,"*"&B6&"*") -> 0 | T6: =SUM(SUMIFS('Expense Register'!$D:$D,'Expense Register'!$B:$B,"Vegetables",'Expense Register'!$A:$A,">="&'Payroll Settings'!$B$8,'Expense Register'!$A:$A,"<="&'Payroll Settings'!$B$9,'Expense Register'!$F:$F,"*"&B6&"*"),SUMIFS('Expense Register'!$D:$D,'Expense Register'!$B:$B,"Grocery",'Expense Register'!$A:$A,">="&'Payroll Settings'!$B$8,'Expense Register'!$A:$A,"<="&'Payroll Settings'!$B$9,'Expense Register'!$F:$F,"*"&B6&"*")) -> 0 | U6: 0 | V6: =SUM(R6:U6) -> 0 | W6: =Q6-V6 -> 3677.4194 | X6: Pending
A7: EMP004 | B7: =IFERROR(VLOOKUP($A7,'Employee Master'!$A:$I,2,FALSE),"") -> Shah Jahan | C7: =IFERROR(VLOOKUP($A7,'Employee Master'!$A:$I,3,FALSE),"") -> Roll Man | D7: =IFERROR(VLOOKUP($A7,'Employee Master'!$A:$I,5,FALSE),"") -> Monthly | E7: =IFERROR(VLOOKUP($A7,'Employee Master'!$A:$I,6,FALSE),0) -> 17000 | F7: =MAX(0,'Payroll Settings'!$B$9-MAX('Payroll Settings'!$B$8,IFERROR(VLOOKUP($A7,'Employee Master'!$A:$I,4,FALSE),'Payroll Settings'!$B$8))+1) -> 107 | G7: =COUNTIFS(Attendance!$B$5:$B$1000,$A7,Attendance!$F$5:$F$1000,"P",Attendance!$A$5:$A$1000,">="&'Payroll Settings'!$B$8,Attendance!$A$5:$A$1000,"<="&'Payroll Settings'!$B$9) -> 4 | H7: =COUNTIFS(Attendance!$B$5:$B$1000,$A7,Attendance!$F$5:$F$1000,"A",Attendance!$A$5:$A$1000,">="&'Payroll Settings'!$B$8,Attendance!$A$5:$A$1000,"<="&'Payroll Settings'!$B$9) -> 0 | I7: =COUNTIFS(Attendance!$B$5:$B$1000,$A7,Attendance!$F$5:$F$1000,"HD",Attendance!$A$5:$A$1000,">="&'Payroll Settings'!$B$8,Attendance!$A$5:$A$1000,"<="&'Payroll Settings'!$B$9) -> 0 | J7: =COUNTIFS(Attendance!$B$5:$B$1000,$A7,Attendance!$F$5:$F$1000,"L",Attendance!$A$5:$A$1000,">="&'Payroll Settings'!$B$8,Attendance!$A$5:$A$1000,"<="&'Payroll Settings'!$B$9) -> 1 | K7: =COUNTIFS(Attendance!$B$5:$B$1000,$A7,Attendance!$F$5:$F$1000,"WO",Attendance!$A$5:$A$1000,">="&'Payroll Settings'!$B$8,Attendance!$A$5:$A$1000,"<="&'Payroll Settings'!$B$9) -> 1 | L7: =IF(OR($A7="EMP005",$A7="EMP006"),G7,G7+I7*'Payroll Settings'!$B$6+IF('Payroll Settings'!$B$4="Yes",J7,0)+IF('Payroll Settings'!$B$5="Yes",K7,0)) -> 6 | M7: =SUMIFS(Attendance!$G$5:$G$1000,Attendance!$B$5:$B$1000,$A7,Attendance!$A$5:$A$1000,">="&'Payroll Settings'!$B$8,Attendance!$A$5:$A$1000,"<="&'Payroll Settings'!$B$9) -> 0 | N7: =IFERROR(VLOOKUP($A7,'Employee Master'!$A:$I,9,FALSE),0) -> 47 | O7: =IF('Payroll Settings'!$B$7="Yes",M7*N7,0) -> 0 | P7: =IF(OR($A7="EMP005",$A7="EMP006"),E7*G7,IF(D7="Monthly",E7/IF('Payroll Settings'!$B$3="30 Days",30,DAY('Payroll Settings'!$B$9))*L7,E7*L7)) -> 3290.3226 | Q7: =P7+O7 -> 3290.3226 | R7: =SUMIFS('Expense Register'!$D:$D,'Expense Register'!$B:$B,"Advance Salary",'Expense Register'!$A:$A,">="&'Payroll Settings'!$B$8,'Expense Register'!$A:$A,"<="&'Payroll Settings'!$B$9,'Expense Register'!$F:$F,"*"&B7&"*") -> 0 | S7: =SUMIFS('Expense Register'!$D:$D,'Expense Register'!$B:$B,"Travel Expense",'Expense Register'!$A:$A,">="&'Payroll Settings'!$B$8,'Expense Register'!$A:$A,"<="&'Payroll Settings'!$B$9,'Expense Register'!$F:$F,"*"&B7&"*") -> 0 | T7: =SUM(SUMIFS('Expense Register'!$D:$D,'Expense Register'!$B:$B,"Vegetables",'Expense Register'!$A:$A,">="&'Payroll Settings'!$B$8,'Expense Register'!$A:$A,"<="&'Payroll Settings'!$B$9,'Expense Register'!$F:$F,"*"&B7&"*"),SUMIFS('Expense Register'!$D:$D,'Expense Register'!$B:$B,"Grocery",'Expense Register'!$A:$A,">="&'Payroll Settings'!$B$8,'Expense Register'!$A:$A,"<="&'Payroll Settings'!$B$9,'Expense Register'!$F:$F,"*"&B7&"*")) -> 0 | U7: 0 | V7: =SUM(R7:U7) -> 0 | W7: =Q7-V7 -> 3290.3226 | X7: Pending
A8: EMP005 | B8: =IFERROR(VLOOKUP($A8,'Employee Master'!$A:$I,2,FALSE),"") -> Shanti Devi | C8: =IFERROR(VLOOKUP($A8,'Employee Master'!$A:$I,3,FALSE),"") -> Pipe Cutting | D8: =IFERROR(VLOOKUP($A8,'Employee Master'!$A:$I,5,FALSE),"") -> Daily | E8: =IFERROR(VLOOKUP($A8,'Employee Master'!$A:$I,6,FALSE),0) -> 400 | F8: =MAX(0,'Payroll Settings'!$B$9-MAX('Payroll Settings'!$B$8,IFERROR(VLOOKUP($A8,'Employee Master'!$A:$I,4,FALSE),'Payroll Settings'!$B$8))+1) -> 89 | G8: =COUNTIFS(Attendance!$B$5:$B$1000,$A8,Attendance!$F$5:$F$1000,"P",Attendance!$A$5:$A$1000,">="&'Payroll Settings'!$B$8,Attendance!$A$5:$A$1000,"<="&'Payroll Settings'!$B$9) -> 3 | H8: =COUNTIFS(Attendance!$B$5:$B$1000,$A8,Attendance!$F$5:$F$1000,"A",Attendance!$A$5:$A$1000,">="&'Payroll Settings'!$B$8,Attendance!$A$5:$A$1000,"<="&'Payroll Settings'!$B$9) -> 1 | I8: =COUNTIFS(Attendance!$B$5:$B$1000,$A8,Attendance!$F$5:$F$1000,"HD",Attendance!$A$5:$A$1000,">="&'Payroll Settings'!$B$8,Attendance!$A$5:$A$1000,"<="&'Payroll Settings'!$B$9) -> 0 | J8: =COUNTIFS(Attendance!$B$5:$B$1000,$A8,Attendance!$F$5:$F$1000,"L",Attendance!$A$5:$A$1000,">="&'Payroll Settings'!$B$8,Attendance!$A$5:$A$1000,"<="&'Payroll Settings'!$B$9) -> 1 | K8: =COUNTIFS(Attendance!$B$5:$B$1000,$A8,Attendance!$F$5:$F$1000,"WO",Attendance!$A$5:$A$1000,">="&'Payroll Settings'!$B$8,Attendance!$A$5:$A$1000,"<="&'Payroll Settings'!$B$9) -> 1 | L8: =IF(OR($A8="EMP005",$A8="EMP006"),G8,G8+I8*'Payroll Settings'!$B$6+IF('Payroll Settings'!$B$4="Yes",J8,0)+IF('Payroll Settings'!$B$5="Yes",K8,0)) -> 3 | M8: =SUMIFS(Attendance!$G$5:$G$1000,Attendance!$B$5:$B$1000,$A8,Attendance!$A$5:$A$1000,">="&'Payroll Settings'!$B$8,Attendance!$A$5:$A$1000,"<="&'Payroll Settings'!$B$9) -> 0 | N8: =IFERROR(VLOOKUP($A8,'Employee Master'!$A:$I,9,FALSE),0) -> 0 | O8: =IF('Payroll Settings'!$B$7="Yes",M8*N8,0) -> 0 | P8: =IF(OR($A8="EMP005",$A8="EMP006"),E8*G8,IF(D8="Monthly",E8/IF('Payroll Settings'!$B$3="30 Days",30,DAY('Payroll Settings'!$B$9))*L8,E8*L8)) -> 1200 | Q8: =P8+O8 -> 1200 | R8: =SUMIFS('Expense Register'!$D:$D,'Expense Register'!$B:$B,"Advance Salary",'Expense Register'!$A:$A,">="&'Payroll Settings'!$B$8,'Expense Register'!$A:$A,"<="&'Payroll Settings'!$B$9,'Expense Register'!$F:$F,"*"&B8&"*") -> 0 | S8: =SUMIFS('Expense Register'!$D:$D,'Expense Register'!$B:$B,"Travel Expense",'Expense Register'!$A:$A,">="&'Payroll Settings'!$B$8,'Expense Register'!$A:$A,"<="&'Payroll Settings'!$B$9,'Expense Register'!$F:$F,"*"&B8&"*") -> 0 | T8: =SUM(SUMIFS('Expense Register'!$D:$D,'Expense Register'!$B:$B,"Vegetables",'Expense Register'!$A:$A,">="&'Payroll Settings'!$B$8,'Expense Register'!$A:$A,"<="&'Payroll Settings'!$B$9,'Expense Register'!$F:$F,"*"&B8&"*"),SUMIFS('Expense Register'!$D:$D,'Expense Register'!$B:$B,"Grocery",'Expense Register'!$A:$A,">="&'Payroll Settings'!$B$8,'Expense Register'!$A:$A,"<="&'Payroll Settings'!$B$9,'Expense Register'!$F:$F,"*"&B8&"*")) -> 0 | U8: 0 | V8: =SUM(R8:U8) -> 0 | W8: =Q8-V8 -> 1200 | X8: Pending | AA8: PRESENT DAYS ONLY
A9: EMP007 | B9: =IFERROR(VLOOKUP($A9,'Employee Master'!$A:$I,2,FALSE),"") -> Muttalib Ansari | C9: =IFERROR(VLOOKUP($A9,'Employee Master'!$A:$I,3,FALSE),"") -> Helper | D9: =IFERROR(VLOOKUP($A9,'Employee Master'!$A:$I,5,FALSE),"") -> Monthly | E9: =IFERROR(VLOOKUP($A9,'Employee Master'!$A:$I,6,FALSE),0) -> 17000 | F9: =MAX(0,'Payroll Settings'!$B$9-MAX('Payroll Settings'!$B$8,IFERROR(VLOOKUP($A9,'Employee Master'!$A:$I,4,FALSE),'Payroll Settings'!$B$8))+1) -> 44 | G9: =COUNTIFS(Attendance!$B$5:$B$1000,$A9,Attendance!$F$5:$F$1000,"P",Attendance!$A$5:$A$1000,">="&'Payroll Settings'!$B$8,Attendance!$A$5:$A$1000,"<="&'Payroll Settings'!$B$9) -> 4 | H9: =COUNTIFS(Attendance!$B$5:$B$1000,$A9,Attendance!$F$5:$F$1000,"A",Attendance!$A$5:$A$1000,">="&'Payroll Settings'!$B$8,Attendance!$A$5:$A$1000,"<="&'Payroll Settings'!$B$9) -> 0 | I9: =COUNTIFS(Attendance!$B$5:$B$1000,$A9,Attendance!$F$5:$F$1000,"HD",Attendance!$A$5:$A$1000,">="&'Payroll Settings'!$B$8,Attendance!$A$5:$A$1000,"<="&'Payroll Settings'!$B$9) -> 0 | J9: =COUNTIFS(Attendance!$B$5:$B$1000,$A9,Attendance!$F$5:$F$1000,"L",Attendance!$A$5:$A$1000,">="&'Payroll Settings'!$B$8,Attendance!$A$5:$A$1000,"<="&'Payroll Settings'!$B$9) -> 1 | K9: =COUNTIFS(Attendance!$B$5:$B$1000,$A9,Attendance!$F$5:$F$1000,"WO",Attendance!$A$5:$A$1000,">="&'Payroll Settings'!$B$8,Attendance!$A$5:$A$1000,"<="&'Payroll Settings'!$B$9) -> 1 | L9: =IF(OR($A9="EMP005",$A9="EMP006"),G9,G9+I9*'Payroll Settings'!$B$6+IF('Payroll Settings'!$B$4="Yes",J9,0)+IF('Payroll Settings'!$B$5="Yes",K9,0)) -> 6 | M9: =SUMIFS(Attendance!$G$5:$G$1000,Attendance!$B$5:$B$1000,$A9,Attendance!$A$5:$A$1000,">="&'Payroll Settings'!$B$8,Attendance!$A$5:$A$1000,"<="&'Payroll Settings'!$B$9) -> 0 | N9: =IFERROR(VLOOKUP($A9,'Employee Master'!$A:$I,9,FALSE),0) -> 47 | O9: =IF('Payroll Settings'!$B$7="Yes",M9*N9,0) -> 0 | P9: =IF(OR($A9="EMP005",$A9="EMP006"),E9*G9,IF(D9="Monthly",E9/IF('Payroll Settings'!$B$3="30 Days",30,DAY('Payroll Settings'!$B$9))*L9,E9*L9)) -> 3290.3226 | Q9: =P9+O9 -> 3290.3226 | R9: =SUMIFS('Expense Register'!$D:$D,'Expense Register'!$B:$B,"Advance Salary",'Expense Register'!$A:$A,">="&'Payroll Settings'!$B$8,'Expense Register'!$A:$A,"<="&'Payroll Settings'!$B$9,'Expense Register'!$F:$F,"*"&B9&"*") -> 0 | S9: =SUMIFS('Expense Register'!$D:$D,'Expense Register'!$B:$B,"Travel Expense",'Expense Register'!$A:$A,">="&'Payroll Settings'!$B$8,'Expense Register'!$A:$A,"<="&'Payroll Settings'!$B$9,'Expense Register'!$F:$F,"*"&B9&"*") -> 0 | T9: =SUM(SUMIFS('Expense Register'!$D:$D,'Expense Register'!$B:$B,"Vegetables",'Expense Register'!$A:$A,">="&'Payroll Settings'!$B$8,'Expense Register'!$A:$A,"<="&'Payroll Settings'!$B$9,'Expense Register'!$F:$F,"*"&B9&"*"),SUMIFS('Expense Register'!$D:$D,'Expense Register'!$B:$B,"Grocery",'Expense Register'!$A:$A,">="&'Payroll Settings'!$B$8,'Expense Register'!$A:$A,"<="&'Payroll Settings'!$B$9,'Expense Register'!$F:$F,"*"&B9&"*")) -> 0 | U9: 0 | V9: =SUM(R9:U9) -> 0 | W9: =Q9-V9 -> 3290.3226 | X9: Pending
A10: EMP008 | B10: =IFERROR(VLOOKUP($A10,'Employee Master'!$A:$I,2,FALSE),"") -> Debashis Munda | C10: =IFERROR(VLOOKUP($A10,'Employee Master'!$A:$I,3,FALSE),"") -> Mixer Man | D10: =IFERROR(VLOOKUP($A10,'Employee Master'!$A:$I,5,FALSE),"") -> Monthly | E10: =IFERROR(VLOOKUP($A10,'Employee Master'!$A:$I,6,FALSE),0) -> 19000 | F10: =MAX(0,'Payroll Settings'!$B$9-MAX('Payroll Settings'!$B$8,IFERROR(VLOOKUP($A10,'Employee Master'!$A:$I,4,FALSE),'Payroll Settings'!$B$8))+1) -> 41 | G10: =COUNTIFS(Attendance!$B$5:$B$1000,$A10,Attendance!$F$5:$F$1000,"P",Attendance!$A$5:$A$1000,">="&'Payroll Settings'!$B$8,Attendance!$A$5:$A$1000,"<="&'Payroll Settings'!$B$9) -> 4 | H10: =COUNTIFS(Attendance!$B$5:$B$1000,$A10,Attendance!$F$5:$F$1000,"A",Attendance!$A$5:$A$1000,">="&'Payroll Settings'!$B$8,Attendance!$A$5:$A$1000,"<="&'Payroll Settings'!$B$9) -> 0 | I10: =COUNTIFS(Attendance!$B$5:$B$1000,$A10,Attendance!$F$5:$F$1000,"HD",Attendance!$A$5:$A$1000,">="&'Payroll Settings'!$B$8,Attendance!$A$5:$A$1000,"<="&'Payroll Settings'!$B$9) -> 0 | J10: =COUNTIFS(Attendance!$B$5:$B$1000,$A10,Attendance!$F$5:$F$1000,"L",Attendance!$A$5:$A$1000,">="&'Payroll Settings'!$B$8,Attendance!$A$5:$A$1000,"<="&'Payroll Settings'!$B$9) -> 1 | K10: =COUNTIFS(Attendance!$B$5:$B$1000,$A10,Attendance!$F$5:$F$1000,"WO",Attendance!$A$5:$A$1000,">="&'Payroll Settings'!$B$8,Attendance!$A$5:$A$1000,"<="&'Payroll Settings'!$B$9) -> 1 | L10: =IF(OR($A10="EMP005",$A10="EMP006"),G10,G10+I10*'Payroll Settings'!$B$6+IF('Payroll Settings'!$B$4="Yes",J10,0)+IF('Payroll Settings'!$B$5="Yes",K10,0)) -> 6 | M10: =SUMIFS(Attendance!$G$5:$G$1000,Attendance!$B$5:$B$1000,$A10,Attendance!$A$5:$A$1000,">="&'Payroll Settings'!$B$8,Attendance!$A$5:$A$1000,"<="&'Payroll Settings'!$B$9) -> 0 | N10: =IFERROR(VLOOKUP($A10,'Employee Master'!$A:$I,9,FALSE),0) -> 53 | O10: =IF('Payroll Settings'!$B$7="Yes",M10*N10,0) -> 0 | P10: =IF(OR($A10="EMP005",$A10="EMP006"),E10*G10,IF(D10="Monthly",E10/IF('Payroll Settings'!$B$3="30 Days",30,DAY('Payroll Settings'!$B$9))*L10,E10*L10)) -> 3677.4194 | Q10: =P10+O10 -> 3677.4194 | R10: =SUMIFS('Expense Register'!$D:$D,'Expense Register'!$B:$B,"Advance Salary",'Expense Register'!$A:$A,">="&'Payroll Settings'!$B$8,'Expense Register'!$A:$A,"<="&'Payroll Settings'!$B$9,'Expense Register'!$F:$F,"*"&B10&"*") -> 0 | S10: =SUMIFS('Expense Register'!$D:$D,'Expense Register'!$B:$B,"Travel Expense",'Expense Register'!$A:$A,">="&'Payroll Settings'!$B$8,'Expense Register'!$A:$A,"<="&'Payroll Settings'!$B$9,'Expense Register'!$F:$F,"*"&B10&"*") -> 0 | T10: =SUM(SUMIFS('Expense Register'!$D:$D,'Expense Register'!$B:$B,"Vegetables",'Expense Register'!$A:$A,">="&'Payroll Settings'!$B$8,'Expense Register'!$A:$A,"<="&'Payroll Settings'!$B$9,'Expense Register'!$F:$F,"*"&B10&"*"),SUMIFS('Expense Register'!$D:$D,'Expense Register'!$B:$B,"Grocery",'Expense Register'!$A:$A,">="&'Payroll Settings'!$B$8,'Expense Register'!$A:$A,"<="&'Payroll Settings'!$B$9,'Expense Register'!$F:$F,"*"&B10&"*")) -> 0 | U10: 0 | V10: =SUM(R10:U10) -> 0 | W10: =Q10-V10 -> 3677.4194 | X10: Pending
A11: EMP009 | B11: =IFERROR(VLOOKUP($A11,'Employee Master'!$A:$I,2,FALSE),"") -> Moumita Sardar | C11: =IFERROR(VLOOKUP($A11,'Employee Master'!$A:$I,3,FALSE),"") -> Pipe Cutting | D11: =IFERROR(VLOOKUP($A11,'Employee Master'!$A:$I,5,FALSE),"") -> Monthly | E11: =IFERROR(VLOOKUP($A11,'Employee Master'!$A:$I,6,FALSE),0) -> 11000 | F11: =MAX(0,'Payroll Settings'!$B$9-MAX('Payroll Settings'!$B$8,IFERROR(VLOOKUP($A11,'Employee Master'!$A:$I,4,FALSE),'Payroll Settings'!$B$8))+1) -> 41 | G11: =COUNTIFS(Attendance!$B$5:$B$1000,$A11,Attendance!$F$5:$F$1000,"P",Attendance!$A$5:$A$1000,">="&'Payroll Settings'!$B$8,Attendance!$A$5:$A$1000,"<="&'Payroll Settings'!$B$9) -> 4 | H11: =COUNTIFS(Attendance!$B$5:$B$1000,$A11,Attendance!$F$5:$F$1000,"A",Attendance!$A$5:$A$1000,">="&'Payroll Settings'!$B$8,Attendance!$A$5:$A$1000,"<="&'Payroll Settings'!$B$9) -> 0 | I11: =COUNTIFS(Attendance!$B$5:$B$1000,$A11,Attendance!$F$5:$F$1000,"HD",Attendance!$A$5:$A$1000,">="&'Payroll Settings'!$B$8,Attendance!$A$5:$A$1000,"<="&'Payroll Settings'!$B$9) -> 0 | J11: =COUNTIFS(Attendance!$B$5:$B$1000,$A11,Attendance!$F$5:$F$1000,"L",Attendance!$A$5:$A$1000,">="&'Payroll Settings'!$B$8,Attendance!$A$5:$A$1000,"<="&'Payroll Settings'!$B$9) -> 1 | K11: =COUNTIFS(Attendance!$B$5:$B$1000,$A11,Attendance!$F$5:$F$1000,"WO",Attendance!$A$5:$A$1000,">="&'Payroll Settings'!$B$8,Attendance!$A$5:$A$1000,"<="&'Payroll Settings'!$B$9) -> 1 | L11: =IF(OR($A11="EMP005",$A11="EMP006"),G11,G11+I11*'Payroll Settings'!$B$6+IF('Payroll Settings'!$B$4="Yes",J11,0)+IF('Payroll Settings'!$B$5="Yes",K11,0)) -> 6 | M11: =SUMIFS(Attendance!$G$5:$G$1000,Attendance!$B$5:$B$1000,$A11,Attendance!$A$5:$A$1000,">="&'Payroll Settings'!$B$8,Attendance!$A$5:$A$1000,"<="&'Payroll Settings'!$B$9) -> 0 | N11: =IFERROR(VLOOKUP($A11,'Employee Master'!$A:$I,9,FALSE),0) -> 0 | O11: =IF('Payroll Settings'!$B$7="Yes",M11*N11,0) -> 0 | P11: =IF(OR($A11="EMP005",$A11="EMP006"),E11*G11,IF(D11="Monthly",E11/IF('Payroll Settings'!$B$3="30 Days",30,DAY('Payroll Settings'!$B$9))*L11,E11*L11)) -> 2129.0323 | Q11: =P11+O11 -> 2129.0323 | R11: =SUMIFS('Expense Register'!$D:$D,'Expense Register'!$B:$B,"Advance Salary",'Expense Register'!$A:$A,">="&'Payroll Settings'!$B$8,'Expense Register'!$A:$A,"<="&'Payroll Settings'!$B$9,'Expense Register'!$F:$F,"*"&B11&"*") -> 0 | S11: =SUMIFS('Expense Register'!$D:$D,'Expense Register'!$B:$B,"Travel Expense",'Expense Register'!$A:$A,">="&'Payroll Settings'!$B$8,'Expense Register'!$A:$A,"<="&'Payroll Settings'!$B$9,'Expense Register'!$F:$F,"*"&B11&"*") -> 0 | T11: =SUM(SUMIFS('Expense Register'!$D:$D,'Expense Register'!$B:$B,"Vegetables",'Expense Register'!$A:$A,">="&'Payroll Settings'!$B$8,'Expense Register'!$A:$A,"<="&'Payroll Settings'!$B$9,'Expense Register'!$F:$F,"*"&B11&"*"),SUMIFS('Expense Register'!$D:$D,'Expense Register'!$B:$B,"Grocery",'Expense Register'!$A:$A,">="&'Payroll Settings'!$B$8,'Expense Register'!$A:$A,"<="&'Payroll Settings'!$B$9,'Expense Register'!$F:$F,"*"&B11&"*")) -> 0 | U11: 0 | V11: =SUM(R11:U11) -> 0 | W11: =Q11-V11 -> 2129.0323 | X11: Pending
A12: TOTAL | G12: =SUM(G5:G11) -> 27 | H12: =SUM(H5:H11) -> 1 | I12: =SUM(I5:I11) -> 0 | J12: =SUM(J5:J11) -> 7 | K12: =SUM(K5:K11) -> 7 | L12: =SUM(L5:L11) -> 39 | M12: =SUM(M5:M11) -> 0 | O12: =SUM(O5:O11) -> 0 | P12: =SUM(P5:P11) -> 25006.452 | Q12: =SUM(Q5:Q11) -> 25006.452 | R12: =SUM(R5:R11) -> 0 | S12: =SUM(S5:S11) -> 0 | T12: =SUM(T5:T11) -> 0 | U12: =SUM(U5:U11) -> 0 | V12: =SUM(V5:V11) -> 0 | W12: =SUM(W5:W11) -> 25006.452

Sheet Salary Payment Register
A1: SALARY PAYMENT REGISTER
A3: Payroll Month | B3: Employee ID | C3: Employee | D3: Net Salary | E3: Payment Date | F3: Payment Mode | G3: Transaction / UTR
A4: ='Payroll Settings'!B2 -> 01-Oct-2026 | B4: EMP001 | C4: =IFERROR(VLOOKUP(B4,Payroll!$A:$X,2,FALSE),"") -> Ravi | D4: =IFERROR(VLOOKUP(B4,Payroll!$A:$X,23,FALSE),0) -> 7741.9355
A5: ='Payroll Settings'!B2 -> 01-Oct-2026 | B5: EMP002 | C5: =IFERROR(VLOOKUP(B5,Payroll!$A:$X,2,FALSE),"") -> Raju | D5: =IFERROR(VLOOKUP(B5,Payroll!$A:$X,23,FALSE),0) -> 3677.4194
A6: ='Payroll Settings'!B2 -> 01-Oct-2026 | B6: EMP004 | C6: =IFERROR(VLOOKUP(B6,Payroll!$A:$X,2,FALSE),"") -> Shah Jahan | D6: =IFERROR(VLOOKUP(B6,Payroll!$A:$X,23,FALSE),0) -> 3290.3226
A7: ='Payroll Settings'!B2 -> 01-Oct-2026 | B7: EMP005 | C7: =IFERROR(VLOOKUP(B7,Payroll!$A:$X,2,FALSE),"") -> Shanti Devi | D7: =IFERROR(VLOOKUP(B7,Payroll!$A:$X,23,FALSE),0) -> 1200
A8: ='Payroll Settings'!B2 -> 01-Oct-2026 | B8: EMP007 | C8: =IFERROR(VLOOKUP(B8,Payroll!$A:$X,2,FALSE),"") -> Muttalib Ansari | D8: =IFERROR(VLOOKUP(B8,Payroll!$A:$X,23,FALSE),0) -> 3290.3226
A9: ='Payroll Settings'!B2 -> 01-Oct-2026 | B9: EMP008 | C9: =IFERROR(VLOOKUP(B9,Payroll!$A:$X,2,FALSE),"") -> Debashis Munda | D9: =IFERROR(VLOOKUP(B9,Payroll!$A:$X,23,FALSE),0) -> 3677.4194
A10: ='Payroll Settings'!B2 -> 01-Oct-2026 | B10: EMP009 | C10: =IFERROR(VLOOKUP(B10,Payroll!$A:$X,2,FALSE),"") -> Moumita Sardar | D10: =IFERROR(VLOOKUP(B10,Payroll!$A:$X,23,FALSE),0) -> 2129.0323

Sheet Payroll Summary
A1: PAYROLL SUMMARY
A3: Payroll Month | B3: ='Payroll Settings'!B2 -> 01-Oct-2026
A4: Active Employees | B4: =COUNTA(Payroll!A5:A99) -> 8
A5: Gross Basic Salary | B5: =SUM(Payroll!P5:P99) -> 50012.903
A6: OT Amount | B6: =SUM(Payroll!O5:O99) -> 0
A7: Gross Earnings | B7: =SUM(Payroll!Q5:Q99) -> 50012.903
A8: Total Advances | B8: =SUM(Payroll!R5:R99) -> 0
A9: Total Travel Deductions | B9: =SUM(Payroll!S5:S99) -> 0
A10: Total Food/Grocery Deductions | B10: =SUM(Payroll!T5:T99) -> 0
A11: Other Deductions | B11: =SUM(Payroll!U5:U99) -> 0
A12: Total Deductions | B12: =SUM(Payroll!V5:V99) -> 0
A13: Net Salary Payable | B13: =SUM(Payroll!W5:W99) -> 50012.903
A16: PAYMENT STATUS
A17: Paid | B17: =COUNTIF(Payroll!X5:X99,"Paid") -> 0
A18: Pending | B18: =COUNTIF(Payroll!X5:X99,"Pending") -> 7
A19: Part Paid | B19: =COUNTIF(Payroll!X5:X99,"Part Paid") -> 0
