Workbook

Sheet Labour
A2: Sl.no | B2: Labour name | C2: April | D2: May | E2: June | F2: July | G2: Aug | H2: Sept | I2: Oct | J2: Nov | K2: Dec | L2: Jan | M2: Feb | N2: March | P2: Total:
A3: 1 | B3: Pooja | C3: =April!AG6 -> 18 | D3: =May!AH5 -> 22 | E3: =June!AH6 -> 25.5 | F3: =July!AH6 -> 24 | G3: =August!AH6 -> 22 | H3: ='September '!AG6 | I3: ='October '!AH6 -> 4 | J3: ='November '!AG6 -> 0 | K3: ='December '!AH6 -> 0 | L3: =Jan!AH6 -> 0 | M3: =Feb!AE6 -> 0 | N3: ='March '!AH6 -> 0 | P3: =sum(C3:N3) -> 115.5
A4: 2 | B4: Kalpana | C4: =April!AG7 -> 11 | D4: =May!AH6 -> 22 | E4: =June!AH7 -> 23.5 | F4: =July!AH7 -> 22 | G4: =August!AH7 -> 22 | H4: ='September '!AG7 | I4: ='October '!AH7 -> 4 | J4: ='November '!AG7 -> 0 | K4: ='December '!AH7 -> 0 | L4: =Jan!AH7 -> 0 | M4: =Feb!AE7 -> 0 | N4: ='March '!AH7 -> 0 | P4: =sum(C4:N4) -> 104.5
A5: 3 | B5: Kavitha | C5: =April!AG8 -> 21 | D5: =May!AH7 -> 21 | E5: =June!AH8 -> 24.5 | F5: =July!AH8 -> 24 | G5: =August!AH8 -> 20.5 | H5: ='September '!AG8 | I5: ='October '!AH8 -> 4 | J5: ='November '!AG8 -> 0 | K5: ='December '!AH8 -> 0 | L5: =Jan!AH8 -> 0 | M5: =Feb!AE8 -> 0 | N5: ='March '!AH8 -> 0 | P5: =sum(C5:N5) -> 115
A6: 4 | B6: Shafiya | C6: =April!AG9 -> 20 | D6: =May!AH8 -> 19.5 | E6: =June!AH9 -> 25 | F6: =July!AH9 -> 24 | G6: =August!AH9 -> 22 | H6: ='September '!AG9 | I6: ='October '!AH9 -> 4 | J6: ='November '!AG9 -> 0 | K6: ='December '!AH9 -> 0 | L6: =Jan!AH9 -> 0 | M6: =Feb!AE9 -> 0 | N6: ='March '!AH9 -> 0 | P6: =sum(C6:N6) -> 114.5
A7: 5 | B7: Lakshmi | C7: =April!AG10 -> 21 | D7: =May!AH9 -> 12 | E7: =June!AH10 -> 18 | F7: =July!AH10 -> 22 | G7: =August!AH10 -> 0 | H7: ='September '!AG10 | I7: ='October '!AH10 -> 4 | J7: ='November '!AG10 -> 0 | K7: ='December '!AH10 -> 0 | L7: =Jan!AH10 -> 0 | M7: =Feb!AE10 -> 0 | N7: ='March '!AH10 -> 0 | P7: =sum(C7:N7) -> 77
A8: 6 | B8: Sagni devi | C8: =April!AG11 -> 10 | D8: =May!AH10 -> 0 | E8: =June!AH11 -> 24.5 | F8: =July!AH11 -> 23.5 | G8: =August!AH11 -> 23 | H8: ='September '!AG11 | I8: ='October '!AH11 -> 4 | J8: ='November '!AG11 -> 0 | K8: ='December '!AH11 -> 0 | L8: =Jan!AH11 -> 0 | M8: =Feb!AE11 -> 0 | N8: ='March '!AH11 -> 0 | P8: =sum(C8:N8) -> 85
A9: 7 | B9: Kamala | C9: =April!AG12 -> 3 | D9: =May!AH11 -> 0 | E9: =June!AH12 -> 24.5 | F9: =July!AH12 -> 24 | G9: =August!AH12 -> 23 | H9: ='September '!AG12 | I9: ='October '!AH12 -> 4 | J9: ='November '!AG12 -> 0 | K9: ='December '!AH12 -> 0 | L9: =Jan!AH12 -> 0 | M9: =Feb!AE12 -> 0 | N9: ='March '!AH12 -> 0 | P9: =sum(C9:N9) -> 78.5
A10: 8 | B10: Kanku Devi | C10: =April!AG13 -> 0 | D10: =May!AH12 -> 0 | E10: =June!AH13 -> 0 | F10: =July!AH13 -> 20 | G10: =August!AH13 -> 21 | H10: ='September '!AG13 | I10: ='October '!AH13 -> 4 | J10: ='November '!AG13 -> 0 | K10: ='December '!AH13 -> 0 | L10: =Jan!AH13 -> 0 | M10: =Feb!AE13 -> 0 | N10: ='March '!AH13 -> 0 | P10: =sum(C10:N10) -> 45
A11: 9 | B11: Bhagya | C11: =April!AG14 -> 18 | D11: =May!AH13 -> 18 | E11: =June!AH14 -> 14 | F11: 0 | G11: =August!AH14 -> 20 | H11: ='September '!AG14 | I11: ='October '!AH14 -> 2 | J11: ='November '!AG14 -> 0 | K11: ='December '!AH14 -> 0 | L11: =Jan!AH14 -> 0 | M11: =Feb!AE14 -> 0 | N11: ='March '!AH14 -> 0 | P11: =sum(C11:N11) -> 72
A12: 10 | B12: Keli Devi | C12: =April!AG15 -> 15 | D12: =May!AH14 -> 22 | E12: =June!AH15 -> 20.5 | F12: 24 | G12: =August!AH15 -> 0 | H12: ='September '!AG15 | I12: ='October '!AH15 -> 4 | J12: ='November '!AG15 -> 0 | K12: ='December '!AH15 -> 0 | L12: =Jan!AH15 -> 0 | M12: =Feb!AE15 -> 0 | N12: ='March '!AH15 -> 0 | P12: =sum(C12:N12) -> 85.5
A13: 11
A14: 12
A15: 13 | P15: =sum(C15:N15) -> 0
A16: 14 | P16: =sum(C16:N16) -> 0
A17: 15 | P17: =sum(C17:N17) -> 0
A18: 16 | P18: =sum(C18:N18) -> 0
A19: 17 | P19: =sum(C19:N19) -> 0
A20: 18 | P20: =sum(C20:N20) -> 0
B24: TOTAL: | C24: =SUM(C3:C22) -> 137 | D24: =SUM(D3:D22) -> 136.5 | E24: =SUM(E3:E22) -> 200 | F24: =SUM(F3:F22) -> 207.5 | G24: =SUM(G3:G22) -> 173.5 | H24: =SUM(H3:H22) -> 0 | I24: =SUM(I3:I22) -> 38 | J24: =SUM(J3:J22) -> 0 | ... N24: =SUM(N3:N22) -> 0

Sheet April
L2: April
A4: Sl.no | B4: Labour Name : | C4: 1 | D4: 2 | E4: 3 | F4: 4 | G4: 5 | H4: 6 | I4: 7 | J4: 8 | K4: 9 | L4: 10 | M4: 11 | N4: 12 | O4: 13 | P4: 14 | Q4: 15 | R4: 16 | S4: 17 | T4: 18 | U4: 19 | V4: 20 | W4: 21 | X4: 22 | Y4: 23 | Z4: 24 | AA4: 25 | AB4: 26 | AC4: 27 | AD4: 28 | AE4: 29 | AF4: 30 | AG4: (Total)
C5: Wed | D5: Thu | E5: Fri | F5: Sat | G5: Sun | H5: Mon | I5: Tue | J5: Wed | K5: Thu | L5: Fri | M5: Sat | N5: Sun | O5: Mon | P5: Tue | Q5: Wed | R5: Thu | S5: Fri | T5: Sat | U5: Sun | V5: Mon | W5: Tue | X5: Wed | Y5: Thu | Z5: Fri | AA5: Sat | AB5: Sun | AC5: Mon | AD5: Tue | AE5: Wed | AF5: Thu
A6: 1 | B6: Pooja | C6: P | D6: L | E6: P | F6: P | G6: L | H6: P | I6: P | J6: P | K6: P | L6: P | M6: P | N6: L | O6: P | P6: P | Q6: P | R6: P | S6: P | T6: L | U6: L | V6: P | W6: P | X6: P | Y6: A | Z6: A | AA6: A | AB6: A | AC6: A | AD6: A | AE6: A | AF6: P | AG6: =countif(C6:AF6,"P")+countif(C6:AF6,"H")*0.5+countif(C6:AF6,"A")*0 -> 18
A7: 2 | B7: Kalpana | C7: P | D7: L | E7: P | F7: A | G7: L | H7: A | I7: A | J7: A | K7: A | L7: A | M7: A | N7: L | O7: A | P7: A | Q7: A | R7: A | S7: P | T7: L | U7: L | V7: P | W7: P | X7: P | Y7: P | Z7: P | AA7: P | AB7: A | AC7: P | AD7: A | AE7: A | AF7: P | AG7: =countif(C7:AF7,"P")+countif(C7:AF7,"H")*0.5+countif(C7:AF7,"A")*0 -> 11
A8: 3 | B8: Kavitha | C8: P | D8: L | E8: P | F8: P | G8: L | H8: P | I8: P | J8: P | K8: P | L8: P | M8: P | N8: L | O8: P | P8: P | Q8: P | R8: P | S8: P | T8: L | U8: L | V8: P | W8: P | X8: P | Y8: P | Z8: P | AA8: P | AB8: A | AC8: P | AD8: A | AE8: A | AF8: A | AG8: =countif(C8:AF8,"P")+countif(C8:AF8,"H")*0.5+countif(C8:AF8,"A")*0 -> 21
A9: 4 | B9: Shafiya | C9: P | D9: L | E9: P | F9: P | G9: L | H9: A | I9: P | J9: P | K9: P | L9: P | M9: P | N9: L | O9: P | P9: P | Q9: P | R9: P | S9: P | T9: L | U9: L | V9: P | W9: P | X9: P | Y9: A | Z9: P | AA9: P | AB9: A | AC9: P | AD9: A | AE9: A | AF9: P | AG9: =countif(C9:AF9,"P")+countif(C9:AF9,"H")*0.5+countif(C9:AF9,"A")*0 -> 20
A10: 5 | B10: Lakshmi | C10: P | D10: L | E10: P | F10: P | G10: L | H10: P | I10: P | J10: P | K10: P | L10: P | M10: P | N10: L | O10: P | P10: P | Q10: P | R10: P | S10: P | T10: L | U10: L | V10: P | W10: P | X10: P | Y10: A | Z10: P | AA10: P | AB10: A | AC10: P | AD10: A | AE10: A | AF10: P | AG10: =countif(C10:AF10,"P")+countif(C10:AF10,"H")*0.5+countif(C10:AF10,"A")*0 -> 21
A11: 6 | B11: Sagni devi | C11: A | D11: L | E11: P | F11: P | G11: L | H11: P | I11: P | J11: P | K11: P | L11: P | M11: P | N11: L | O11: P | P11: P | Q11: A | R11: A | S11: A | T11: L | U11: L | V11: A | W11: A | X11: A | Y11: A | Z11: A | AA11: A | AB11: A | AC11: A | AD11: A | AE11: A | AF11: A | AG11: =countif(C11:AF11,"P")+countif(C11:AF11,"H")*0.5+countif(C11:AF11,"A")*0 -> 10
A12: 7 | B12: Kamala | C12: A | D12: L | E12: A | F12: P | G12: L | H12: P | I12: P | J12: A | K12: A | L12: A | M12: A | N12: L | O12: A | P12: A | Q12: A | R12: A | S12: A | T12: L | U12: L | V12: A | W12: A | X12: A | Y12: A | Z12: A | AA12: A | AB12: A | AC12: A | AD12: A | AE12: A | AF12: A | AG12: =countif(C12:AF12,"P")+countif(C12:AF12,"H")*0.5+countif(C12:AF12,"A")*0 -> 3
A13: 8 | B13: Kanku Devi | C13: A | D13: A | E13: A | F13: A | G13: A | H13: A | I13: A | J13: A | K13: A | L13: A | M13: A | N13: L | O13: A | P13: A | Q13: A | R13: A | S13: A | T13: L | U13: L | V13: A | W13: A | X13: A | Y13: A | Z13: A | AA13: A | AB13: A | AC13: A | AD13: A | AE13: A | AF13: A | AG13: =countif(C13:AF13,"P")+countif(C13:AF13,"H")*0.5+countif(C13:AF13,"A")*0 -> 0
A14: 9 | B14: Bhagya | C14: P | D14: L | E14: P | F14: P | G14: L | H14: P | I14: P | J14: A | K14: A | L14: A | M14: A | N14: L | O14: P | P14: P | Q14: P | R14: P | S14: P | T14: L | U14: L | V14: P | W14: P | X14: P | Y14: P | Z14: P | AA14: P | AB14: A | AC14: P | AD14: A | AE14: A | AF14: P | AG14: =countif(C14:AF14,"P")+countif(C14:AF14,"H")*0.5+countif(C14:AF14,"A")*0 -> 18
A15: 10 | B15: Keli Devi | C15: A | D15: L | E15: A | F15: A | G15: L | H15: P | I15: P | J15: A | K15: A | L15: A | M15: A | N15: L | O15: P | P15: P | Q15: P | R15: P | S15: P | T15: L | U15: L | V15: P | W15: P | X15: P | Y15: P | Z15: P | AA15: P | AB15: A | AC15: P | AD15: A | AE15: A | AF15: P | AG15: =countif(C15:AF15,"P")+countif(C15:AF15,"H")*0.5+countif(C15:AF15,"A")*0 -> 15
B24: Total labour per day : | C24: =countif(C6:C19,"P")+countif(C6:C19,"H")*0.5+countif(C6:C19,"A")*0 -> 6 | D24: =countif(D6:D19,"P")+countif(D6:D19,"H")*0.5+countif(D6:D19,"A")*0 -> 0 | E24: =countif(E6:E19,"P")+countif(E6:E19,"H")*0.5+countif(E6:E19,"A")*0 -> 7 | F24: =countif(F6:F19,"P")+countif(F6:F19,"H")*0.5+countif(F6:F19,"A")*0 -> 7 | G24: =countif(G6:G19,"P")+countif(G6:G19,"H")*0.5+countif(G6:G19,"A")*0 -> 0 | H24: =countif(H6:H19,"P")+countif(H6:H19,"H")*0.5+countif(H6:H19,"A")*0 -> 7 | I24: =countif(I6:I19,"P")+countif(I6:I19,"H")*0.5+countif(I6:I19,"A")*0 -> 8 | J24: =countif(J6:J19,"P")+countif(J6:J19,"H")*0.5+countif(J6:J19,"A")*0 -> 5 | ... AF24: =countif(AF6:AF19,"P")+countif(AF6:AF19,"H")*0.5+countif(AF6:AF19,"A")*0 -> 6
L28: April
B29: Over time sheet
A30: Sl.no | B30: Labour Name : | C30: 1 | D30: 2 | E30: 3 | F30: 4 | G30: 5 | H30: 6 | I30: 7 | J30: 8 | K30: 9 | L30: 10 | M30: 11 | N30: 12 | O30: 13 | P30: 14 | Q30: 15 | R30: 16 | S30: 17 | T30: 18 | U30: 19 | V30: 20 | W30: 21 | X30: 22 | Y30: 23 | Z30: 24 | AA30: 25 | AB30: 26 | AC30: 27 | AD30: 28 | AE30: 29 | AF30: 30 | AG30: (Total)
C31: Wed | D31: Thu | E31: Fri | F31: Sat | G31: Sun | H31: Mon | I31: Tue | J31: Wed | K31: Thu | L31: Fri | M31: Sat | N31: Sun | O31: Mon | P31: Tue | Q31: Wed | R31: Thu | S31: Fri | T31: Sat | U31: Sun | V31: Mon | W31: Tue | X31: Wed | Y31: Thu | Z31: Fri | AA31: Sat | AB31: Sun | AC31: Mon | AD31: Tue | AE31: Wed | AF31: Thu
A32: 1 | B32: Pooja | C32: 1 | D32: A | E32: 1 | F32: 1 | G32: L | H32: 1 | I32: 1 | J32: 1 | K32: 1 | L32: 1 | M32: A | N32: L | O32: 1 | P32: A | Q32: A | R32: A | S32: A | T32: L | U32: L | V32: A | W32: 1 | X32: A | Y32: A | Z32: A | AA32: A | AB32: A | AC32: A | AD32: A | AE32: A | AF32: 1 | AG32: =countif(C32:AF32,"1")+countif(C32:AF32,"H")*0.5+countif(C32:AF32,"A")*0 -> 11
A33: 2 | B33: Kalpana | C33: 1 | D33: A | E33: A | F33: A | G33: L | H33: A | I33: A | J33: A | K33: A | L33: A | M33: A | N33: L | O33: A | P33: A | Q33: A | R33: A | S33: A | T33: L | U33: L | V33: A | W33: 1 | X33: A | Y33: 1 | Z33: 1 | AA33: 1 | AB33: A | AC33: 1 | AD33: A | AE33: A | AF33: 1 | AG33: =countif(C33:AF33,"1")+countif(C33:AF33,"H")*0.5+countif(C33:AF33,"A")*0 -> 7
A34: 3 | B34: Kavitha | C34: 1 | D34: A | E34: 1 | F34: 1 | G34: L | H34: 1 | I34: 1 | J34: 1 | K34: 1 | L34: 1 | M34: A | N34: L | O34: 1 | P34: A | Q34: A | R34: A | S34: A | T34: L | U34: L | V34: A | W34: 1 | X34: A | Y34: 1 | Z34: 1 | AA34: 1 | AB34: A | AC34: 1 | AD34: A | AE34: A | AF34: A | AG34: =countif(C34:AF34,"1")+countif(C34:AF34,"H")*0.5+countif(C34:AF34,"A")*0 -> 14
A35: 4 | B35: Shafiya | C35: 1 | D35: A | E35: 1 | F35: 1 | G35: L | H35: A | I35: 1 | J35: 1 | K35: 1 | L35: 1 | M35: A | N35: L | O35: 1 | P35: A | Q35: A | R35: A | S35: A | T35: L | U35: L | V35: A | W35: 1 | X35: A | Y35: A | Z35: 1 | AA35: 1 | AB35: A | AC35: 1 | AD35: A | AE35: A | AF35: 1 | AG35: =countif(C35:AF35,"1")+countif(C35:AF35,"H")*0.5+countif(C35:AF35,"A")*0 -> 13
A36: 5 | B36: Lakshmi | C36: 1 | D36: A | E36: 1 | F36: 1 | G36: L | H36: 1 | I36: 1 | J36: 1 | K36: 1 | L36: 1 | M36: A | N36: L | O36: 1 | P36: A | Q36: A | R36: A | S36: A | T36: L | U36: L | V36: A | W36: 1 | X36: A | Y36: A | Z36: 1 | AA36: 1 | AB36: A | AC36: 1 | AD36: A | AE36: A | AF36: 1 | AG36: =countif(C36:AF36,"1")+countif(C36:AF36,"H")*0.5+countif(C36:AF36,"A")*0 -> 14
A37: 6 | B37: Sagni devi | C37: A | D37: A | E37: 1 | F37: 1 | G37: L | H37: 1 | I37: 1 | J37: 1 | K37: 1 | L37: 1 | M37: A | N37: L | O37: 1 | P37: A | Q37: A | R37: A | S37: A | T37: L | U37: L | V37: A | W37: A | X37: A | Y37: A | Z37: A | AA37: A | AB37: A | AC37: A | AD37: A | AE37: A | AF37: A | AG37: =countif(C37:AF37,"1")+countif(C37:AF37,"H")*0.5+countif(C37:AF37,"A")*0 -> 8
A38: 7 | B38: Kamala | C38: A | D38: A | E38: A | F38: 1 | G38: L | H38: 1 | I38: 1 | J38: A | K38: A | L38: A | M38: A | N38: L | O38: A | P38: A | Q38: A | R38: A | S38: A | T38: L | U38: L | V38: A | W38: A | X38: A | Y38: A | Z38: A | AA38: A | AB38: A | AC38: A | AD38: A | AE38: A | AF38: A | AG38: =countif(C38:AF38,"1")+countif(C38:AF38,"H")*0.5+countif(C38:AF38,"A")*0 -> 3
A39: 8 | B39: Kanku Devi | C39: A | D39: A | E39: A | F39: A | G39: L | H39: A | I39: A | J39: A | K39: A | L39: A | M39: A | N39: L | O39: A | P39: A | Q39: A | R39: A | S39: A | T39: L | U39: L | V39: A | W39: A | X39: A | Y39: A | Z39: A | AA39: A | AB39: A | AC39: A | AD39: A | AE39: A | AF39: A | AG39: =countif(C39:AF39,"1")+countif(C39:AF39,"H")*0.5+countif(C39:AF39,"A")*0 -> 0
A40: 9 | B40: Bhagya | C40: 1 | D40: A | E40: 1 | F40: 1 | G40: L | H40: 1 | I40: 1 | J40: A | K40: A | L40: A | M40: A | N40: L | O40: 1 | P40: A | Q40: A | R40: A | S40: A | T40: L | U40: L | V40: A | W40: 1 | X40: A | Y40: 1 | Z40: 1 | AA40: 1 | AB40: A | AC40: 1 | AD40: A | AE40: A | AF40: 1 | AG40: =countif(C40:AF40,"1")+countif(C40:AF40,"H")*0.5+countif(C40:AF40,"A")*0 -> 12
A41: 10 | B41: Keli Devi | C41: A | D41: A | E41: A | F41: A | G41: L | H41: 1 | I41: 1 | J41: A | K41: A | L41: A | M41: A | N41: L | O41: 1 | P41: A | Q41: A | R41: A | S41: A | T41: L | U41: L | V41: A | W41: 1 | X41: A | Y41: 1 | Z41: 1 | AA41: A | AB41: A | AC41: 1 | AD41: A | AE41: A | AF41: 1 | AG41: =countif(C41:AF41,"1")+countif(C41:AF41,"H")*0.5+countif(C41:AF41,"A")*0 -> 8
AG42: =countif(C42:AF42,"1")+countif(C42:AF42,"H")*0.5+countif(C42:AF42,"A")*0 -> 0
AG43: =countif(C43:AF43,"1")+countif(C43:AF43,"H")*0.5+countif(C43:AF43,"A")*0 -> 0
AG44: =countif(C44:AF44,"1")+countif(C44:AF44,"H")*0.5+countif(C44:AF44,"A")*0 -> 0
AG45: =countif(C45:AF45,"1")+countif(C45:AF45,"H")*0.5+countif(C45:AF45,"A")*0 -> 0
B46: Overtime (OT) | AG46: =SUM(AG29:AG45) -> 90
B50: Total labour per day : | C50: =countif(C32:C45,"1")+countif(C32:C45,"H")*0.5+countif(C32:C45,"A")*0 -> 6 | D50: =countif(D32:D45,"1")+countif(D32:D45,"H")*0.5+countif(D32:D45,"A")*0 -> 0 | E50: =countif(E32:E45,"1")+countif(E32:E45,"H")*0.5+countif(E32:E45,"A")*0 -> 6 | F50: =countif(F32:F45,"1")+countif(F32:F45,"H")*0.5+countif(F32:F45,"A")*0 -> 7 | G50: =countif(G32:G45,"1")+countif(G32:G45,"H")*0.5+countif(G32:G45,"A")*0 -> 0 | H50: =countif(H32:H45,"1")+countif(H32:H45,"H")*0.5+countif(H32:H45,"A")*0 -> 7 | I50: =countif(I32:I45,"1")+countif(I32:I45,"H")*0.5+countif(I32:I45,"A")*0 -> 8 | J50: =countif(J32:J45,"1")+countif(J32:J45,"H")*0.5+countif(J32:J45,"A")*0 -> 5 | ... AF50: =countif(AF32:AF45,"1")+countif(AF32:AF45,"H")*0.5+countif(AF32:AF45,"A")*0 -> 6

Sheet May
L1: May
A3: Sl.no | B3: Labour Name : | C3: 1 | D3: 2 | E3: 3 | F3: 4 | G3: 5 | H3: 6 | I3: 7 | J3: 8 | K3: 9 | L3: 10 | M3: 11 | N3: 12 | O3: 13 | P3: 14 | Q3: 15 | R3: 16 | S3: 17 | T3: 18 | U3: 19 | V3: 20 | W3: 21 | X3: 22 | Y3: 23 | Z3: 24 | AA3: 25 | AB3: 26 | AC3: 27 | AD3: 28 | AE3: 29 | AF3: 30 | AG3: 31 | AH3: (Total)
C4: Fri | D4: Sat | E4: Sun | F4: Mon | G4: Tue | H4: Wed | I4: Thu | J4: Fri | K4: Sat | L4: Sun | M4: Mon | N4: Tue | O4: Wed | P4: Thu | Q4: Fri | R4: Sat | S4: Sun | T4: Mon | U4: Tue | V4: Wed | W4: Thu | X4: Fri | Y4: Sat | Z4: Sun | AA4: Mon | AB4: Tue | AC4: Wed | AD4: Thu | AE4: Fri | AF4: Sat | AG4: Sun
A5: 1 | B5: Pooja | C5: L | D5: P | E5: L | F5: P | G5: P | H5: P | I5: P | J5: P | K5: P | L5: L | M5: P | N5: P | O5: P | P5: P | Q5: L | R5: P | S5: L | T5: P | U5: L | V5: P | W5: P | X5: P | Y5: P | Z5: L | AA5: P | AB5: P | AC5: P | AD5: L | AE5: P | AF5: P | AG5: L | AH5: =countif(C5:AG5,"P")+countif(C5:AG5,"H")*0.5+countif(C5:AG5,"A")*0 -> 22
A6: 2 | B6: Kalpana | C6: L | D6: P | E6: L | F6: P | G6: P | H6: P | I6: P | J6: P | K6: P | L6: L | M6: P | N6: P | O6: P | P6: P | Q6: L | R6: P | S6: L | T6: P | U6: L | V6: P | W6: P | X6: P | Y6: P | Z6: L | AA6: P | AB6: P | AC6: P | AD6: L | AE6: P | AF6: P | AG6: L | AH6: =countif(C6:AG6,"P")+countif(C6:AG6,"H")*0.5+countif(C6:AG6,"A")*0 -> 22
A7: 3 | B7: Kavitha | C7: L | D7: P | E7: L | F7: P | G7: P | H7: P | I7: P | J7: P | K7: P | L7: L | M7: P | N7: P | O7: P | P7: P | Q7: L | R7: P | S7: L | T7: P | U7: L | V7: P | W7: P | X7: P | Y7: P | Z7: L | AA7: P | AB7: A | AC7: P | AD7: L | AE7: P | AF7: P | AG7: L | AH7: =countif(C7:AG7,"P")+countif(C7:AG7,"H")*0.5+countif(C7:AG7,"A")*0 -> 21
A8: 4 | B8: Shafiya | C8: L | D8: P | E8: L | F8: A | G8: P | H8: P | I8: P | J8: P | K8: P | L8: L | M8: P | N8: H | O8: P | P8: P | Q8: L | R8: P | S8: L | T8: P | U8: L | V8: P | W8: P | X8: P | Y8: P | Z8: L | AA8: P | AB8: P | AC8: P | AD8: L | AE8: A | AF8: P | AG8: L | AH8: =countif(C8:AG8,"P")+countif(C8:AG8,"H")*0.5+countif(C8:AG8,"A")*0 -> 19.5
A9: 5 | B9: Lakshmi | C9: L | D9: P | E9: L | F9: P | G9: P | H9: P | I9: P | J9: P | K9: P | L9: L | M9: A | N9: A | O9: A | P9: A | Q9: L | R9: P | S9: L | T9: P | U9: L | V9: P | W9: P | X9: P | Y9: A | Z9: L | AA9: A | AB9: A | AC9: A | AD9: L | AE9: A | AF9: A | AG9: L | AH9: =countif(C9:AG9,"P")+countif(C9:AG9,"H")*0.5+countif(C9:AG9,"A")*0 -> 12
A10: 6 | B10: Sagni devi | C10: L | D10: A | E10: L | F10: A | G10: A | H10: A | I10: A | J10: A | K10: A | L10: L | M10: A | N10: A | O10: A | P10: A | Q10: L | R10: A | S10: L | T10: A | U10: L | V10: A | W10: A | X10: A | Y10: A | Z10: L | AA10: A | AB10: A | AC10: A | AD10: L | AE10: A | AF10: A | AG10: L | AH10: =countif(C10:AG10,"P")+countif(C10:AG10,"H")*0.5+countif(C10:AG10,"A")*0 -> 0
A11: 7 | B11: Kamala | C11: L | D11: A | E11: L | F11: A | G11: A | H11: A | I11: A | J11: A | K11: A | L11: L | M11: A | N11: A | O11: A | P11: A | Q11: L | R11: A | S11: L | T11: A | U11: L | V11: A | W11: A | X11: A | Y11: A | Z11: L | AA11: A | AB11: A | AC11: A | AD11: L | AE11: A | AF11: A | AG11: L | AH11: =countif(C11:AG11,"P")+countif(C11:AG11,"H")*0.5+countif(C11:AG11,"A")*0 -> 0
A12: 8 | B12: Kanku Devi | C12: L | D12: A | E12: L | F12: A | G12: A | H12: A | I12: A | J12: A | K12: A | L12: L | M12: A | N12: A | O12: A | P12: A | Q12: L | R12: A | S12: L | T12: A | U12: L | V12: A | W12: A | X12: A | Y12: A | Z12: L | AA12: A | AB12: A | AC12: A | AD12: L | AE12: A | AF12: A | AG12: L | AH12: =countif(C12:AG12,"P")+countif(C12:AG12,"H")*0.5+countif(C12:AG12,"A")*0 -> 0
A13: 9 | B13: Bhagya | C13: L | D13: A | E13: L | F13: P | G13: P | H13: P | I13: P | J13: P | K13: P | L13: L | M13: P | N13: P | O13: A | P13: A | Q13: L | R13: P | S13: L | T13: P | U13: L | V13: P | W13: P | X13: P | Y13: P | Z13: L | AA13: P | AB13: P | AC13: P | AD13: L | AE13: A | AF13: P | AG13: L | AH13: =countif(C13:AG13,"P")+countif(C13:AG13,"H")*0.5+countif(C13:AG13,"A")*0 -> 18
A14: 10 | B14: Keli Devi | C14: L | D14: P | E14: L | F14: P | G14: P | H14: P | I14: P | J14: P | K14: P | L14: L | M14: P | N14: P | O14: P | P14: P | Q14: L | R14: P | S14: L | T14: P | U14: L | V14: P | W14: P | X14: P | Y14: P | Z14: L | AA14: P | AB14: P | AC14: P | AD14: L | AE14: P | AF14: P | AG14: L | AH14: =countif(C14:AG14,"P")+countif(C14:AG14,"H")*0.5+countif(C14:AG14,"A")*0 -> 22
A15: 11 | AH15: =countif(C15:AG15,"P")+countif(C15:AG15,"H")*0.5+countif(C15:AG15,"A")*0 -> 0
A16: 12 | AH16: =countif(C16:AG16,"P")+countif(C16:AG16,"H")*0.5+countif(C16:AG16,"A")*0 -> 0
A17: 13 | AH17: =countif(C17:AG17,"P")+countif(C17:AG17,"H")*0.5+countif(C17:AG17,"A")*0 -> 0
A18: 14 | AH18: =countif(C18:AG18,"P")+countif(C18:AG18,"H")*0.5+countif(C18:AG18,"A")*0 -> 0
A19: 15 | AH19: =countif(C19:AG19,"P")+countif(C19:AG19,"H")*0.5+countif(C19:AG19,"A")*0 -> 0
B26: Total per day : | C26: =countif(C5:C21,"P")+countif(C5:C21,"H")*0.5+countif(C5:C21,"A")*0 -> 0 | D26: =countif(D5:D21,"P")+countif(D5:D21,"H")*0.5+countif(D5:D21,"A")*0 -> 6 | E26: =countif(E5:E21,"P")+countif(E5:E21,"H")*0.5+countif(E5:E21,"A")*0 -> 0 | F26: =countif(F5:F21,"P")+countif(F5:F21,"H")*0.5+countif(F5:F21,"A")*0 -> 6 | G26: =countif(G5:G21,"P")+countif(G5:G21,"H")*0.5+countif(G5:G21,"A")*0 -> 7 | H26: =countif(H5:H21,"P")+countif(H5:H21,"H")*0.5+countif(H5:H21,"A")*0 -> 7 | I26: =countif(I5:I21,"P")+countif(I5:I21,"H")*0.5+countif(I5:I21,"A")*0 -> 7 | J26: =countif(J5:J21,"P")+countif(J5:J21,"H")*0.5+countif(J5:J21,"A")*0 -> 7 | ... AF26: =countif(AF5:AF21,"P")+countif(AF5:AF21,"H")*0.5+countif(AF5:AF21,"A")*0 -> 6 | AH26: =sum(C26:AG26) -> 136.5
L31: May- OT
A33: Sl.no | B33: Labour Name : | C33: 1 | D33: 2 | E33: 3 | F33: 4 | G33: 5 | H33: 6 | I33: 7 | J33: 8 | K33: 9 | L33: 10 | M33: 11 | N33: 12 | O33: 13 | P33: 14 | Q33: 15 | R33: 16 | S33: 17 | T33: 18 | U33: 19 | V33: 20 | W33: 21 | X33: 22 | Y33: 23 | Z33: 24 | AA33: 25 | AB33: 26 | AC33: 27 | AD33: 28 | AE33: 29 | AF33: 30 | AG33: 31 | AH33: (Total)
C34: Fri | D34: Sat | E34: Sun | F34: Mon | G34: Tue | H34: Wed | I34: Thu | J34: Fri | K34: Sat | L34: Sun | M34: Mon | N34: Tue | O34: Wed | P34: Thu | Q34: Fri | R34: Sat | S34: Sun | T34: Mon | U34: Tue | V34: Wed | W34: Thu | X34: Fri | Y34: Sat | Z34: Sun | AA34: Mon | AB34: Tue | AC34: Wed | AD34: Thu | AE34: Fri | AF34: Sat | AG34: Sun
A35: 1 | B35: Pooja | C35: L | D35: 1 | E35: L | F35: 1 | G35: 1 | H35: - | I35: 1 | J35: 1 | K35: 1 | L35: L | M35: 1 | N35: - | O35: - | P35: - | Q35: L | R35: 1 | S35: L | T35: - | U35: L | V35: 1 | W35: 1 | X35: - | Y35: - | Z35: - | AA35: - | AB35: - | AC35: - | AD35: L | AE35: 1 | AF35: 1 | AG35: L | AH35: =countif(C35:AG35,"1")+countif(C35:AG35,"H")*0.5+countif(C35:AG35,"A")*0 -> 12
A36: 2 | B36: Kalpana | C36: L | D36: 1 | E36: L | F36: 1 | G36: 1 | H36: - | I36: 1 | J36: 1 | K36: 1 | L36: L | M36: 1 | N36: - | O36: - | P36: - | Q36: L | R36: 1 | S36: L | T36: - | U36: L | V36: 1 | W36: 1 | X36: - | Y36: - | Z36: - | AA36: - | AB36: - | AC36: - | AD36: L | AE36: 1 | AF36: 1 | AG36: L | AH36: =countif(C36:AG36,"1")+countif(C36:AG36,"H")*0.5+countif(C36:AG36,"A")*0 -> 12
A37: 3 | B37: Kavitha | C37: L | D37: 1 | E37: L | F37: 1 | G37: 1 | H37: - | I37: 1 | J37: 1 | K37: 1 | L37: L | M37: 1 | N37: - | O37: - | P37: - | Q37: L | R37: 1 | S37: L | T37: - | U37: L | V37: 1 | W37: 1 | X37: - | Y37: - | Z37: - | AA37: - | AB37: - | AC37: - | AD37: L | AE37: 1 | AF37: 1 | AG37: L | AH37: =countif(C37:AG37,"1")+countif(C37:AG37,"H")*0.5+countif(C37:AG37,"A")*0 -> 12
A38: 4 | B38: Shafiya | C38: L | D38: 1 | E38: L | F38: A | G38: 1 | H38: - | I38: 1 | J38: 1 | K38: 1 | L38: L | M38: 1 | N38: - | O38: - | P38: - | Q38: L | R38: 1 | S38: L | T38: - | U38: L | V38: 1 | W38: 1 | X38: - | Y38: - | Z38: - | AA38: - | AB38: - | AC38: - | AD38: L | AE38: L | AF38: 1 | AG38: L | AH38: =countif(C38:AG38,"1")+countif(C38:AG38,"H")*0.5+countif(C38:AG38,"A")*0 -> 10
A39: 5 | B39: Lakshmi | C39: L | D39: 1 | E39: L | F39: 1 | G39: 1 | H39: - | I39: 1 | J39: 1 | K39: 1 | L39: L | M39: A | N39: - | O39: - | P39: - | Q39: L | R39: 1 | S39: L | T39: - | U39: L | V39: 1 | W39: 1 | X39: - | Y39: - | Z39: - | AA39: - | AB39: - | AC39: - | AD39: L | AE39: L | AF39: L | AG39: L | AH39: =countif(C39:AG39,"1")+countif(C39:AG39,"H")*0.5+countif(C39:AG39,"A")*0 -> 9
A40: 6 | B40: Sagni devi | C40: L | D40: A | E40: L | F40: A | G40: A | H40: - | I40: A | J40: A | K40: A | L40: L | M40: A | N40: - | O40: - | P40: - | Q40: L | R40: A | S40: L | T40: - | U40: L | V40: A | W40: A | X40: - | Y40: - | Z40: - | AA40: - | AB40: - | AC40: - | AD40: L | AE40: L | AF40: L | AG40: L | AH40: =countif(C40:AG40,"1")+countif(C40:AG40,"H")*0.5+countif(C40:AG40,"A")*0 -> 0
A41: 7 | B41: Kamala | C41: L | D41: A | E41: L | F41: A | G41: A | H41: - | I41: A | J41: A | K41: A | L41: L | M41: A | N41: - | O41: - | P41: - | Q41: L | R41: A | S41: L | T41: - | U41: L | V41: A | W41: A | X41: - | Y41: - | Z41: - | AA41: - | AB41: - | AC41: - | AD41: L | AE41: L | AF41: L | AG41: L | AH41: =countif(C41:AG41,"1")+countif(C41:AG41,"H")*0.5+countif(C41:AG41,"A")*0 -> 0
A42: 8 | B42: Kanku Devi | C42: L | D42: A | E42: L | F42: A | G42: A | H42: - | I42: A | J42: A | K42: A | L42: L | M42: A | N42: - | O42: - | P42: - | Q42: L | R42: A | S42: L | T42: - | U42: L | V42: A | W42: A | X42: - | Y42: - | Z42: - | AA42: - | AB42: - | AC42: - | AD42: L | AE42: L | AF42: L | AG42: L | AH42: =countif(C42:AG42,"1")+countif(C42:AG42,"H")*0.5+countif(C42:AG42,"A")*0 -> 0
A43: 9 | B43: Bhagya | C43: L | D43: A | E43: L | F43: 1 | G43: 1 | H43: - | I43: 1 | J43: 1 | K43: 1 | L43: L | M43: 1 | N43: - | O43: - | P43: - | Q43: L | R43: 1 | S43: L | T43: - | U43: L | V43: 1 | W43: 1 | X43: - | Y43: - | Z43: - | AA43: - | AB43: - | AC43: - | AD43: L | AE43: L | AF43: 1 | AG43: L | AH43: =countif(C43:AG43,"1")+countif(C43:AG43,"H")*0.5+countif(C43:AG43,"A")*0 -> 10
A44: 10 | B44: Keli Devi | C44: L | D44: 1 | E44: L | F44: 1 | G44: 1 | H44: - | I44: 1 | J44: 1 | K44: 1 | L44: L | M44: 1 | N44: - | O44: - | P44: - | Q44: L | R44: 1 | S44: L | T44: - | U44: L | V44: 1 | W44: 1 | X44: - | Y44: - | Z44: - | AA44: - | AB44: - | AC44: - | AD44: L | AE44: 1 | AF44: 1 | AG44: L | AH44: =countif(C44:AG44,"1")+countif(C44:AG44,"H")*0.5+countif(C44:AG44,"A")*0 -> 12
AH45: =countif(C45:AG45,"1")+countif(C45:AG45,"H")*0.5+countif(C45:AG45,"A")*0 -> 0
AH46: =countif(C46:AG46,"1")+countif(C46:AG46,"H")*0.5+countif(C46:AG46,"A")*0 -> 0
AH47: =countif(C47:AG47,"1")+countif(C47:AG47,"H")*0.5+countif(C47:AG47,"A")*0 -> 0
AH48: =countif(C48:AG48,"1")+countif(C48:AG48,"H")*0.5+countif(C48:AG48,"A")*0 -> 0
B49: Overtime (OT) | AH49: =SUM(AH35:AH48) -> 77
C53: Total labour per day : | D53: =countif(C35:C48,"1")+countif(C35:C48,"H")*0.5+countif(C35:C48,"A")*0 -> 0 | E53: =countif(D35:D48,"1")+countif(D35:D48,"H")*0.5+countif(D35:D48,"A")*0 -> 6 | F53: =countif(E35:E48,"1")+countif(E35:E48,"H")*0.5+countif(E35:E48,"A")*0 -> 0 | G53: =countif(F35:F48,"1")+countif(F35:F48,"H")*0.5+countif(F35:F48,"A")*0 -> 6 | H53: =countif(G35:G48,"1")+countif(G35:G48,"H")*0.5+countif(G35:G48,"A")*0 -> 7 | I53: =countif(H35:H48,"1")+countif(H35:H48,"H")*0.5+countif(H35:H48,"A")*0 -> 0 | J53: =countif(I35:I48,"1")+countif(I35:I48,"H")*0.5+countif(I35:I48,"A")*0 -> 7 | K53: =countif(J35:J48,"1")+countif(J35:J48,"H")*0.5+countif(J35:J48,"A")*0 -> 7 | ... AG53: =countif(AF35:AF48,"1")+countif(AF35:AF48,"H")*0.5+countif(AF35:AF48,"A")*0 -> 6

Sheet June
L2: June
A4: Sl.no | B4: Labour Name : | C4: 1 | D4: 2 | E4: 3 | F4: 4 | G4: 5 | H4: 6 | I4: 7 | J4: 8 | K4: 9 | L4: 10 | M4: 11 | N4: 12 | O4: 13 | P4: 14 | Q4: 15 | R4: 16 | S4: 17 | T4: 18 | U4: 19 | V4: 20 | W4: 21 | X4: 22 | Y4: 23 | Z4: 24 | AA4: 25 | AB4: 26 | AC4: 27 | AD4: 28 | AE4: 29 | AF4: 30 | AH4: (Total)
C5: Mon | D5: Tue | E5: Wed | F5: Thu | G5: Fri | H5: Sat | I5: Sun | J5: Mon | K5: Tue | L5: Wed | M5: Thu | N5: Fri | O5: Sat | P5: Sun | Q5: Mon | R5: Tue | S5: Wed | T5: Thu | U5: Fri | V5: Sat | W5: Sun | X5: Mon | Y5: Tue | Z5: Wed | AA5: Thu | AB5: Fri | AC5: Sat | AD5: Sun | AE5: Mon | AF5: Tue
A6: 1 | B6: Pooja | C6: H | D6: P | E6: P | F6: P | G6: P | H6: P | I6: L | J6: P | K6: P | L6: P | M6: P | N6: P | O6: P | P6: L | Q6: P | R6: P | S6: P | T6: P | U6: P | V6: P | W6: L | X6: P | Y6: P | Z6: P | AA6: P | AB6: P | AC6: P | AD6: L | AE6: P | AF6: P | AH6: =countif(C6:AF6,"P")+countif(C6:AF6,"H")*0.5+countif(C6:AF6,"A")*0 -> 25.5
A7: 2 | B7: Kalpana | C7: H | D7: P | E7: P | F7: P | G7: P | H7: P | I7: L | J7: P | K7: P | L7: P | M7: P | N7: P | O7: P | P7: L | Q7: P | R7: P | S7: P | T7: P | U7: A | V7: P | W7: L | X7: P | Y7: P | Z7: P | AA7: P | AB7: A | AC7: P | AD7: L | AE7: P | AF7: P | AH7: =countif(C7:AF7,"P")+countif(C7:AF7,"H")*0.5+countif(C7:AF7,"A")*0 -> 23.5
A8: 3 | B8: Kavitha | C8: H | D8: P | E8: P | F8: P | G8: P | H8: P | I8: L | J8: P | K8: P | L8: P | M8: P | N8: P | O8: P | P8: L | Q8: P | R8: P | S8: P | T8: P | U8: P | V8: P | W8: L | X8: P | Y8: P | Z8: P | AA8: A | AB8: P | AC8: P | AD8: L | AE8: P | AF8: P | AH8: =countif(C8:AF8,"P")+countif(C8:AF8,"H")*0.5+countif(C8:AF8,"A")*0 -> 24.5
A9: 4 | B9: Shafiya | C9: A | D9: P | E9: P | F9: P | G9: P | H9: P | I9: L | J9: P | K9: P | L9: P | M9: P | N9: P | O9: P | P9: L | Q9: P | R9: P | S9: P | T9: P | U9: P | V9: P | W9: L | X9: P | Y9: P | Z9: P | AA9: P | AB9: P | AC9: P | AD9: L | AE9: P | AF9: P | AH9: =countif(C9:AF9,"P")+countif(C9:AF9,"H")*0.5+countif(C9:AF9,"A")*0 -> 25
A10: 5 | B10: Lakshmi | C10: A | D10: A | E10: A | F10: A | G10: A | H10: A | I10: L | J10: A | K10: P | L10: P | M10: P | N10: P | O10: P | P10: L | Q10: P | R10: P | S10: P | T10: P | U10: P | V10: P | W10: L | X10: P | Y10: P | Z10: P | AA10: P | AB10: A | AC10: P | AD10: L | AE10: P | AF10: P | AH10: =countif(C10:AF10,"P")+countif(C10:AF10,"H")*0.5+countif(C10:AF10,"A")*0 -> 18
A11: 6 | B11: Sagni devi | C11: H | D11: P | E11: P | F11: P | G11: P | H11: P | I11: L | J11: P | K11: A | L11: P | M11: P | N11: P | O11: P | P11: L | Q11: P | R11: P | S11: P | T11: P | U11: P | V11: P | W11: L | X11: P | Y11: P | Z11: P | AA11: P | AB11: P | AC11: P | AD11: L | AE11: P | AF11: P | AH11: =countif(C11:AF11,"P")+countif(C11:AF11,"H")*0.5+countif(C11:AF11,"A")*0 -> 24.5
A12: 7 | B12: Kamala | C12: H | D12: P | E12: P | F12: P | G12: P | H12: P | I12: L | J12: P | K12: P | L12: P | M12: P | N12: P | O12: P | P12: L | Q12: P | R12: P | S12: P | T12: P | U12: P | V12: P | W12: L | X12: P | Y12: P | Z12: P | AA12: P | AB12: P | AC12: P | AD12: L | AE12: A | AF12: P | AH12: =countif(C12:AF12,"P")+countif(C12:AF12,"H")*0.5+countif(C12:AF12,"A")*0 -> 24.5
A13: 8 | B13: Kanku Devi | C13: A | D13: A | E13: A | F13: A | G13: A | H13: A | I13: L | J13: A | K13: A | L13: A | M13: A | N13: A | O13: A | P13: L | Q13: A | R13: A | S13: A | T13: A | U13: A | V13: A | W13: L | X13: A | Y13: A | Z13: A | AA13: A | AB13: A | AC13: A | AD13: L | AE13: A | AF13: A | AH13: =countif(C13:AF13,"P")+countif(C13:AF13,"H")*0.5+countif(C13:AF13,"A")*0 -> 0
A14: 9 | B14: Bhagya | C14: H | D14: P | E14: P | F14: P | G14: P | H14: P | I14: L | J14: H | K14: A | L14: P | M14: P | N14: P | O14: P | P14: L | Q14: P | R14: A | S14: A | T14: A | U14: A | V14: A | W14: L | X14: P | Y14: P | Z14: P | AA14: A | AB14: A | AC14: A | AD14: L | AE14: A | AF14: A | AH14: =countif(C14:AF14,"P")+countif(C14:AF14,"H")*0.5+countif(C14:AF14,"A")*0 -> 14
A15: 10 | B15: Keli Devi | C15: H | D15: P | E15: P | F15: P | G15: P | H15: P | I15: L | J15: P | K15: P | L15: P | M15: P | N15: P | O15: P | P15: L | Q15: A | R15: A | S15: A | T15: A | U15: A | V15: P | W15: L | X15: P | Y15: P | Z15: P | AA15: P | AB15: P | AC15: P | AD15: L | AE15: P | AF15: P | AH15: =countif(C15:AF15,"P")+countif(C15:AF15,"H")*0.5+countif(C15:AF15,"A")*0 -> 20.5
AH16: =countif(C16:AF16,"P")+countif(C16:AF16,"H")*0.5+countif(C16:AF16,"A")*0 -> 0
AH17: =countif(C17:AF17,"P")+countif(C17:AF17,"H")*0.5+countif(C17:AF17,"A")*0 -> 0
AH18: =countif(C18:AF18,"P")+countif(C18:AF18,"H")*0.5+countif(C18:AF18,"A")*0 -> 0
AH19: =countif(C19:AF19,"P")+countif(C19:AF19,"H")*0.5+countif(C19:AF19,"A")*0 -> 0
AH20: =countif(C20:AF20,"P")+countif(C20:AF20,"H")*0.5+countif(C20:AF20,"A")*0 -> 0
A26: Total labour per day : | C26: =countif(C6:C21,"P")+countif(C6:C21,"H")*0.5+countif(C6:C21,"A")*0 -> 3.5 | D26: =countif(D6:D21,"P")+countif(D6:D21,"H")*0.5+countif(D6:D21,"A")*0 -> 8 | E26: =countif(E6:E21,"P")+countif(E6:E21,"H")*0.5+countif(E6:E21,"A")*0 -> 8 | F26: =countif(F6:F21,"P")+countif(F6:F21,"H")*0.5+countif(F6:F21,"A")*0 -> 8 | G26: =countif(G6:G21,"P")+countif(G6:G21,"H")*0.5+countif(G6:G21,"A")*0 -> 8 | H26: =countif(H6:H21,"P")+countif(H6:H21,"H")*0.5+countif(H6:H21,"A")*0 -> 8 | I26: =countif(I6:I21,"P")+countif(I6:I21,"H")*0.5+countif(I6:I21,"A")*0 -> 0 | J26: =countif(J6:J21,"P")+countif(J6:J21,"H")*0.5+countif(J6:J21,"A")*0 -> 7.5 | ... AE26: =countif(AE6:AE21,"P")+countif(AE6:AE21,"H")*0.5+countif(AE6:AE21,"A")*0 -> 7 | AG26: =sum(B26:AF26) -> 192
L52: June- OT
A54: Sl.no | B54: Labour Name : | C54: 1 | D54: 2 | E54: 3 | F54: 4 | G54: 5 | H54: 6 | I54: 7 | J54: 8 | K54: 9 | L54: 10 | M54: 11 | N54: 12 | O54: 13 | P54: 14 | Q54: 15 | R54: 16 | S54: 17 | T54: 18 | U54: 19 | V54: 20 | W54: 21 | X54: 22 | Y54: 23 | Z54: 24 | AA54: 25 | AB54: 26 | AC54: 27 | AD54: 28 | AE54: 29 | AF54: 30 | AH54: (Total)
C55: Mon | D55: Tue | E55: Wed | F55: Thu | G55: Fri | H55: Sat | I55: Sun | J55: Mon | K55: Tue | L55: Wed | M55: Thu | N55: Fri | O55: Sat | P55: Sun | Q55: Mon | R55: Tue | S55: Wed | T55: Thu | U55: Fri | V55: Sat | W55: Sun | X55: Mon | Y55: Tue | Z55: Wed | AA55: Thu | AB55: Fri | AC55: Sat | AD55: Sun | AE55: Mon | AF55: Tue
A56: 1 | B56: Pooja | C56: - | D56: 1 | E56: 1 | F56: - | G56: 1 | H56: - | I56: - | J56: 1 | K56: 1 | L56: 1 | M56: 1 | N56: 1 | O56: 1 | P56: - | Q56: 1 | R56: 1 | S56: 1 | T56: 1 | U56: 1 | V56: - | W56: - | X56: 1 | Y56: - | Z56: - | AA56: 1 | AB56: 1 | AC56: - | AD56: - | AE56: 1 | AF56: - | AH56: =countif(C56:AG56,"1")+countif(C56:AG56,"H")*0.5+countif(C56:AG56,"A")*0 -> 18
A57: 2 | B57: Kalpana | C57: - | D57: 1 | E57: 1 | F57: - | G57: 1 | H57: - | I57: - | J57: 1 | K57: 1 | L57: 1 | M57: 1 | N57: 1 | O57: 1 | P57: - | Q57: 1 | R57: A | S57: 1 | T57: 1 | U57: A | V57: - | W57: - | X57: 1 | Y57: - | Z57: - | AA57: 1 | AB57: A | AC57: - | AD57: - | AE57: 1 | AF57: - | AH57: =countif(C57:AG57,"1")+countif(C57:AG57,"H")*0.5+countif(C57:AG57,"A")*0 -> 15
A58: 3 | B58: Kavitha | C58: - | D58: 1 | E58: 1 | F58: - | G58: 1 | H58: - | I58: - | J58: 1 | K58: 1 | L58: 1 | M58: 1 | N58: 1 | O58: 1 | P58: - | Q58: 1 | R58: 1 | S58: 1 | T58: 1 | U58: 1 | V58: - | W58: - | X58: 1 | Y58: - | Z58: - | AA58: A | AB58: 1 | AC58: - | AD58: - | AE58: 1 | AF58: - | AH58: =countif(C58:AG58,"1")+countif(C58:AG58,"H")*0.5+countif(C58:AG58,"A")*0 -> 17
A59: 4 | B59: Shafiya | C59: - | D59: 1 | E59: 1 | F59: - | G59: 1 | H59: - | I59: - | J59: 1 | K59: 1 | L59: 1 | M59: 1 | N59: 1 | O59: 1 | P59: - | Q59: 1 | R59: 1 | S59: 1 | T59: 1 | U59: 1 | V59: - | W59: - | X59: 1 | Y59: - | Z59: - | AA59: 1 | AB59: 1 | AC59: - | AD59: - | AE59: 1 | AF59: - | AH59: =countif(C59:AG59,"1")+countif(C59:AG59,"H")*0.5+countif(C59:AG59,"A")*0 -> 18
A60: 5 | B60: Lakshmi | C60: - | D60: A | E60: A | F60: - | G60: A | H60: - | I60: - | J60: A | K60: 1 | L60: 1 | M60: 1 | N60: 1 | O60: 1 | P60: - | Q60: 1 | R60: A | S60: 1 | T60: 1 | U60: 1 | V60: - | W60: - | X60: 1 | Y60: - | Z60: - | AA60: 1 | AB60: A | AC60: - | AD60: - | AE60: 1 | AF60: - | AH60: =countif(C60:AG60,"1")+countif(C60:AG60,"H")*0.5+countif(C60:AG60,"A")*0 -> 12
A61: 6 | B61: Sagni devi | C61: - | D61: 1 | E61: 1 | F61: - | G61: 1 | H61: - | I61: - | J61: 1 | K61: A | L61: 1 | M61: 1 | N61: 1 | O61: 1 | P61: - | Q61: 1 | R61: 1 | S61: 1 | T61: 1 | U61: 1 | V61: - | W61: - | X61: 1 | Y61: - | Z61: - | AA61: 1 | AB61: 1 | AC61: - | AD61: - | AE61: 1 | AF61: - | AH61: =countif(C61:AG61,"1")+countif(C61:AG61,"H")*0.5+countif(C61:AG61,"A")*0 -> 17
A62: 7 | B62: Kamala | C62: - | D62: 1 | E62: 1 | F62: - | G62: 1 | H62: - | I62: - | J62: 1 | K62: 1 | L62: 1 | M62: 1 | N62: 1 | O62: 1 | P62: - | Q62: 1 | R62: 1 | S62: 1 | T62: 1 | U62: 1 | V62: - | W62: - | X62: 1 | Y62: - | Z62: - | AA62: 1 | AB62: 1 | AC62: - | AD62: - | AE62: A | AF62: - | AH62: =countif(C62:AG62,"1")+countif(C62:AG62,"H")*0.5+countif(C62:AG62,"A")*0 -> 17
A63: 8 | B63: Kanku Devi | C63: - | D63: A | E63: A | F63: - | G63: A | H63: - | I63: - | J63: A | K63: A | L63: A | M63: A | N63: A | O63: A | P63: - | Q63: A | R63: A | S63: A | T63: A | U63: A | V63: - | W63: - | X63: A | Y63: - | Z63: - | AA63: A | AB63: A | AC63: A | AD63: - | AE63: A | AF63: - | AH63: =countif(C63:AG63,"1")+countif(C63:AG63,"H")*0.5+countif(C63:AG63,"A")*0 -> 0
A64: 9 | B64: Bhagya | C64: - | D64: 1 | E64: 1 | F64: - | G64: 1 | H64: - | I64: - | J64: - | K64: A | L64: 1 | M64: 1 | N64: 1 | O64: 1 | P64: - | Q64: 1 | R64: A | S64: A | T64: A | U64: A | V64: - | W64: - | X64: A | Y64: - | Z64: - | AA64: A | AB64: A | AC64: A | AD64: - | AE64: A | AF64: - | AH64: =countif(C64:AG64,"1")+countif(C64:AG64,"H")*0.5+countif(C64:AG64,"A")*0 -> 8
A65: 10 | B65: Keli Devi | C65: - | D65: 1 | E65: 1 | F65: - | G65: 1 | H65: - | I65: - | J65: 1 | K65: 1 | L65: 1 | M65: 1 | N65: 1 | O65: 1 | P65: - | Q65: A | R65: A | S65: A | T65: A | U65: A | V65: - | W65: - | X65: A | Y65: - | Z65: - | AA65: 1 | AB65: 1 | AC65: - | AD65: - | AE65: 1 | AF65: - | AH65: =countif(C65:AG65,"1")+countif(C65:AG65,"H")*0.5+countif(C65:AG65,"A")*0 -> 12
AH66: =countif(C66:AG66,"1")+countif(C66:AG66,"H")*0.5+countif(C66:AG66,"A")*0 -> 0
AH67: =countif(C67:AG67,"1")+countif(C67:AG67,"H")*0.5+countif(C67:AG67,"A")*0 -> 0
AH68: =countif(C68:AG68,"1")+countif(C68:AG68,"H")*0.5+countif(C68:AG68,"A")*0 -> 0
AH69: =countif(C69:AG69,"1")+countif(C69:AG69,"H")*0.5+countif(C69:AG69,"A")*0 -> 0
B70: Overtime (OT) | AH70: =SUM(AH56:AH69) -> 134

Sheet July
L2: July
A4: Sl.no | B4: Labour Name : | C4: 1 | D4: 2 | E4: 3 | F4: 4 | G4: 5 | H4: 6 | I4: 7 | J4: 8 | K4: 9 | L4: 10 | M4: 11 | N4: 12 | O4: 13 | P4: 14 | Q4: 15 | R4: 16 | S4: 17 | T4: 18 | U4: 19 | V4: 20 | W4: 21 | X4: 22 | Y4: 23 | Z4: 24 | AA4: 25 | AB4: 26 | AC4: 27 | AD4: 28 | AE4: 29 | AF4: 30 | AG4: 31 | AH4: (Total)
C5: Wed | D5: Thu | E5: Fri | F5: Sat | G5: Sun | H5: Mon | I5: Tue | J5: Wed | K5: Thu | L5: Fri | M5: Sat | N5: Sun | O5: Mon | P5: Tue | Q5: Wed | R5: Thu | S5: Fri | T5: Sat | U5: Sun | V5: Mon | W5: Tue | X5: Wed | Y5: Thu | Z5: Fri | AA5: Sat | AB5: Sun | AC5: Mon | AD5: Tue | AE5: Wed | AF5: Thu | AG5: Fri
A6: 1 | B6: Pooja | C6: P | D6: L | E6: P | F6: P | G6: L | H6: P | I6: P | J6: P | K6: P | L6: P | M6: A | N6: L | O6: P | P6: P | Q6: P | R6: P | S6: P | T6: P | U6: L | V6: P | W6: P | X6: L | Y6: P | Z6: P | AA6: P | AB6: L | AC6: P | AD6: P | AE6: P | AF6: P | AG6: P | AH6: =countif(C6:AG6,"P")+countif(C6:AG6,"H")*0.5+countif(C6:AG6,"A")*0 -> 24
A7: 2 | B7: Kalpana | C7: P | D7: L | E7: A | F7: P | G7: L | H7: A | I7: P | J7: P | K7: P | L7: P | M7: A | N7: L | O7: P | P7: P | Q7: P | R7: P | S7: P | T7: P | U7: L | V7: P | W7: P | X7: L | Y7: P | Z7: P | AA7: P | AB7: L | AC7: P | AD7: P | AE7: P | AF7: P | AG7: P | AH7: =countif(C7:AG7,"P")+countif(C7:AG7,"H")*0.5+countif(C7:AG7,"A")*0 -> 22
A8: 3 | B8: Kavitha | C8: P | D8: L | E8: P | F8: P | G8: L | H8: P | I8: P | J8: P | K8: P | L8: P | M8: A | N8: L | O8: P | P8: P | Q8: P | R8: P | S8: P | T8: P | U8: L | V8: P | W8: P | X8: L | Y8: P | Z8: P | AA8: P | AB8: L | AC8: P | AD8: P | AE8: P | AF8: P | AG8: P | AH8: =countif(C8:AG8,"P")+countif(C8:AG8,"H")*0.5+countif(C8:AG8,"A")*0 -> 24
A9: 4 | B9: Shafiya | C9: P | D9: L | E9: P | F9: P | G9: L | H9: P | I9: P | J9: P | K9: P | L9: P | M9: A | N9: L | O9: P | P9: P | Q9: P | R9: P | S9: P | T9: P | U9: L | V9: P | W9: P | X9: L | Y9: P | Z9: P | AA9: P | AB9: L | AC9: P | AD9: P | AE9: P | AF9: P | AG9: P | AH9: =countif(C9:AG9,"P")+countif(C9:AG9,"H")*0.5+countif(C9:AG9,"A")*0 -> 24
A10: 5 | B10: Lakshmi | C10: P | D10: L | E10: A | F10: P | G10: L | H10: P | I10: P | J10: P | K10: P | L10: P | M10: A | N10: L | O10: P | P10: P | Q10: P | R10: P | S10: P | T10: P | U10: L | V10: A | W10: P | X10: L | Y10: P | Z10: P | AA10: P | AB10: L | AC10: P | AD10: P | AE10: P | AF10: P | AG10: P | AH10: =countif(C10:AG10,"P")+countif(C10:AG10,"H")*0.5+countif(C10:AG10,"A")*0 -> 22
A11: 6 | B11: Sagni devi | C11: P | D11: L | E11: P | F11: P | G11: L | H11: P | I11: P | J11: P | K11: P | L11: P | M11: A | N11: L | O11: P | P11: P | Q11: P | R11: P | S11: H | T11: P | U11: L | V11: P | W11: P | X11: L | Y11: P | Z11: P | AA11: P | AB11: L | AC11: P | AD11: P | AE11: P | AF11: P | AG11: P | AH11: =countif(C11:AG11,"P")+countif(C11:AG11,"H")*0.5+countif(C11:AG11,"A")*0 -> 23.5
A12: 7 | B12: Kamala | C12: P | D12: L | E12: P | F12: P | G12: L | H12: P | I12: P | J12: P | K12: P | L12: P | M12: A | N12: L | O12: P | P12: P | Q12: P | R12: P | S12: P | T12: P | U12: L | V12: P | W12: P | X12: L | Y12: P | Z12: P | AA12: P | AB12: L | AC12: P | AD12: P | AE12: P | AF12: P | AG12: P | AH12: =countif(C12:AG12,"P")+countif(C12:AG12,"H")*0.5+countif(C12:AG12,"A")*0 -> 24
A13: 8 | B13: Kanku Devi | C13: P | D13: L | E13: P | F13: P | G13: L | H13: P | I13: P | J13: P | K13: P | L13: P | M13: A | N13: L | O13: P | P13: P | Q13: A | R13: A | S13: A | T13: A | U13: L | V13: P | W13: P | X13: L | Y13: P | Z13: P | AA13: P | AB13: L | AC13: P | AD13: P | AE13: P | AF13: P | AG13: P | AH13: =countif(C13:AG13,"P")+countif(C13:AG13,"H")*0.5+countif(C13:AG13,"A")*0 -> 20
A14: 9 | B14: Keli Devi | C14: P | D14: L | E14: P | F14: P | G14: L | H14: P | I14: P | J14: P | K14: P | L14: P | M14: A | N14: L | O14: P | P14: P | Q14: P | R14: P | S14: P | T14: P | U14: L | V14: P | W14: P | X14: L | Y14: P | Z14: P | AA14: P | AB14: L | AC14: P | AD14: P | AE14: P | AF14: P | AG14: P | AH14: =countif(C14:AG14,"P")+countif(C14:AG14,"H")*0.5+countif(C14:AG14,"A")*0 -> 24
A15: 10 | AH15: =countif(C15:AF15,"P")+countif(C15:AF15,"H")*0.5+countif(C15:AF15,"A")*0 -> 0
AH16: =countif(C16:AF16,"P")+countif(C16:AF16,"H")*0.5+countif(C16:AF16,"A")*0 -> 0
AH17: =countif(C17:AF17,"P")+countif(C17:AF17,"H")*0.5+countif(C17:AF17,"A")*0 -> 0
AH18: =countif(C18:AF18,"P")+countif(C18:AF18,"H")*0.5+countif(C18:AF18,"A")*0 -> 0
AH19: =countif(C19:AF19,"P")+countif(C19:AF19,"H")*0.5+countif(C19:AF19,"A")*0 -> 0
AH20: =countif(C20:AF20,"P")+countif(C20:AF20,"H")*0.5+countif(C20:AF20,"A")*0 -> 0
A26: Total labour per day : | C26: =countif(C6:C21,"P")+countif(C6:C21,"H")*0.5+countif(C6:C21,"A")*0 -> 9 | D26: =countif(D6:D21,"P")+countif(D6:D21,"H")*0.5+countif(D6:D21,"A")*0 -> 0 | E26: =countif(E6:E21,"P")+countif(E6:E21,"H")*0.5+countif(E6:E21,"A")*0 -> 7 | F26: =countif(F6:F21,"P")+countif(F6:F21,"H")*0.5+countif(F6:F21,"A")*0 -> 9 | G26: =countif(G6:G21,"P")+countif(G6:G21,"H")*0.5+countif(G6:G21,"A")*0 -> 0 | H26: =countif(H6:H21,"P")+countif(H6:H21,"H")*0.5+countif(H6:H21,"A")*0 -> 8 | I26: =countif(I6:I21,"P")+countif(I6:I21,"H")*0.5+countif(I6:I21,"A")*0 -> 9 | J26: =countif(J6:J21,"P")+countif(J6:J21,"H")*0.5+countif(J6:J21,"A")*0 -> 9 | ... AE26: =countif(AE6:AE21,"P")+countif(AE6:AE21,"H")*0.5+countif(AE6:AE21,"A")*0 -> 9 | AH26: =sum(B26:AF26) -> 189.5
L31: July- OT
A33: Sl.no | B33: Labour Name : | C33: 1 | D33: 2 | E33: 3 | F33: 4 | G33: 5 | H33: 6 | I33: 7 | J33: 8 | K33: 9 | L33: 10 | M33: 11 | N33: 12 | O33: 13 | P33: 14 | Q33: 15 | R33: 16 | S33: 17 | T33: 18 | U33: 19 | V33: 20 | W33: 21 | X33: 22 | Y33: 23 | Z33: 24 | AA33: 25 | AB33: 26 | AC33: 27 | AD33: 28 | AE33: 29 | AF33: 30 | AG33: 31 | AH33: (Total)
C34: Wed | D34: Thu | E34: Fri | F34: Sat | G34: Sun | H34: Mon | I34: Tue | J34: Wed | K34: Thu | L34: Fri | M34: Sat | N34: Sun | O34: Mon | P34: Tue | Q34: Wed | R34: Thu | S34: Fri | T34: Sat | U34: Sun | V34: Mon | W34: Tue | X34: Wed | Y34: Thu | Z34: Fri | AA34: Sat | AB34: Sun | AC34: Mon | AD34: Tue | AE34: Wed | AF34: Thu | AG34: Fri
A35: 1 | B35: Pooja | C35: - | D35: L | E35: - | F35: 1 | G35: L | H35: 1 | I35: 1 | J35: 1 | K35: 1 | L35: - | M35: A | N35: L | O35: - | P35: - | Q35: - | R35: - | S35: - | T35: - | U35: A | V35: - | W35: - | X35: L | Y35: - | Z35: - | AA35: - | AB35: L | AC35: - | AD35: - | AE35: - | AF35: - | AG35: - | AH35: =countif(C35:AG35,"1")+countif(C35:AG35,"H")*0.5+countif(C35:AG35,"A")*0 -> 5
A36: 2 | B36: Kalpana | C36: - | D36: L | E36: A | F36: 1 | G36: L | H36: A | I36: 1 | J36: 1 | K36: 1 | L36: - | M36: A | N36: L | O36: - | P36: - | Q36: - | R36: - | S36: - | T36: - | U36: A | V36: - | W36: - | X36: L | Y36: - | Z36: - | AA36: - | AB36: L | AC36: - | AD36: - | AE36: - | AF36: - | AG36: - | AH36: =countif(C36:AG36,"1")+countif(C36:AG36,"H")*0.5+countif(C36:AG36,"A")*0 -> 4
A37: 3 | B37: Kavitha | C37: - | D37: L | E37: - | F37: 1 | G37: L | H37: 1 | I37: 1 | J37: 1 | K37: 1 | L37: - | M37: A | N37: L | O37: - | P37: - | Q37: - | R37: - | S37: - | T37: - | U37: A | V37: - | W37: - | X37: L | Y37: - | Z37: - | AA37: - | AB37: L | AC37: - | AD37: - | AE37: - | AF37: - | AG37: - | AH37: =countif(C37:AG37,"1")+countif(C37:AG37,"H")*0.5+countif(C37:AG37,"A")*0 -> 5
A38: 4 | B38: Shafiya | C38: - | D38: L | E38: - | F38: 1 | G38: L | H38: 1 | I38: 1 | J38: 1 | K38: 1 | L38: - | M38: A | N38: L | O38: - | P38: - | Q38: - | R38: - | S38: - | T38: - | U38: A | V38: - | W38: - | X38: L | Y38: - | Z38: - | AA38: - | AB38: L | AC38: - | AD38: - | AE38: - | AF38: - | AG38: - | AH38: =countif(C38:AG38,"1")+countif(C38:AG38,"H")*0.5+countif(C38:AG38,"A")*0 -> 5
A39: 5 | B39: Lakshmi | C39: - | D39: L | E39: A | F39: 1 | G39: L | H39: 1 | I39: 1 | J39: 1 | K39: 1 | L39: - | M39: A | N39: L | O39: - | P39: - | Q39: - | R39: - | S39: - | T39: - | U39: A | V39: A | W39: - | X39: L | Y39: - | Z39: - | AA39: - | AB39: L | AC39: - | AD39: - | AE39: - | AF39: - | AG39: - | AH39: =countif(C39:AG39,"1")+countif(C39:AG39,"H")*0.5+countif(C39:AG39,"A")*0 -> 5
A40: 6 | B40: Sagni devi | C40: - | D40: L | E40: - | F40: 1 | G40: L | H40: 1 | I40: 1 | J40: 1 | K40: 1 | L40: - | M40: A | N40: L | O40: - | P40: - | Q40: - | R40: - | S40: - | T40: - | U40: A | V40: - | W40: - | X40: L | Y40: - | Z40: - | AA40: - | AB40: L | AC40: - | AD40: - | AE40: - | AF40: - | AG40: - | AH40: =countif(C40:AG40,"1")+countif(C40:AG40,"H")*0.5+countif(C40:AG40,"A")*0 -> 5
A41: 7 | B41: Kamala | C41: - | D41: L | E41: - | F41: 1 | G41: L | H41: 1 | I41: 1 | J41: 1 | K41: 1 | L41: - | M41: A | N41: L | O41: - | P41: - | Q41: - | R41: - | S41: - | T41: - | U41: A | V41: - | W41: - | X41: L | Y41: - | Z41: - | AA41: - | AB41: L | AC41: - | AD41: - | AE41: - | AF41: - | AG41: - | AH41: =countif(C41:AG41,"1")+countif(C41:AG41,"H")*0.5+countif(C41:AG41,"A")*0 -> 5
A42: 8 | B42: Kanku Devi | C42: - | D42: L | E42: - | F42: 1 | G42: L | H42: 1 | I42: 1 | J42: 1 | K42: 1 | L42: - | M42: A | N42: L | O42: - | P42: - | Q42: A | R42: A | S42: A | T42: A | U42: A | V42: - | W42: - | X42: L | Y42: - | Z42: - | AA42: - | AB42: L | AC42: - | AD42: - | AE42: - | AF42: - | AG42: - | AH42: =countif(C42:AG42,"1")+countif(C42:AG42,"H")*0.5+countif(C42:AG42,"A")*0 -> 5
A43: 9 | B43: Keli Devi | C43: - | D43: L | E43: - | F43: 1 | G43: L | H43: 1 | I43: 1 | J43: 1 | K43: 1 | L43: - | M43: A | N43: L | O43: - | P43: - | Q43: - | R43: - | S43: - | T43: - | U43: A | V43: - | W43: - | X43: L | Y43: - | Z43: - | AA43: - | AB43: L | AC43: - | AD43: - | AE43: - | AF43: - | AG43: - | AH43: =countif(C43:AG43,"1")+countif(C43:AG43,"H")*0.5+countif(C43:AG43,"A")*0 -> 5
AH44: =countif(C44:AG44,"1")+countif(C44:AG44,"H")*0.5+countif(C44:AG44,"A")*0 -> 0
AH45: =countif(C45:AG45,"1")+countif(C45:AG45,"H")*0.5+countif(C45:AG45,"A")*0 -> 0
AH46: =countif(C46:AG46,"1")+countif(C46:AG46,"H")*0.5+countif(C46:AG46,"A")*0 -> 0
AH47: =countif(C47:AG47,"1")+countif(C47:AG47,"H")*0.5+countif(C47:AG47,"A")*0 -> 0
B48: Overtime (OT) | AH48: =SUM(AH35:AH47) -> 44

Sheet August
L2: August
A4: Sl.no | B4: Labour Name : | C4: 1 | D4: 2 | E4: 3 | F4: 4 | G4: 5 | H4: 6 | I4: 7 | J4: 8 | K4: 9 | L4: 10 | M4: 11 | N4: 12 | O4: 13 | P4: 14 | Q4: 15 | R4: 16 | S4: 17 | T4: 18 | U4: 19 | V4: 20 | W4: 21 | X4: 22 | Y4: 23 | Z4: 24 | AA4: 25 | AB4: 26 | AC4: 27 | AD4: 28 | AE4: 29 | AF4: 30 | AG4: 31 | AH4: (Total)
C5: Sat | D5: Sun | E5: Mon | F5: Tue | G5: Wed | H5: Thu | I5: Fri | J5: Sat | K5: Sun | L5: Mon | M5: Tue | N5: Wed | O5: Thu | P5: Fri | Q5: Sat | R5: Sun | S5: Mon | T5: Tue | U5: Wed | V5: Thu | W5: Fri | X5: Sat | Y5: Sun | Z5: Mon | AA5: Tue | AB5: Wed | AC5: Thu | AD5: Fri | AE5: Sat | AF5: Sun | AG5: Mon
A6: 1 | B6: Pooja | C6: L | D6: L | E6: P | F6: P | G6: P | H6: P | I6: P | J6: P | K6: L | L6: P | M6: P | N6: P | O6: P | P6: P | Q6: L | R6: L | S6: P | T6: P | U6: P | V6: A | W6: A | X6: P | Y6: L | Z6: P | AA6: P | AB6: P | AC6: P | AD6: P | AE6: P | AF6: L | AG6: P | AH6: =countif(C6:AG6,"P")+countif(C6:AG6,"H")*0.5+countif(C6:AG6,"A")*0 -> 22
A7: 2 | B7: Kalpana | C7: L | D7: L | E7: P | F7: P | G7: P | H7: P | I7: P | J7: P | K7: L | L7: P | M7: P | N7: P | O7: P | P7: P | Q7: L | R7: L | S7: P | T7: P | U7: P | V7: A | W7: A | X7: P | Y7: L | Z7: P | AA7: P | AB7: P | AC7: P | AD7: P | AE7: P | AF7: L | AG7: P | AH7: =countif(C7:AG7,"P")+countif(C7:AG7,"H")*0.5+countif(C7:AG7,"A")*0 -> 22
A8: 3 | B8: Kavitha | C8: L | D8: L | E8: P | F8: P | G8: P | H8: H | I8: P | J8: P | K8: L | L8: P | M8: P | N8: P | O8: P | P8: P | Q8: L | R8: L | S8: P | T8: P | U8: P | V8: A | W8: A | X8: P | Y8: L | Z8: A | AA8: P | AB8: P | AC8: P | AD8: P | AE8: P | AF8: L | AG8: P | AH8: =countif(C8:AG8,"P")+countif(C8:AG8,"H")*0.5+countif(C8:AG8,"A")*0 -> 20.5
A9: 4 | B9: Shafiya | C9: L | D9: L | E9: P | F9: P | G9: P | H9: P | I9: P | J9: P | K9: L | L9: P | M9: P | N9: P | O9: P | P9: P | Q9: L | R9: L | S9: P | T9: P | U9: P | V9: A | W9: A | X9: P | Y9: L | Z9: P | AA9: P | AB9: P | AC9: P | AD9: P | AE9: P | AF9: L | AG9: P | AH9: =countif(C9:AG9,"P")+countif(C9:AG9,"H")*0.5+countif(C9:AG9,"A")*0 -> 22
A10: 5 | B10: Lakshmi | C10: - | D10: - | E10: - | F10: - | G10: - | H10: - | I10: - | J10: - | K10: - | L10: - | M10: - | N10: - | O10: - | P10: - | Q10: - | R10: - | S10: - | T10: - | U10: - | V10: - | W10: - | X10: - | Y10: - | Z10: - | AA10: - | AB10: - | AC10: - | AD10: - | AE10: - | AF10: - | AG10: - | AH10: =countif(C10:AG10,"P")+countif(C10:AG10,"H")*0.5+countif(C10:AG10,"A")*0 -> 0
A11: 6 | B11: Sagni devi | C11: L | D11: L | E11: P | F11: P | G11: P | H11: P | I11: P | J11: P | K11: L | L11: P | M11: A | N11: P | O11: P | P11: P | Q11: L | R11: L | S11: P | T11: P | U11: P | V11: P | W11: P | X11: P | Y11: L | Z11: P | AA11: P | AB11: P | AC11: P | AD11: P | AE11: P | AF11: L | AG11: P | AH11: =countif(C11:AG11,"P")+countif(C11:AG11,"H")*0.5+countif(C11:AG11,"A")*0 -> 23
A12: 7 | B12: Kamala | C12: L | D12: L | E12: P | F12: P | G12: P | H12: P | I12: P | J12: P | K12: L | L12: P | M12: P | N12: P | O12: P | P12: P | Q12: L | R12: L | S12: P | T12: P | U12: P | V12: P | W12: P | X12: P | Y12: L | Z12: P | AA12: A | AB12: P | AC12: P | AD12: P | AE12: P | AF12: L | AG12: P | AH12: =countif(C12:AG12,"P")+countif(C12:AG12,"H")*0.5+countif(C12:AG12,"A")*0 -> 23
A13: 8 | B13: Kanku Devi | C13: L | D13: L | E13: P | F13: P | G13: P | H13: P | I13: P | J13: P | K13: L | L13: P | M13: P | N13: A | O13: P | P13: P | Q13: L | R13: L | S13: P | T13: P | U13: P | V13: P | W13: P | X13: P | Y13: L | Z13: A | AA13: P | AB13: P | AC13: P | AD13: P | AE13: P | AF13: L | AG13: A | AH13: =countif(C13:AG13,"P")+countif(C13:AG13,"H")*0.5+countif(C13:AG13,"A")*0 -> 21
A14: 9 | B14: Keli Devi | C14: L | D14: L | E14: P | F14: P | G14: P | H14: P | I14: P | J14: P | K14: L | L14: P | M14: P | N14: P | O14: P | P14: P | Q14: L | R14: L | S14: P | T14: P | U14: P | V14: P | W14: P | X14: P | Y14: L | Z14: P | AA14: P | AB14: A | AC14: P | AD14: A | AE14: A | AF14: L | AG14: A | AH14: =countif(C14:AG14,"P")+countif(C14:AG14,"H")*0.5+countif(C14:AG14,"A")*0 -> 20
A15: 10 | AH15: =countif(C15:AG15,"P")+countif(C15:AG15,"H")*0.5+countif(C15:AG15,"A")*0 -> 0
A16: 11 | AH16: =countif(C16:AG16,"P")+countif(C16:AG16,"H")*0.5+countif(C16:AG16,"A")*0 -> 0
A17: 12 | AH17: =countif(C17:AG17,"P")+countif(C17:AG17,"H")*0.5+countif(C17:AG17,"A")*0 -> 0
A18: 13 | AH18: =countif(C18:AG18,"P")+countif(C18:AG18,"H")*0.5+countif(C18:AG18,"A")*0 -> 0
A19: 14 | AH19: =countif(C19:AG19,"P")+countif(C19:AG19,"H")*0.5+countif(C19:AG19,"A")*0 -> 0
A20: 15 | AH20: =countif(C20:AG20,"P")+countif(C20:AG20,"H")*0.5+countif(C20:AG20,"A")*0 -> 0
A23: Total labour per day : | C23: =countif(C3:C18,"P")+countif(C3:C18,"H")*0.5+countif(C3:C18,"A")*0 -> 0 | D23: =countif(D3:D18,"P")+countif(D3:D18,"H")*0.5+countif(D3:D18,"A")*0 -> 0 | E23: =countif(E3:E18,"P")+countif(E3:E18,"H")*0.5+countif(E3:E18,"A")*0 -> 8 | F23: =countif(F3:F18,"P")+countif(F3:F18,"H")*0.5+countif(F3:F18,"A")*0 -> 8 | G23: =countif(G3:G18,"P")+countif(G3:G18,"H")*0.5+countif(G3:G18,"A")*0 -> 8 | H23: =countif(H3:H18,"P")+countif(H3:H18,"H")*0.5+countif(H3:H18,"A")*0 -> 7.5 | I23: =countif(I3:I18,"P")+countif(I3:I18,"H")*0.5+countif(I3:I18,"A")*0 -> 8 | J23: =countif(J3:J18,"P")+countif(J3:J18,"H")*0.5+countif(J3:J18,"A")*0 -> 8 | ... AE23: =countif(AE3:AE18,"P")+countif(AE3:AE18,"H")*0.5+countif(AE3:AE18,"A")*0 -> 7 | AH23: =sum(B23:AF23) -> 167.5

Sheet September 
A1: =AG13
L2: September
A4: Sl.no | B4: Labour Name : | C4: 1 | D4: 2 | E4: 3 | F4: 4 | G4: 5 | H4: 6 | I4: 7 | J4: 8 | K4: 9 | L4: 10 | M4: 11 | N4: 12 | O4: 13 | P4: 14 | Q4: 15 | R4: 16 | S4: 17 | T4: 18 | U4: 19 | V4: 20 | W4: 21 | X4: 22 | Y4: 23 | Z4: 24 | AA4: 25 | AB4: 26 | AC4: 27 | AD4: 28 | AE4: 29 | AF4: 30 | AH4: (Total)
C5: Tue | D5: Wed | E5: Thu | F5: Fri | G5: Sat | H5: Sun | I5: Mon | J5: Tue | K5: Wed | L5: Thu | M5: Fri | N5: Sat | O5: Sun | P5: Mon | Q5: Tue | R5: Wed | S5: Thu | T5: Fri | U5: Sat | V5: Sun | W5: Mon | X5: Tue | Y5: Wed | Z5: Thu | AA5: Fri | AB5: Sat | AC5: Sun | AD5: Mon | AE5: Tue | AF5: Wed
A6: 1 | B6: Pooja | C6: P | D6: P | E6: P | F6: P | G6: P | H6: P | I6: P | J6: P | K6: P | L6: P | M6: P | N6: P | O6: L | P6: L | Q6: P | R6: P | S6: P | T6: P | U6: H | V6: L | W6: P | X6: P | Y6: P | Z6: P | AA6: P | AB6: P | AC6: L | AD6: P | AE6: P | AF6: P | AH6: =countif(C6:AG6,"P")+countif(C6:AG6,"H")*0.5+countif(C6:AG6,"A")*0 -> 25.5
A7: 2 | B7: Kalpana | C7: P | D7: P | E7: P | F7: P | G7: P | H7: P | I7: P | J7: P | K7: P | L7: P | M7: P | N7: P | O7: L | P7: L | Q7: P | R7: P | S7: P | T7: P | U7: H | V7: L | W7: P | X7: P | Y7: P | Z7: P | AA7: H | AB7: P | AC7: L | AD7: P | AE7: P | AF7: P | AH7: =countif(C7:AG7,"P")+countif(C7:AG7,"H")*0.5+countif(C7:AG7,"A")*0 -> 25
A8: 3 | B8: Kavitha | C8: P | D8: P | E8: P | F8: P | G8: P | H8: P | I8: P | J8: P | K8: P | L8: P | M8: P | N8: P | O8: L | P8: L | Q8: P | R8: P | S8: P | T8: P | U8: H | V8: L | W8: P | X8: P | Y8: P | Z8: P | AA8: A | AB8: A | AC8: L | AD8: P | AE8: P | AF8: P | AH8: =countif(C8:AG8,"P")+countif(C8:AG8,"H")*0.5+countif(C8:AG8,"A")*0 -> 23.5
A9: 4 | B9: Shafiya | C9: P | D9: P | E9: P | F9: P | G9: P | H9: P | I9: P | J9: P | K9: P | L9: P | M9: P | N9: P | O9: L | P9: L | Q9: P | R9: P | S9: P | T9: P | U9: H | V9: L | W9: P | X9: A | Y9: P | Z9: P | AA9: P | AB9: P | AC9: L | AD9: P | AE9: P | AF9: P | AH9: =countif(C9:AG9,"P")+countif(C9:AG9,"H")*0.5+countif(C9:AG9,"A")*0 -> 24.5
A10: 5 | B10: Sagni devi | C10: P | D10: P | E10: P | F10: P | G10: P | H10: P | I10: P | J10: P | K10: P | L10: P | M10: P | N10: P | O10: L | P10: L | Q10: P | R10: P | S10: P | T10: P | U10: H | V10: L | W10: P | X10: A | Y10: P | Z10: P | AA10: P | AB10: P | AC10: L | AD10: P | AE10: P | AF10: P | AH10: =countif(C10:AG10,"P")+countif(C10:AG10,"H")*0.5+countif(C10:AG10,"A")*0 -> 24.5
A11: 6 | B11: Kamala | C11: P | D11: P | E11: P | F11: P | G11: A | H11: P | I11: P | J11: A | K11: P | L11: P | M11: P | N11: P | O11: L | P11: L | Q11: P | R11: P | S11: P | T11: P | U11: H | V11: L | W11: P | X11: A | Y11: P | Z11: P | AA11: P | AB11: P | AC11: L | AD11: P | AE11: P | AF11: P | AH11: =countif(C11:AG11,"P")+countif(C11:AG11,"H")*0.5+countif(C11:AG11,"A")*0 -> 22.5
A12: 7 | B12: Kanku Devi | C12: P | D12: P | E12: P | F12: A | G12: A | H12: A | I12: A | J12: A | K12: A | L12: P | M12: P | N12: P | O12: L | P12: L | Q12: P | R12: P | S12: A | T12: P | U12: H | V12: L | W12: H | X12: A | Y12: P | Z12: P | AA12: P | AB12: P | AC12: L | AD12: P | AE12: P | AF12: P | AH12: =countif(C12:AG12,"P")+countif(C12:AG12,"H")*0.5+countif(C12:AG12,"A")*0 -> 17
A13: 8 | B13: Keli Devi | C13: A | D13: A | E13: A | F13: A | G13: P | H13: P | I13: P | J13: P | K13: P | L13: P | M13: P | N13: P | O13: L | P13: L | Q13: P | R13: P | S13: P | T13: P | U13: H | V13: L | W13: P | X13: A | Y13: P | Z13: P | AA13: P | AB13: P | AC13: L | AD13: P | AE13: P | AF13: P | AH13: =countif(C13:AG13,"P")+countif(C13:AG13,"H")*0.5+countif(C13:AG13,"A")*0 -> 20.5
A14: 9 | B14: Manjula | C14: - | D14: - | E14: - | F14: - | G14: - | H14: - | I14: - | J14: - | K14: - | L14: - | M14: - | N14: - | O14: - | P14: - | Q14: - | R14: P | S14: P | T14: P | U14: H | V14: L | W14: P | X14: P | Y14: P | Z14: P | AA14: P | AB14: P | AC14: L | AD14: P | AE14: P | AF14: P | AH14: =countif(C14:AG14,"P")+countif(C14:AG14,"H")*0.5+countif(C14:AG14,"A")*0 -> 12.5
A15: 10 | B15: Kuki Devi | C15: - | D15: - | E15: - | F15: - | G15: - | H15: - | I15: - | J15: - | K15: - | L15: - | M15: - | N15: - | O15: - | P15: - | Q15: - | R15: - | S15: - | T15: P | U15: H | V15: L | W15: P | X15: A | Y15: P | Z15: P | AA15: P | AB15: P | AC15: L | AD15: P | AE15: P | AF15: P | AH15: =countif(C15:AG15,"P")+countif(C15:AG15,"H")*0.5+countif(C15:AG15,"A")*0 -> 9.5
A16: 11 | AH16: =countif(C16:AG16,"P")+countif(C16:AG16,"H")*0.5+countif(C16:AG16,"A")*0 -> 0
A17: 12 | AH17: =countif(C17:AG17,"P")+countif(C17:AG17,"H")*0.5+countif(C17:AG17,"A")*0 -> 0
A18: 13 | AH18: =countif(C18:AG18,"P")+countif(C18:AG18,"H")*0.5+countif(C18:AG18,"A")*0 -> 0
A19: 14 | AH19: =countif(C19:AG19,"P")+countif(C19:AG19,"H")*0.5+countif(C19:AG19,"A")*0 -> 0
A20: 15 | AH20: =countif(C20:AG20,"P")+countif(C20:AG20,"H")*0.5+countif(C20:AG20,"A")*0 -> 0
A23: Total labour per day : | C23: =countif(C3:C18,"P")+countif(C3:C18,"H")*0.5+countif(C3:C18,"A")*0 -> 7 | D23: =countif(D3:D18,"P")+countif(D3:D18,"H")*0.5+countif(D3:D18,"A")*0 -> 7 | E23: =countif(E3:E18,"P")+countif(E3:E18,"H")*0.5+countif(E3:E18,"A")*0 -> 7 | F23: =countif(F3:F18,"P")+countif(F3:F18,"H")*0.5+countif(F3:F18,"A")*0 -> 6 | G23: =countif(G3:G18,"P")+countif(G3:G18,"H")*0.5+countif(G3:G18,"A")*0 -> 6 | H23: =countif(H3:H18,"P")+countif(H3:H18,"H")*0.5+countif(H3:H18,"A")*0 -> 7 | I23: =countif(I3:I18,"P")+countif(I3:I18,"H")*0.5+countif(I3:I18,"A")*0 -> 7 | J23: =countif(J3:J18,"P")+countif(J3:J18,"H")*0.5+countif(J3:J18,"A")*0 -> 6 | ... AE23: =countif(AE3:AE18,"P")+countif(AE3:AE18,"H")*0.5+countif(AE3:AE18,"A")*0 -> 10 | AH23: =sum(B23:AF23) -> 195

Sheet October 
L2: October
A4: Sl.no | B4: Labour Name : | C4: 1 | D4: 2 | E4: 3 | F4: 4 | G4: 5 | H4: 6 | I4: 7 | J4: 8 | K4: 9 | L4: 10 | M4: 11 | N4: 12 | O4: 13 | P4: 14 | Q4: 15 | R4: 16 | S4: 17 | T4: 18 | U4: 19 | V4: 20 | W4: 21 | X4: 22 | Y4: 23 | Z4: 24 | AA4: 25 | AB4: 26 | AC4: 27 | AD4: 28 | AE4: 29 | AF4: 30 | AG4: 31 | AH4: (Total)
C5: Thu | D5: Fri | E5: Sat | F5: Sun | G5: Mon | H5: Tue | I5: Wed | J5: Thu | K5: Fri | L5: Sat | M5: Sun | N5: Mon | O5: Tue | P5: Wed | Q5: Thu | R5: Fri | S5: Sat | T5: Sun | U5: Mon | V5: Tue | W5: Wed | X5: Thu | Y5: Fri | Z5: Sat | AA5: Sun | AB5: Mon | AC5: Tue | AD5: Wed | AE5: Thu | AF5: Fri | AG5: Sat
A6: 1 | B6: Pooja | C6: P | D6: L | E6: P | F6: L | G6: P | H6: P | AH6: =countif(C6:AG6,"P")+countif(C6:AG6,"H")*0.5+countif(C6:AG6,"A")*0 -> 4
A7: 2 | B7: Kalpana | C7: P | D7: L | E7: P | F7: L | G7: P | H7: P | AH7: =countif(C7:AG7,"P")+countif(C7:AG7,"H")*0.5+countif(C7:AG7,"A")*0 -> 4
A8: 3 | B8: Kavitha | C8: P | D8: L | E8: P | F8: L | G8: P | H8: P | AH8: =countif(C8:AG8,"P")+countif(C8:AG8,"H")*0.5+countif(C8:AG8,"A")*0 -> 4
A9: 4 | B9: Shafiya | C9: P | D9: L | E9: P | F9: L | G9: P | H9: P | AH9: =countif(C9:AG9,"P")+countif(C9:AG9,"H")*0.5+countif(C9:AG9,"A")*0 -> 4
A10: 5 | B10: Sagni devi | C10: P | D10: L | E10: P | F10: L | G10: P | H10: P | AH10: =countif(C10:AG10,"P")+countif(C10:AG10,"H")*0.5+countif(C10:AG10,"A")*0 -> 4
A11: 6 | B11: Kamala | C11: P | D11: L | E11: P | F11: L | G11: P | H11: P | AH11: =countif(C11:AG11,"P")+countif(C11:AG11,"H")*0.5+countif(C11:AG11,"A")*0 -> 4
A12: 7 | B12: Kanku Devi | C12: P | D12: L | E12: P | F12: L | G12: P | H12: P | AH12: =countif(C12:AG12,"P")+countif(C12:AG12,"H")*0.5+countif(C12:AG12,"A")*0 -> 4
A13: 8 | B13: Keli Devi | C13: P | D13: L | E13: P | F13: L | G13: P | H13: P | AH13: =countif(C13:AG13,"P")+countif(C13:AG13,"H")*0.5+countif(C13:AG13,"A")*0 -> 4
A14: 9 | B14: Manjula | C14: P | D14: L | E14: A | F14: L | G14: A | H14: P | AH14: =countif(C14:AG14,"P")+countif(C14:AG14,"H")*0.5+countif(C14:AG14,"A")*0 -> 2
