Workbook

Sheet Daily Tracking
A1: Date | B1: Product Type | C1: Total Production (kg) | D1: Solvent Before (g) | E1: Solvent After (g) | F1: Solvent Used (g) | G1: Solvent / kg (MG) | H1: Ink Before (g) | I1: Ink After (g) | J1: Ink Used (g) | K1: Ink / kg (MG) | L1: Remarks
A2: 06-Aug-2026 | B2: Braider | C2: 418.4 | D2: 217.2 | E2: 161.9 | F2: =IF(OR(D2="",E2=""),"",D2-E2) -> 55.3 | G2: =IF(OR(C2="",F2=""),"",F2/C2) -> 0.13217017 | H2: 689 | I2: 689 | J2: =IF(OR(H2="",I2=""),"",H2-I2) -> 0 | K2: =IF(OR(C2="",J2=""),"",J2/C2) -> 0
A3: 07-Aug-2026 | B3: Braider | C3: 420 | D3: 161.9 | E3: 120 | F3: =IF(OR(D3="",E3=""),"",D3-E3) -> 41.9 | G3: =IF(OR(C3="",F3=""),"",F3/C3) -> 0.099761905 | H3: 689 | I3: 688 | J3: =IF(OR(H3="",I3=""),"",H3-I3) -> 1 | K3: =IF(OR(C3="",J3=""),"",J3/C3) -> 0.0023809524
A4: 46242 | B4: Tubing | C4: 292.4 | D4: 681 | E4: 627 | F4: =IF(OR(D4="",E4=""),"",D4-E4) -> 54 | G4: =IF(OR(C4="",F4=""),"",F4/C4) -> 0.18467852 | H4: 688 | I4: 688 | J4: =IF(OR(H4="",I4=""),"",H4-I4) -> 0 | K4: =IF(OR(C4="",J4=""),"",J4/C4) -> 0 | L4: New bottel solvent
A5: 46244 | B5: Tubing | C5: 220 | D5: 627 | E5: 562 | F5: =IF(OR(D5="",E5=""),"",D5-E5) -> 65 | G5: =IF(OR(C5="",F5=""),"",F5/C5) -> 0.29545455 | H5: 688 | I5: 687 | J5: =IF(OR(H5="",I5=""),"",H5-I5) -> 1 | K5: =IF(OR(C5="",J5=""),"",J5/C5) -> 0.0045454545
A6: 46245 | B6: Braider | C6: 315 | D6: 562 | E6: 488 | F6: =IF(OR(D6="",E6=""),"",D6-E6) -> 74 | G6: =IF(OR(C6="",F6=""),"",F6/C6) -> 0.23492063 | H6: 687 | I6: 686 | J6: =IF(OR(H6="",I6=""),"",H6-I6) -> 1 | K6: =IF(OR(C6="",J6=""),"",J6/C6) -> 0.0031746032
A7: 46246 | B7: Braider | C7: 395 | D7: 488 | E7: 422 | F7: =IF(OR(D7="",E7=""),"",D7-E7) -> 66 | G7: =IF(OR(C7="",F7=""),"",F7/C7) -> 0.16708861 | H7: 686 | I7: 685 | J7: =IF(OR(H7="",I7=""),"",H7-I7) -> 1 | K7: =IF(OR(C7="",J7=""),"",J7/C7) -> 0.0025316456
A8: 46247 | B8: Braider | C8: 309 | D8: 422 | E8: 363 | F8: =IF(OR(D8="",E8=""),"",D8-E8) -> 59 | G8: =IF(OR(C8="",F8=""),"",F8/C8) -> 0.19093851 | H8: 685 | I8: 684 | J8: =IF(OR(H8="",I8=""),"",H8-I8) -> 1 | K8: =IF(OR(C8="",J8=""),"",J8/C8) -> 0.003236246
A9: 46248 | B9: Tubing | C9: 150 | D9: 363 | E9: 302 | F9: =IF(OR(D9="",E9=""),"",D9-E9) -> 61 | G9: =IF(OR(C9="",F9=""),"",F9/C9) -> 0.40666667 | H9: 684 | I9: 683 | J9: =IF(OR(H9="",I9=""),"",H9-I9) -> 1 | K9: =IF(OR(C9="",J9=""),"",J9/C9) -> 0.0066666667
A10: 46251 | B10: Tubing | C10: 320 | D10: 302 | E10: 231 | F10: =IF(OR(D10="",E10=""),"",D10-E10) -> 71 | G10: =IF(OR(C10="",F10=""),"",F10/C10) -> 0.221875 | H10: 683 | I10: 682 | J10: =IF(OR(H10="",I10=""),"",H10-I10) -> 1 | K10: =IF(OR(C10="",J10=""),"",J10/C10) -> 0.003125
A11: 46252 | B11: Tubing | C11: 255 | D11: 231 | E11: 160 | F11: =IF(OR(D11="",E11=""),"",D11-E11) -> 71 | G11: =IF(OR(C11="",F11=""),"",F11/C11) -> 0.27843137 | H11: 682 | I11: 681 | J11: =IF(OR(H11="",I11=""),"",H11-I11) -> 1 | K11: =IF(OR(C11="",J11=""),"",J11/C11) -> 0.0039215686
A12: 46253 | B12: Tubing | C12: 341 | D12: 160 | E12: 92 | F12: =IF(OR(D12="",E12=""),"",D12-E12) -> 68 | G12: =IF(OR(C12="",F12=""),"",F12/C12) -> 0.19941349 | H12: 681 | I12: 676 | J12: =IF(OR(H12="",I12=""),"",H12-I12) -> 5 | K12: =IF(OR(C12="",J12=""),"",J12/C12) -> 0.014662757
A13: 46254 | B13: Tubing | C13: 315 | D13: 662 | E13: 604 | F13: =IF(OR(D13="",E13=""),"",D13-E13) -> 58 | G13: =IF(OR(C13="",F13=""),"",F13/C13) -> 0.18412698 | H13: 676 | I13: 672 | J13: =IF(OR(H13="",I13=""),"",H13-I13) -> 4 | K13: =IF(OR(C13="",J13=""),"",J13/C13) -> 0.012698413 | L13: New solvent bottel
A14: 46255 | B14: Tubing | C14: 325.57 | D14: 604 | E14: 530 | F14: =IF(OR(D14="",E14=""),"",D14-E14) -> 74 | G14: =IF(OR(C14="",F14=""),"",F14/C14) -> 0.22729367 | H14: 672 | I14: 671 | J14: =IF(OR(H14="",I14=""),"",H14-I14) -> 1 | K14: =IF(OR(C14="",J14=""),"",J14/C14) -> 0.0030715361
A15: 46256 | B15: Tubing | C15: 301.349 | D15: 530 | E15: 476 | F15: =IF(OR(D15="",E15=""),"",D15-E15) -> 54 | G15: =IF(OR(C15="",F15=""),"",F15/C15) -> 0.17919422 | H15: 671 | I15: 665 | J15: =IF(OR(H15="",I15=""),"",H15-I15) -> 6 | K15: =IF(OR(C15="",J15=""),"",J15/C15) -> 0.019910469
A16: 46258 | B16: Braider | C16: 319 | D16: 476 | E16: 419 | F16: =IF(OR(D16="",E16=""),"",D16-E16) -> 57 | G16: =IF(OR(C16="",F16=""),"",F16/C16) -> 0.17868339 | H16: 665 | I16: 663 | J16: =IF(OR(H16="",I16=""),"",H16-I16) -> 2 | K16: =IF(OR(C16="",J16=""),"",J16/C16) -> 0.0062695925
A17: 46259 | B17: Tubing | C17: 261 | D17: 419 | E17: 360 | F17: =IF(OR(D17="",E17=""),"",D17-E17) -> 59 | G17: =IF(OR(C17="",F17=""),"",F17/C17) -> 0.22605364 | H17: 663 | I17: 658 | J17: =IF(OR(H17="",I17=""),"",H17-I17) -> 5 | K17: =IF(OR(C17="",J17=""),"",J17/C17) -> 0.019157088
A18: 46260 | B18: Tubing | C18: 358 | D18: 360 | E18: 297 | F18: =IF(OR(D18="",E18=""),"",D18-E18) -> 63 | G18: =IF(OR(C18="",F18=""),"",F18/C18) -> 0.17597765 | H18: 658 | I18: 657 | J18: =IF(OR(H18="",I18=""),"",H18-I18) -> 1 | K18: =IF(OR(C18="",J18=""),"",J18/C18) -> 0.0027932961
A19: 46261 | B19: Tubing | C19: 319.16 | D19: 297 | E19: 231 | F19: =IF(OR(D19="",E19=""),"",D19-E19) -> 66 | G19: =IF(OR(C19="",F19=""),"",F19/C19) -> 0.20679283 | H19: 657 | I19: 657 | J19: =IF(OR(H19="",I19=""),"",H19-I19) -> 0 | K19: =IF(OR(C19="",J19=""),"",J19/C19) -> 0
A20: 46262 | B20: Tubing | C20: 294 | D20: 231 | E20: 180 | F20: =IF(OR(D20="",E20=""),"",D20-E20) -> 51 | G20: =IF(OR(C20="",F20=""),"",F20/C20) -> 0.17346939 | H20: 657 | I20: 655 | J20: =IF(OR(H20="",I20=""),"",H20-I20) -> 2 | K20: =IF(OR(C20="",J20=""),"",J20/C20) -> 0.0068027211
A21: 46263 | B21: Tubing | C21: 244 | D21: 180 | E21: 113 | F21: =IF(OR(D21="",E21=""),"",D21-E21) -> 67 | G21: =IF(OR(C21="",F21=""),"",F21/C21) -> 0.27459016 | H21: 655 | I21: 651 | J21: =IF(OR(H21="",I21=""),"",H21-I21) -> 4 | K21: =IF(OR(C21="",J21=""),"",J21/C21) -> 0.016393443
A22: 46265 | B22: Tubing | C22: 338 | D22: 677 | E22: 609 | F22: =IF(OR(D22="",E22=""),"",D22-E22) -> 68 | G22: =IF(OR(C22="",F22=""),"",F22/C22) -> 0.20118343 | H22: 651 | I22: 650 | J22: =IF(OR(H22="",I22=""),"",H22-I22) -> 1 | K22: =IF(OR(C22="",J22=""),"",J22/C22) -> 0.0029585799 | L22: New solvent bottel
A23: 46266 | B23: Braided | C23: 343 | D23: 609 | E23: 542 | F23: =IF(OR(D23="",E23=""),"",D23-E23) -> 67 | G23: =IF(OR(C23="",F23=""),"",F23/C23) -> 0.19533528 | H23: 650 | I23: 650 | J23: =IF(OR(H23="",I23=""),"",H23-I23) -> 0 | K23: =IF(OR(C23="",J23=""),"",J23/C23) -> 0
A24: 46267 | B24: Braided | C24: 380 | D24: 542 | E24: 464 | F24: =IF(OR(D24="",E24=""),"",D24-E24) -> 78 | G24: =IF(OR(C24="",F24=""),"",F24/C24) -> 0.20526316 | H24: 650 | I24: 648 | J24: =IF(OR(H24="",I24=""),"",H24-I24) -> 2 | K24: =IF(OR(C24="",J24=""),"",J24/C24) -> 0.0052631579
A25: 46268 | B25: Braided | C25: 366 | D25: 464 | E25: 397 | F25: =IF(OR(D25="",E25=""),"",D25-E25) -> 67 | G25: =IF(OR(C25="",F25=""),"",F25/C25) -> 0.18306011 | H25: 648 | I25: 638 | J25: =IF(OR(H25="",I25=""),"",H25-I25) -> 10 | K25: =IF(OR(C25="",J25=""),"",J25/C25) -> 0.027322404
A26: 46269 | B26: Tubing | C26: 484 | D26: 397 | E26: 297 | F26: =IF(OR(D26="",E26=""),"",D26-E26) -> 100 | G26: =IF(OR(C26="",F26=""),"",F26/C26) -> 0.20661157 | H26: 638 | I26: 633 | J26: =IF(OR(H26="",I26=""),"",H26-I26) -> 5 | K26: =IF(OR(C26="",J26=""),"",J26/C26) -> 0.010330579
A27: 46272 | B27: Tubing | C27: 435 | D27: 297 | E27: 216 | F27: =IF(OR(D27="",E27=""),"",D27-E27) -> 81 | G27: =IF(OR(C27="",F27=""),"",F27/C27) -> 0.1862069 | H27: 633 | I27: 625 | J27: =IF(OR(H27="",I27=""),"",H27-I27) -> 8 | K27: =IF(OR(C27="",J27=""),"",J27/C27) -> 0.018390805
A28: 46273 | B28: Tubing | C28: 436 | D28: 216 | E28: 138 | F28: =IF(OR(D28="",E28=""),"",D28-E28) -> 78 | G28: =IF(OR(C28="",F28=""),"",F28/C28) -> 0.17889908 | H28: 625 | I28: 624 | J28: =IF(OR(H28="",I28=""),"",H28-I28) -> 1 | K28: =IF(OR(C28="",J28=""),"",J28/C28) -> 0.002293578
A29: 46274 | B29: Braided | C29: 272 | D29: 702 | E29: 622 | F29: =IF(OR(D29="",E29=""),"",D29-E29) -> 80 | G29: =IF(OR(C29="",F29=""),"",F29/C29) -> 0.29411765 | H29: 624 | I29: 620 | J29: =IF(OR(H29="",I29=""),"",H29-I29) -> 4 | K29: =IF(OR(C29="",J29=""),"",J29/C29) -> 0.014705882 | L29: New solvent bottel (12)
A30: 46275 | B30: Braided | C30: 410 | D30: 622 | E30: 549 | F30: =IF(OR(D30="",E30=""),"",D30-E30) -> 73 | G30: =IF(OR(C30="",F30=""),"",F30/C30) -> 0.17804878 | H30: 620 | I30: 617 | J30: =IF(OR(H30="",I30=""),"",H30-I30) -> 3 | K30: =IF(OR(C30="",J30=""),"",J30/C30) -> 0.0073170732
A31: 46276 | B31: Braided | C31: 426 | D31: 549 | E31: 468 | F31: =IF(OR(D31="",E31=""),"",D31-E31) -> 81 | G31: =IF(OR(C31="",F31=""),"",F31/C31) -> 0.19014085 | H31: 617 | I31: 617 | J31: =IF(OR(H31="",I31=""),"",H31-I31) -> 0 | K31: =IF(OR(C31="",J31=""),"",J31/C31) -> 0
A32: 46277 | B32: Braided | C32: 348 | D32: 468 | E32: 364 | F32: =IF(OR(D32="",E32=""),"",D32-E32) -> 104 | G32: =IF(OR(C32="",F32=""),"",F32/C32) -> 0.29885057 | H32: 617 | I32: 611 | J32: =IF(OR(H32="",I32=""),"",H32-I32) -> 6 | K32: =IF(OR(C32="",J32=""),"",J32/C32) -> 0.017241379
A33: 46279 | B33: Tubing | C33: 373 | D33: 364 | E33: 314 | F33: =IF(OR(D33="",E33=""),"",D33-E33) -> 50 | G33: =IF(OR(C33="",F33=""),"",F33/C33) -> 0.13404826 | H33: 611 | I33: 608 | J33: =IF(OR(H33="",I33=""),"",H33-I33) -> 3 | K33: =IF(OR(C33="",J33=""),"",J33/C33) -> 0.0080428954
A34: 46280 | B34: Tubing | C34: 360 | D34: 314 | E34: 229 | F34: =IF(OR(D34="",E34=""),"",D34-E34) -> 85 | G34: =IF(OR(C34="",F34=""),"",F34/C34) -> 0.23611111 | H34: 608 | I34: 604 | J34: =IF(OR(H34="",I34=""),"",H34-I34) -> 4 | K34: =IF(OR(C34="",J34=""),"",J34/C34) -> 0.011111111
A35: 46281 | B35: Tubing | C35: 360 | D35: 229 | E35: 157 | F35: =IF(OR(D35="",E35=""),"",D35-E35) -> 72 | G35: =IF(OR(C35="",F35=""),"",F35/C35) -> 0.2 | H35: 604 | I35: 599 | J35: =IF(OR(H35="",I35=""),"",H35-I35) -> 5 | K35: =IF(OR(C35="",J35=""),"",J35/C35) -> 0.013888889
A36: 46283 | B36: Tubing | C36: 460 | D36: 734 | E36: 651 | F36: =IF(OR(D36="",E36=""),"",D36-E36) -> 83 | G36: =IF(OR(C36="",F36=""),"",F36/C36) -> 0.18043478 | H36: 599 | I36: 594 | J36: =IF(OR(H36="",I36=""),"",H36-I36) -> 5 | K36: =IF(OR(C36="",J36=""),"",J36/C36) -> 0.010869565 | L36: New solvent bottel (11)
A37: 46284 | B37: Tubing | C37: 383 | D37: 651 | E37: 576 | F37: =IF(OR(D37="",E37=""),"",D37-E37) -> 75 | G37: =IF(OR(C37="",F37=""),"",F37/C37) -> 0.19582245 | H37: 594 | I37: 590 | J37: =IF(OR(H37="",I37=""),"",H37-I37) -> 4 | K37: =IF(OR(C37="",J37=""),"",J37/C37) -> 0.010443864
A38: 46286 | B38: Tubing | C38: 408 | D38: 576 | E38: 495 | F38: =IF(OR(D38="",E38=""),"",D38-E38) -> 81 | G38: =IF(OR(C38="",F38=""),"",F38/C38) -> 0.19852941 | H38: 590 | I38: 577 | J38: =IF(OR(H38="",I38=""),"",H38-I38) -> 13 | K38: =IF(OR(C38="",J38=""),"",J38/C38) -> 0.031862745
A39: 46287 | B39: Tubing | C39: 517 | D39: 495 | E39: 420 | F39: =IF(OR(D39="",E39=""),"",D39-E39) -> 75 | G39: =IF(OR(C39="",F39=""),"",F39/C39) -> 0.1450677 | H39: 577 | I39: 576 | J39: =IF(OR(H39="",I39=""),"",H39-I39) -> 1 | K39: =IF(OR(C39="",J39=""),"",J39/C39) -> 0.001934236
A40: 46288 | B40: Tubing | C40: 523 | D40: 420 | E40: 337 | F40: =IF(OR(D40="",E40=""),"",D40-E40) -> 83 | G40: =IF(OR(C40="",F40=""),"",F40/C40) -> 0.15869981 | H40: 576 | I40: 569 | J40: =IF(OR(H40="",I40=""),"",H40-I40) -> 7 | K40: =IF(OR(C40="",J40=""),"",J40/C40) -> 0.013384321
...

Sheet Monthly Summary
A1: Month | B1: Total Production (kg) | C1: Total Solvent Used (g) | D1: Average Solvent / kg | E1: Total Ink Used (g) | F1: Average Ink / kg
A2: August | B2: =SUM('Daily Tracking'!C2:C22) -> 6510.879 | C2: =SUM('Daily Tracking'!F2:F22) -> 1303.2 | D2: =IFERROR(C2/B2,"") -> 0.20015731 | E2: =SUM('Daily Tracking'!J2:J22) -> 39 | F2: =IFERROR(E2/B2,"") -> 0.0059899746
A3: September | B3: =SUM('Daily Tracking'!C23:C47) -> 9669 | C3: =SUM('Daily Tracking'!F23:F47) -> 1891 | D3: =IFERROR(C3/B3,"") -> 0.19557348 | E3: =SUM('Daily Tracking'!J23:J47) -> 110 | F3: =IFERROR(E3/B3,"") -> 0.011376564
A4: October | B4: =SUM('Daily Tracking'!C48:C78) -> 710 | C4: =SUM('Daily Tracking'!F48:F78) -> 149 | D4: =IFERROR(C4/B4,"") -> 0.20985915 | E4: =SUM('Daily Tracking'!J48:J78) -> 3 | F4: =IFERROR(E4/B4,"") -> 0.0042253521

Sheet Control print count
A1: Tubing pipe inch/mtr | B1: Pcs / Min | C1: Pcs / hr | D1: Pcs / 11 hr | E1: Rolls/Min
A3: 18 Inch | B3: 14 | C3: 834 | D3: =C3*11 -> 9174 | E3: 13
A4: 23 Inch | B4: 11 | C4: 650 | D4: =C4*11 -> 7150 | E4: 13
A5: 36 Inch | E5: 13
A6: 1 mtr | B6: 7 | C6: 410 | D6: =C6*11 -> 4510 | E6: 13
A7: 1.5 mtr | B7: 5 | C7: 290 | D7: =C7*11 -> 3190 | E7: 13
A8: 2 mtr | B8: 3 | C8: 170 | D8: =C8*11 -> 1870 | E8: 13
A17: Braider inch/mtr | B17: Pcs / Min | C17: Pcs / hr | D17: Pcs / 11hr | E17: Rolls/Min
A18: 17 Inch | B18: 12 | C18: 850 | D18: =C18*11 -> 9350 | E18: 15
A19: 23 Inch | B19: 10 | C19: 620 | D19: =C19*11 -> 6820 | E19: 15
A20: 36 Inch | B20: 7 | C20: 430 | D20: =C20*11 -> 4730 | E20: 15
A21: 1 mtr | B21: 6 | C21: 360 | D21: =C21*11 -> 3960 | E21: 15
A22: 1.5 mtr | B22: 4 | C22: 275 | D22: =C22*11 -> 3025 | E22: 15
A23: 2 mtr | B23: 2 | C23: 135 | D23: =C23*11 -> 1485 | E23: 15
