Workbook

Sheet Dashboard
A1: INCOMING MATERIAL INSPECTION | J1: QC INSPECTION
A4: Category | B4: Entries | C4: Received Qty/Kg | D4: Unit (Pcs/Kgs) | E4: Check | G4: Unit (Pcs/Kgs) | H4: Count | J4: Category | K4: Items Checked | L4: Pass Items | M4: Fail Items | N4: Pass % | P4: Result | Q4: Count
A5: Pipe | B5: =COUNTIF(Table1[Product],"Pipe") -> 82 | C5: =IF(A5="","",SUMIF(Table1[Product],A5,Table1[Received qty])) -> 141018 | D5: Pcs | E5: =COUNTIFS(Table1[Product],"Pipe",Table1[QC check],"True") -> 73 | G5: Pcs | H5: =sum(C5:C6,C8:C9) -> 4645518 | J5: Pipe | K5: =COUNTIF(Table2[Product],"Pipe") -> 18 | L5: =COUNTIFS(Table2[Product],"Pipe",Table2[Overall QC Result],"PASS") -> 15 | M5: =COUNTIFS(Table2[Product],"Pipe",Table2[Overall QC Result],"FAIL") -> 3 | N5: =IF(K5=0,0,L5/K5) -> 0.83333333 | P5: PASS | Q5: =L11 -> 29
A6: Nutset | B6: =COUNTIF(Table1[Product],"Nutset") -> 35 | C6: =IF(A6="","",SUMIF(Table1[Product],A6,Table1[Received qty])) -> 3479000 | D6: Pcs | E6: =COUNTIFS(Table1[Product],"Nutset",Table1[QC check],"True") -> 35 | G6: Kgs | H6: =Sum(C7) -> 1187.2 | J6: Nutset | K6: =COUNTIF(Table2[Product],"Nutset") -> 14 | L6: =COUNTIFS(Table2[Product],"Nutset",Table2[Overall QC Result],"PASS") -> 10 | M6: =COUNTIFS(Table2[Product],"Nutset",Table2[Overall QC Result],"FAIL") -> 4 | N6: =IF(K6=0,0,L6/K6) -> 0.71428571 | P6: FAIL | Q6: =M11 -> 6
A7: Cover | B7: =COUNTIF(Table1[Product],"Cover") -> 5 | C7: =IF(A7="","",SUMIF(Table1[Product],A7,Table1[Received qty])) -> 1187.2 | D7: Kgs | E7: =COUNTIFS(Table1[Product],"Cover",Table1[QC check],"True") -> 5 | J7: Cover | K7: =COUNTIF(Table2[Product],"Cover") -> 2 | L7: =COUNTIFS(Table2[Product],"Cover",Table2[Overall QC Result],"PASS") -> 2 | M7: =COUNTIFS(Table2[Product],"Cover",Table2[Overall QC Result],"FAIL") -> 0 | N7: =IF(K7=0,0,L7/K7) -> 1
A8: Label | B8: =COUNTIF(Table1[Product],"Label") -> 2 | C8: =IF(A8="","",SUMIF(Table1[Product],A8,Table1[Received qty])) -> 25500 | D8: Pcs | E8: =COUNTIFS(Table1[Product],"Label",Table1[QC check],"True") -> 2 | J8: Label | K8: =COUNTIF(Table2[Product],"Label") -> 2 | L8: =COUNTIFS(Table2[Product],"Label",Table2[Overall QC Result],"PASS") -> 2 | M8: =COUNTIFS(Table2[Product],"Label",Table2[Overall QC Result],"FAIL") -> 0 | N8: =IF(K8=0,0,L8/K8) -> 1
A9: Washer | B9: =COUNTIF(Table1[Product],"Washer") -> 2 | C9: =IF(A9="","",SUMIF(Table1[Product],A9,Table1[Received qty])) -> 1000000 | D9: Pcs | E9: =COUNTIFS(Table1[Product],"Washer",Table1[QC check],"True") -> 2 | J9: Washer | K9: =COUNTIF(Table2[Product],"Washer") -> 2 | L9: =COUNTIFS(Table2[Product],"Washer",Table2[Overall QC Result],"PASS") -> 0 | M9: =COUNTIFS(Table2[Product],"Washer",Table2[Overall QC Result],"FAIL") -> 2 | N9: =IF(K9=0,0,L9/K9) -> 0
A11: Total | B11: =sum(B5:B10) -> 126 | C11: =sum(C5:C10) -> 4646705.2 | D11: (Pcs/Kgs) | E11: =sum(E5:E10) -> 117 | J11: Total | K11: =sum(K5:K10) -> 38 | L11: =sum(L5:L10) -> 29 | M11: =sum(M6:M9) -> 6 | N11: =IF(K11=0,0,L11/K11) -> 0.76315789

Sheet Inward Register
A1: Date | B1: Invoice/Chalan | C1: Vender | D1: Customer name | E1: Brand | F1: Product | G1: Product type | H1: Size | I1: Received qty | J1: Unit (Pcs/Kgs) | K1: Received | L1: QC check | M1: Production date/QC | N1: Production days | O1: No. Bags/Bins | P1: Bags/Bins | Q1: Remark
A2: 46226 | B2: PP/26-27/0545 | C2: Punith packaging | D2: Aura | E2: Marino | F2: Cover | G2: Cover | H2: 3X21 | I2: 245.4 | J2: Kgs | K2: TRUE | L2: TRUE | N2: =IF(A2="","",IF(M2="",TODAY()-A2,M2-A2)) -> 75 | P2: Bags
A3: 46228 | B3: 5M-CM/0384/26-27 | C3: 5M Moulding and Technologies | D3: - | E3: - | F3: Nutset | G3: L-Round nut | H3: 13mm | I3: 80000 | J3: Pcs | K3: TRUE | L3: TRUE | N3: =IF(A3="","",IF(M3="",TODAY()-A3,M3-A3)) -> 73 | P3: Bags
A4: 46228 | B4: 5M-CM/0384/26-27 | C4: 5M Moulding and Technologies | D4: - | E4: - | F4: Nutset | G4: L-Hex nut | H4: 13mm | I4: 28000 | J4: Pcs | K4: TRUE | L4: TRUE | N4: =IF(A4="","",IF(M4="",TODAY()-A4,M4-A4)) -> 73 | P4: Bags
A5: 46228 | B5: 5M-CM/0384/26-27 | C5: 5M Moulding and Technologies | D5: - | E5: - | F5: Nutset | G5: M-Hex nut | H5: 13.5mm | I5: 60000 | J5: Pcs | K5: TRUE | L5: TRUE | N5: =IF(A5="","",IF(M5="",TODAY()-A5,M5-A5)) -> 73 | P5: Bags
A6: 46234 | B6: 5M-CM/0405/26-27 | C6: 5M Moulding and Technologies | D6: - | E6: - | F6: Nutset | G6: M-Hex nut | H6: 13.5mm | I6: 66000 | J6: Pcs | K6: TRUE | L6: TRUE | N6: =IF(A6="","",IF(M6="",TODAY()-A6,M6-A6)) -> 67 | P6: Bags
A7: 46234 | B7: 5M-CM/0405/26-27 | C7: 5M Moulding and Technologies | D7: - | E7: - | F7: Nutset | G7: L-Round nut | H7: 13mm | I7: 72000 | J7: Pcs | K7: TRUE | L7: TRUE | N7: =IF(A7="","",IF(M7="",TODAY()-A7,M7-A7)) -> 67 | P7: Bags
A8: 46234 | B8: 5M-CM/0405/26-27 | C8: 5M Moulding and Technologies | D8: - | E8: - | F8: Nutset | G8: Inner | I8: 120000 | J8: Pcs | K8: TRUE | L8: TRUE | N8: =IF(A8="","",IF(M8="",TODAY()-A8,M8-A8)) -> 67 | P8: Bags
A9: 46234 | B9: 5M-CM/0405/26-27 | C9: 5M Moulding and Technologies | D9: - | E9: - | F9: Nutset | G9: M-Cap | H9: 13.5mm | I9: 60000 | J9: Pcs | K9: TRUE | L9: TRUE | N9: =IF(A9="","",IF(M9="",TODAY()-A9,M9-A9)) -> 67 | P9: Bags
A10: 46238 | B10: 46236 | C10: Enflow2 | D10: Aura | E10: Waterflo | F10: Pipe | G10: Braded 13.5mm | H10: 13.5mm | J10: Pcs | K10: TRUE | L10: TRUE | N10: =IF(A10="","",IF(M10="",TODAY()-A10,M10-A10)) -> 63 | P10: Bags
A11: 46239 | B11: 46236 | C11: Enflow2 | D11: Aura | E11: Marino | F11: Pipe | G11: Braded 13.5mm | H11: 13.5mm | J11: Pcs | K11: TRUE | L11: TRUE | N11: =IF(A11="","",IF(M11="",TODAY()-A11,M11-A11)) -> 62 | P11: Bags
A12: 46242 | B12: 46236 | C12: Enflow2 | D12: Aura | E12: Marino | F12: Pipe | G12: Braded 13.5mm | H12: 13.5mm | J12: Pcs | K12: TRUE | L12: TRUE | N12: =IF(A12="","",IF(M12="",TODAY()-A12,M12-A12)) -> 59 | P12: Bags
A13: 46242 | B13: PP/26-27/0621 | C13: Punith packaging | D13: Aura | E13: Marino | F13: Cover | G13: Cover | H13: 3X26 | I13: 325 | J13: Kgs | K13: TRUE | L13: TRUE | N13: =IF(A13="","",IF(M13="",TODAY()-A13,M13-A13)) -> 59 | O13: 8 Bags | P13: Bags
A14: 46245 | B14: 5M-CM/0438/26-27 | C14: 5M Moulding and Technologies | D14: - | E14: - | F14: Nutset | G14: L-Round nut | H14: 13mm | I14: 142000 | J14: Pcs | K14: TRUE | L14: TRUE | N14: =IF(A14="","",IF(M14="",TODAY()-A14,M14-A14)) -> 56 | O14: 71 Bags | P14: Bags
A15: 46245 | B15: 5M-CM/0438/26-27 | C15: 5M Moulding and Technologies | D15: - | E15: - | F15: Nutset | G15: M-Hex nut | H15: 13.5mm | I15: 40000 | J15: Pcs | K15: TRUE | L15: TRUE | N15: =IF(A15="","",IF(M15="",TODAY()-A15,M15-A15)) -> 56 | O15: 20 Bags | P15: Bags
A16: 46245 | B16: 5M-CM/0442/26-27 | C16: 5M Moulding and Technologies | D16: - | E16: - | F16: Nutset | G16: M-Hex nut | H16: 13.5mm | I16: 20000 | J16: Pcs | K16: TRUE | L16: TRUE | N16: =IF(A16="","",IF(M16="",TODAY()-A16,M16-A16)) -> 56 | O16: 10 Bags | P16: Bags
A17: 46245 | B17: 5M-CM/0442/26-27 | C17: 5M Moulding and Technologies | D17: - | E17: - | F17: Nutset | G17: Inner | I17: 130000 | J17: Pcs | K17: TRUE | L17: TRUE | N17: =IF(A17="","",IF(M17="",TODAY()-A17,M17-A17)) -> 56 | O17: 13 Bags | P17: Bags
A18: 46245 | B18: 5M-CM/0442/26-27 | C18: 5M Moulding and Technologies | D18: - | E18: - | F18: Nutset | G18: M-Cap | H18: 13.5mm | I18: 100000 | J18: Pcs | K18: TRUE | L18: TRUE | N18: =IF(A18="","",IF(M18="",TODAY()-A18,M18-A18)) -> 56 | O18: 10 Bags | P18: Bags
A19: 46245 | B19: 5M-CM/0442/26-27 | C19: 5M Moulding and Technologies | D19: - | E19: - | F19: Nutset | G19: L-Key | H19: 13mm | I19: 51000 | J19: Pcs | K19: TRUE | L19: TRUE | N19: =IF(A19="","",IF(M19="",TODAY()-A19,M19-A19)) -> 56 | O19: 17 Bags | P19: Bags
A20: 46245 | B20: 5M-CM/0442/26-27 | C20: 5M Moulding and Technologies | D20: - | E20: - | F20: Nutset | G20: M-Key | H20: 13.5mm | I20: 51000 | J20: Pcs | K20: TRUE | L20: TRUE | N20: =IF(A20="","",IF(M20="",TODAY()-A20,M20-A20)) -> 56 | O20: 17 Bags | P20: Bags
A21: 46253 | B21: 46237 | C21: Enflow2 | D21: Idol | E21: Idol | F21: Pipe | G21: Braded 13.5mm | H21: 30 inch | I21: 5000 | J21: Pcs | K21: TRUE | L21: TRUE | N21: =IF(A21="","",IF(M21="",TODAY()-A21,M21-A21)) -> 48 | O21: 10 | P21: Bags
A22: 46253 | B22: 46237 | C22: Enflow2 | D22: Idol | E22: Idol | F22: Pipe | G22: Braded 13.5mm | H22: 36 inch | I22: 5100 | J22: Pcs | K22: TRUE | L22: TRUE | N22: =IF(A22="","",IF(M22="",TODAY()-A22,M22-A22)) -> 48 | O22: 17 | P22: Bags
A23: 46253 | B23: 46237 | C23: Enflow2 | D23: Schintler | E23: Schintler | F23: Pipe | G23: Non-Braded 13mm | H23: 24 inch | I23: 2000 | J23: Pcs | K23: TRUE | L23: TRUE | N23: =IF(A23="","",IF(M23="",TODAY()-A23,M23-A23)) -> 48 | O23: 4 | P23: Bags
A24: 46253 | B24: 46237 | C24: Enflow2 | D24: Schintler | E24: Schintler | F24: Pipe | G24: Non-Braded 13mm | H24: 18 inch | I24: 3000 | J24: Pcs | K24: TRUE | L24: TRUE | N24: =IF(A24="","",IF(M24="",TODAY()-A24,M24-A24)) -> 48 | O24: 3 | P24: Bags
A25: 46253 | B25: 46237 | C25: Enflow2 | D25: Aura | E25: Waterflo | F25: Pipe | G25: Non-Braded 13mm | H25: 1mtr | I25: 900 | J25: Pcs | K25: TRUE | L25: TRUE | N25: =IF(A25="","",IF(M25="",TODAY()-A25,M25-A25)) -> 48 | O25: 3 | P25: Bags
A26: 46253 | B26: 46237 | C26: Enflow2 | D26: Aura | E26: Marino | F26: Pipe | G26: Non-Braded 13mm | H26: 1mtr | I26: 600 | J26: Pcs | K26: TRUE | L26: TRUE | N26: =IF(A26="","",IF(M26="",TODAY()-A26,M26-A26)) -> 48 | O26: 2 | P26: Bags
A27: 46258 | B27: 35 | C27: 5M Moulding and Technologies | D27: - | E27: - | F27: Nutset | G27: L-Round nut | H27: 13mm | I27: 72000 | J27: Pcs | K27: TRUE | L27: TRUE | N27: =IF(A27="","",IF(M27="",TODAY()-A27,M27-A27)) -> 43 | O27: 36 Bags | P27: Bags
A28: 46258 | B28: 35 | C28: 5M Moulding and Technologies | D28: - | E28: - | F28: Nutset | G28: L-Cap | H28: 13mm | I28: 150000 | J28: Pcs | K28: TRUE | L28: TRUE | N28: =IF(A28="","",IF(M28="",TODAY()-A28,M28-A28)) -> 43 | O28: 15 Bags | P28: Bags
A29: 46258 | B29: 35 | C29: 5M Moulding and Technologies | D29: - | E29: - | F29: Nutset | G29: Inner | I29: 120000 | J29: Pcs | K29: TRUE | L29: TRUE | N29: =IF(A29="","",IF(M29="",TODAY()-A29,M29-A29)) -> 43 | O29: 12 Bags | P29: Bags
A30: 46258 | B30: 35 | C30: 5M Moulding and Technologies | D30: - | E30: - | F30: Nutset | G30: L-Key | H30: 13mm | I30: 35000 | J30: Pcs | K30: TRUE | L30: TRUE | N30: =IF(A30="","",IF(M30="",TODAY()-A30,M30-A30)) -> 43 | O30: 11.6 Bags | P30: Bags
A31: 46258 | B31: 35 | C31: 5M Moulding and Technologies | D31: - | E31: - | F31: Nutset | G31: M-Cap | H31: 13.5mm | I31: 50000 | J31: Pcs | K31: TRUE | L31: TRUE | N31: =IF(A31="","",IF(M31="",TODAY()-A31,M31-A31)) -> 43 | O31: 5 Bags | P31: Bags
A32: 46259 | B32: 37 | C32: 5M Moulding and Technologies | D32: - | E32: - | F32: Nutset | G32: L-Hex nut | H32: 13mm | I32: 80000 | J32: Pcs | K32: TRUE | L32: TRUE | N32: =IF(A32="","",IF(M32="",TODAY()-A32,M32-A32)) -> 42 | O32: 40 Bags | P32: Bags
A33: 46259 | B33: 37 | C33: 5M Moulding and Technologies | D33: - | E33: - | F33: Nutset | G33: M-Hex nut | H33: 13.5mm | I33: 50000 | J33: Pcs | K33: TRUE | L33: TRUE | N33: =IF(A33="","",IF(M33="",TODAY()-A33,M33-A33)) -> 42 | O33: 25 Bags | P33: Bags
A34: 46261 | B34: MAK/194/26-27 | C34: Mak flexible | D34: Aura | E34: Waterflo | F34: Cover | G34: Cover | H34: 3X26 | I34: 309 | J34: Kgs | K34: TRUE | L34: TRUE | N34: =IF(A34="","",IF(M34="",TODAY()-A34,M34-A34)) -> 40 | O34: 10 Bags | P34: Bags
A35: 46261 | B35: 1467 | C35: Eva rubber | D35: - | E35: - | F35: Washer | G35: Washer | I35: 250000 | J35: Pcs | K35: TRUE | L35: TRUE | M35: 46267 | N35: =IF(A35="","",IF(M35="",TODAY()-A35,M35-A35)) -> 6 | O35: 10 Bags | P35: Bags
A36: 46262 | B36: 46239 | C36: Enflow2 | D36: Aura | E36: Marino | F36: Pipe | G36: Braded 13.5mm | H36: 24 inch | I36: 4550 | J36: Pcs | K36: TRUE | L36: TRUE | N36: =IF(A36="","",IF(M36="",TODAY()-A36,M36-A36)) -> 39 | O36: 13 Bin | P36: Bins
A37: 46262 | B37: 46239 | C37: Enflow2 | D37: Aura | E37: Waterflo | F37: Pipe | G37: Non-Braded 13mm | H37: 1.5mtr | I37: 2400 | J37: Pcs | K37: TRUE | L37: TRUE | N37: =IF(A37="","",IF(M37="",TODAY()-A37,M37-A37)) -> 39 | O37: 12 Bags | P37: Bags
A38: 46262 | B38: 46239 | C38: Enflow2 | D38: Aura | E38: Marino | F38: Pipe | G38: Non-Braded 13mm | H38: 1mtr | I38: 3500 | J38: Pcs | K38: TRUE | L38: TRUE | N38: =IF(A38="","",IF(M38="",TODAY()-A38,M38-A38)) -> 39 | O38: 10 Bags | P38: Bags
A39: 46262 | B39: 46239 | C39: Enflow2 | D39: Aura | E39: Plain | F39: Pipe | G39: Non-Braded 13mm | H39: 1.5mtr | I39: 1000 | J39: Pcs | K39: TRUE | L39: TRUE | M39: 46295 | N39: =IF(A39="","",IF(M39="",TODAY()-A39,M39-A39)) -> 33 | O39: 5 | P39: Bags
A40: 46265 | B40: PP/26-27/0717 | C40: Punith packaging | D40: Schintler | E40: Schintler | F40: Cover | G40: Cover | H40: 3X21 | I40: 193.2 | J40: Kgs | K40: TRUE | L40: TRUE | M40: 46267 | N40: =IF(A40="","",IF(M40="",TODAY()-A40,M40-A40)) -> 2
...

Sheet QC Inspection
B1: INCOMING MATERIAL QC INSPECTION
A3: Recived Date | B3: QC Date | C3: Supplier | D3: Batch No. | E3: Product | F3: Brand | G3: Product type | H3: Size | I3: Received Qty/Kg | J3: Unit (Pcs/Kgs) | K3: Checked Qty/Kg | L3: Pass Qty/Kg | M3: Fail Qty/Kg | N3: Thread / Dimension | O3: Surface/ color | P3: Shape / Fit | Q3: Overall QC Result | R3: Result% | S3: Remarks
A4: 46263 | B4: 46263 | C4: Mak flexible | D4: MAK/194/26-27 | E4: Cover | F4: Waterflo | G4: Cover | H4: 3x26 | I4: 309 | J4: Kgs | K4: 30 | L4: 30 | M4: =K4-L4 -> 0 | N4: PASS | O4: FAIL | P4: FAIL | Q4: =IF(M4=0,"PASS","FAIL") -> PASS | R4: =AVERAGE(IF(L4=K4,1,0),IF(N4="PASS",1,0),IF(O4="PASS",1,0),IF(P4="PASS",1,0)) -> 0.5 | S4: The Colour of the cover is loo
A5: 46265 | B5: 46267 | C5: 5M Moulding and Technologies | D5: 46239 | E5: Nutset | F5: - | G5: M-Hex nut | H5: 13.5mm | I5: 38000 | J5: Pcs | K5: 50 | L5: 40 | M5: =K5-L5 -> 10 | N5: PASS | O5: PASS | P5: FAIL | Q5: =IF(M5=0,"PASS","FAIL") -> FAIL | R5: =AVERAGE(IF(L5=K5,1,0),IF(N5="PASS",1,0),IF(O5="PASS",1,0),IF(P5="PASS",1,0)) -> 0.5 | S5: Some Hexnut getting tight on cap
A6: 46265 | B6: 46267 | C6: 5M Moulding and Technologies | D6: 46239 | E6: Nutset | F6: - | G6: M-Hex nut | H6: 13mm | I6: 134000 | J6: Pcs | K6: 50 | L6: 50 | M6: =K6-L6 -> 0 | N6: PASS | O6: PASS | P6: PASS | Q6: =IF(M6=0,"PASS","FAIL") -> PASS | R6: =AVERAGE(IF(L6=K6,1,0),IF(N6="PASS",1,0),IF(O6="PASS",1,0),IF(P6="PASS",1,0)) -> 1 | S6: The Colour of the cover is loo for key
A7: 46265 | B7: 46267 | C7: Eva rubber | D7: 46239 | E7: Washer | F7: - | G7: Washer | I7: 250000 | J7: Pcs | K7: 50 | L7: 30 | M7: =K7-L7 -> 20 | Q7: =IF(M7=0,"PASS","FAIL") -> FAIL | R7: =AVERAGE(IF(L7=K7,1,0),IF(N7="PASS",1,0),IF(O7="PASS",1,0),IF(P7="PASS",1,0)) -> 0 | S7: Getting extra flash in centre hole rubber
A8: 46265 | B8: 46267 | C8: Punith packaging | D8: PP/26-27/0717 | E8: Cover | F8: Schintler | G8: Cover | H8: 3x21, 3x26 | M8: =K8-L8 -> 0 | N8: FAIL | O8: PASS | P8: PASS | Q8: =IF(M8=0,"PASS","FAIL") -> PASS | R8: =AVERAGE(IF(L8=K8,1,0),IF(N8="PASS",1,0),IF(O8="PASS",1,0),IF(P8="PASS",1,0)) -> 0.75 | S8: Some cover 4 side sealed
A9: 46273 | B9: 46277 | C9: Eva rubber | D9: 46267 | E9: Washer | F9: - | G9: Washer | I9: 750000 | J9: Pcs | K9: 80 | L9: 50 | M9: =K9-L9 -> 30 | Q9: =IF(M9=0,"PASS","FAIL") -> FAIL | R9: =AVERAGE(IF(L9=K9,1,0),IF(N9="PASS",1,0),IF(O9="PASS",1,0),IF(P9="PASS",1,0)) -> 0 | S9: Getting extra flash in centre hole rubber
A10: 46275 | B10: 46275 | C10: Sri Tex Engineers | D10: 46267 | E10: Nutset | F10: - | G10: L-Cap | H10: 13mm | I10: 100000 | J10: Pcs | K10: 20 | L10: 20 | M10: =K10-L10 -> 0 | N10: PASS | O10: PASS | P10: PASS | Q10: =IF(M10=0,"PASS","FAIL") -> PASS | R10: =AVERAGE(IF(L10=K10,1,0),IF(N10="PASS",1,0),IF(O10="PASS",1,0),IF(P10="PASS",1,0)) -> 1
A11: 46276 | B11: 46277 | C11: 5M Moulding and Technologies | D11: 46268 | E11: Nutset | F11: - | G11: L-Hex nut | H11: 13mm | I11: 98000 | J11: Pcs | K11: 50 | L11: 50 | M11: =K11-L11 -> 0 | N11: PASS | O11: FAIL | P11: PASS | Q11: =IF(M11=0,"PASS","FAIL") -> PASS | R11: =AVERAGE(IF(L11=K11,1,0),IF(N11="PASS",1,0),IF(O11="PASS",1,0),IF(P11="PASS",1,0)) -> 0.75 | S11: The colour is loo campare to L-key
A12: 46276 | B12: 46277 | C12: 5M Moulding and Technologies | D12: 46268 | E12: Nutset | F12: - | G12: L-Round nut | H12: 13mm | I12: 78000 | J12: Pcs | K12: 50 | L12: 50 | M12: =K12-L12 -> 0 | N12: PASS | O12: FAIL | P12: PASS | Q12: =IF(M12=0,"PASS","FAIL") -> PASS | R12: =AVERAGE(IF(L12=K12,1,0),IF(N12="PASS",1,0),IF(O12="PASS",1,0),IF(P12="PASS",1,0)) -> 0.75 | S12: The colour is loo campare to L-key
A13: 46276 | B13: 46277 | C13: 5M Moulding and Technologies | D13: 46268 | E13: Nutset | F13: - | G13: Inner | H13: 13mm | I13: 370000 | J13: Pcs | K13: 100 | L13: 50 | M13: =K13-L13 -> 50 | N13: FAIL | O13: PASS | P13: FAIL | Q13: =IF(M13=0,"PASS","FAIL") -> FAIL | R13: =AVERAGE(IF(L13=K13,1,0),IF(N13="PASS",1,0),IF(O13="PASS",1,0),IF(P13="PASS",1,0)) -> 0.25 | S13: Some bags got flash in inner
A14: 46276 | B14: 46277 | C14: 5M Moulding and Technologies | D14: 46268 | E14: Nutset | F14: - | G14: L-Cap | H14: 13mm | I14: 60000 | J14: Pcs | K14: 50 | L14: 30 | M14: =K14-L14 -> 20 | N14: PASS | O14: PASS | P14: FAIL | Q14: =IF(M14=0,"PASS","FAIL") -> FAIL | R14: =AVERAGE(IF(L14=K14,1,0),IF(N14="PASS",1,0),IF(O14="PASS",1,0),IF(P14="PASS",1,0)) -> 0.5 | S14: Some caps getting flash
A15: 46276 | B15: 46277 | C15: 5M Moulding and Technologies | D15: 46268 | E15: Nutset | F15: - | G15: L-Key | H15: 13mm | I15: 87000 | J15: Pcs | K15: 50 | L15: 50 | M15: =K15-L15 -> 0 | N15: PASS | O15: PASS | P15: PASS | Q15: =IF(M15=0,"PASS","FAIL") -> PASS | R15: =AVERAGE(IF(L15=K15,1,0),IF(N15="PASS",1,0),IF(O15="PASS",1,0),IF(P15="PASS",1,0)) -> 1 | S15: The colour is not matching to Nut
A16: 46276 | B16: 46277 | C16: 5M Moulding and Technologies | D16: 46268 | E16: Nutset | F16: - | G16: M-Key | H16: 13.5mm | I16: 57000 | J16: Pcs | K16: 50 | L16: 50 | M16: =K16-L16 -> 0 | N16: PASS | O16: FAIL | P16: PASS | Q16: =IF(M16=0,"PASS","FAIL") -> PASS | R16: =AVERAGE(IF(L16=K16,1,0),IF(N16="PASS",1,0),IF(O16="PASS",1,0),IF(P16="PASS",1,0)) -> 0.75 | S16: The colour is not matching to Nut
A17: 46283 | B17: 46284 | C17: Kolorkode | D17: 46268 | E17: Label | F17: Schintler | G17: Label | H17: 18 inch, 24 inch | I17: 21000 | J17: Pcs | M17: =K17-L17 -> 0 | N17: PASS | O17: PASS | P17: PASS | Q17: =IF(M17=0,"PASS","FAIL") -> PASS | R17: =AVERAGE(IF(L17=K17,1,0),IF(N17="PASS",1,0),IF(O17="PASS",1,0),IF(P17="PASS",1,0)) -> 1
A18: 46284 | B18: 46287 | C18: Kolorkode | D18: 46269 | E18: Label | F18: Akant | G18: Label | H18: 24 inch, 1mtr | I18: 4656 | J18: Pcs | K18: 4656 | L18: 4656 | M18: =K18-L18 -> 0 | N18: PASS | O18: PASS | P18: PASS | Q18: =IF(M18=0,"PASS","FAIL") -> PASS | R18: =AVERAGE(IF(L18=K18,1,0),IF(N18="PASS",1,0),IF(O18="PASS",1,0),IF(P18="PASS",1,0)) -> 1
A19: 46289 | B19: 46291 | C19: Sri Tex Engineers | D19: 46269 | E19: Nutset | F19: - | G19: L-Cap | H19: 13mm | I19: 50000 | J19: Pcs | K19: 100 | L19: 100 | M19: =K19-L19 -> 0 | N19: PASS | O19: PASS | P19: PASS | Q19: =IF(M19=0,"PASS","FAIL") -> PASS | R19: =AVERAGE(IF(L19=K19,1,0),IF(N19="PASS",1,0),IF(O19="PASS",1,0),IF(P19="PASS",1,0)) -> 1
A20: =IFERROR('Inward Register'!A106,"") -> 46291 | B20: =IFERROR('Inward Register'!M106,"") -> 46293 | C20: =IFERROR('Inward Register'!C106,"") -> Enflow2 | D20: =IFERROR('Inward Register'!B106,"") -> 46269 | E20: =IFERROR('Inward Register'!F106,"") -> Pipe | F20: =IFERROR('Inward Register'!E106,"") -> Ceraflo | G20: =IFERROR('Inward Register'!G106,"") -> Non-Braded 13mm | H20: =IFERROR('Inward Register'!H106,"") -> 18 inch | I20: =IFERROR('Inward Register'!I106,"") -> 200 | J20: =IFERROR('Inward Register'!J106,"") -> Pcs | M20: =K20-L20 -> 0 | Q20: =IF(M20=0,"PASS","FAIL") -> PASS | R20: =AVERAGE(IF(L20=K20,1,0),IF(N20="PASS",1,0),IF(O20="PASS",1,0),IF(P20="PASS",1,0)) -> 0.25
A21: =IFERROR('Inward Register'!A107,"") -> 46291 | B21: =IFERROR('Inward Register'!M107,"") -> 46293 | C21: =IFERROR('Inward Register'!C107,"") -> Enflow2 | D21: =IFERROR('Inward Register'!B107,"") -> 46269 | E21: =IFERROR('Inward Register'!F107,"") -> Pipe | F21: =IFERROR('Inward Register'!E107,"") -> Ceraflo | G21: =IFERROR('Inward Register'!G107,"") -> Non-Braded 13mm | H21: =IFERROR('Inward Register'!H107,"") -> 24 inch | I21: =IFERROR('Inward Register'!I107,"") -> 1500 | J21: =IFERROR('Inward Register'!J107,"") -> Pcs | M21: =K21-L21 -> 0 | Q21: =IF(M21=0,"PASS","FAIL") -> PASS | R21: =AVERAGE(IF(L21=K21,1,0),IF(N21="PASS",1,0),IF(O21="PASS",1,0),IF(P21="PASS",1,0)) -> 0.25
A22: =IFERROR('Inward Register'!A108,"") -> 46291 | B22: =IFERROR('Inward Register'!M108,"") -> 46293 | C22: =IFERROR('Inward Register'!C108,"") -> Enflow2 | D22: =IFERROR('Inward Register'!B108,"") -> 46269 | E22: =IFERROR('Inward Register'!F108,"") -> Pipe | F22: =IFERROR('Inward Register'!E108,"") -> Ceraflo | G22: =IFERROR('Inward Register'!G108,"") -> Non-Braded 13mm | H22: =IFERROR('Inward Register'!H108,"") -> 1mtr | I22: =IFERROR('Inward Register'!I108,"") -> 315 | J22: =IFERROR('Inward Register'!J108,"") -> Pcs | M22: =K22-L22 -> 0 | Q22: =IF(M22=0,"PASS","FAIL") -> PASS | R22: =AVERAGE(IF(L22=K22,1,0),IF(N22="PASS",1,0),IF(O22="PASS",1,0),IF(P22="PASS",1,0)) -> 0.25
A23: =IFERROR('Inward Register'!A109,"") -> 46291 | B23: =IFERROR('Inward Register'!M109,"") -> 46291 | C23: =IFERROR('Inward Register'!C109,"") -> Enflow2 | D23: =IFERROR('Inward Register'!B109,"") -> 46269 | E23: =IFERROR('Inward Register'!F109,"") -> Pipe | F23: =IFERROR('Inward Register'!E109,"") -> CS | G23: =IFERROR('Inward Register'!G109,"") -> Non-Braded 13mm | H23: =IFERROR('Inward Register'!H109,"") -> 24 inch | I23: =IFERROR('Inward Register'!I109,"") -> 7100 | J23: =IFERROR('Inward Register'!J109,"") -> Pcs | M23: =K23-L23 -> 0 | Q23: =IF(M23=0,"PASS","FAIL") -> PASS | R23: =AVERAGE(IF(L23=K23,1,0),IF(N23="PASS",1,0),IF(O23="PASS",1,0),IF(P23="PASS",1,0)) -> 0.25
A24: =IFERROR('Inward Register'!A110,"") -> 46291 | B24: =IFERROR('Inward Register'!M110,"") -> 46293 | C24: =IFERROR('Inward Register'!C110,"") -> Enflow2 | D24: =IFERROR('Inward Register'!B110,"") -> 46269 | E24: =IFERROR('Inward Register'!F110,"") -> Pipe | F24: =IFERROR('Inward Register'!E110,"") -> Futura | G24: =IFERROR('Inward Register'!G110,"") -> Non-Braded 13mm | H24: =IFERROR('Inward Register'!H110,"") -> 18 inch | I24: =IFERROR('Inward Register'!I110,"") -> 3188 | J24: =IFERROR('Inward Register'!J110,"") -> Pcs | M24: =K24-L24 -> 0 | Q24: =IF(M24=0,"PASS","FAIL") -> PASS | R24: =AVERAGE(IF(L24=K24,1,0),IF(N24="PASS",1,0),IF(O24="PASS",1,0),IF(P24="PASS",1,0)) -> 0.25
A25: =IFERROR('Inward Register'!A111,"") -> 46291 | B25: =IFERROR('Inward Register'!M111,"") -> 46293 | C25: =IFERROR('Inward Register'!C111,"") -> Enflow2 | D25: =IFERROR('Inward Register'!B111,"") -> 46269 | E25: =IFERROR('Inward Register'!F111,"") -> Pipe | F25: =IFERROR('Inward Register'!E111,"") -> Futura | G25: =IFERROR('Inward Register'!G111,"") -> Non-Braded 13mm | H25: =IFERROR('Inward Register'!H111,"") -> 36 inch | I25: =IFERROR('Inward Register'!I111,"") -> 500 | J25: =IFERROR('Inward Register'!J111,"") -> Pcs | M25: =K25-L25 -> 0 | Q25: =IF(M25=0,"PASS","FAIL") -> PASS | R25: =AVERAGE(IF(L25=K25,1,0),IF(N25="PASS",1,0),IF(O25="PASS",1,0),IF(P25="PASS",1,0)) -> 0.25
A26: =IFERROR('Inward Register'!A112,"") -> 46291 | B26: =IFERROR('Inward Register'!M112,"") | C26: =IFERROR('Inward Register'!C112,"") -> Enflow2 | D26: =IFERROR('Inward Register'!B112,"") -> 46269 | E26: =IFERROR('Inward Register'!F112,"") -> Pipe | F26: =IFERROR('Inward Register'!E112,"") -> Paras flow | G26: =IFERROR('Inward Register'!G112,"") -> Braded 13.5mm | H26: =IFERROR('Inward Register'!H112,"") -> 18 inch | I26: =IFERROR('Inward Register'!I112,"") -> 600 | J26: =IFERROR('Inward Register'!J112,"") -> Pcs | M26: =K26-L26 -> 0 | Q26: =IF(M26=0,"PASS","FAIL") -> PASS | R26: =AVERAGE(IF(L26=K26,1,0),IF(N26="PASS",1,0),IF(O26="PASS",1,0),IF(P26="PASS",1,0)) -> 0.25
A27: =IFERROR('Inward Register'!A113,"") -> 46291 | B27: =IFERROR('Inward Register'!M113,"") | C27: =IFERROR('Inward Register'!C113,"") -> Enflow2 | D27: =IFERROR('Inward Register'!B113,"") -> 46269 | E27: =IFERROR('Inward Register'!F113,"") -> Pipe | F27: =IFERROR('Inward Register'!E113,"") -> Paras flow | G27: =IFERROR('Inward Register'!G113,"") -> Braded 13.5mm | H27: =IFERROR('Inward Register'!H113,"") -> 24 inch | I27: =IFERROR('Inward Register'!I113,"") -> 2000 | J27: =IFERROR('Inward Register'!J113,"") -> Pcs | M27: =K27-L27 -> 0 | Q27: =IF(M27=0,"PASS","FAIL") -> PASS | R27: =AVERAGE(IF(L27=K27,1,0),IF(N27="PASS",1,0),IF(O27="PASS",1,0),IF(P27="PASS",1,0)) -> 0.25
A28: =IFERROR('Inward Register'!A114,"") -> 46291 | B28: =IFERROR('Inward Register'!M114,"") | C28: =IFERROR('Inward Register'!C114,"") -> Enflow2 | D28: =IFERROR('Inward Register'!B114,"") -> 46269 | E28: =IFERROR('Inward Register'!F114,"") -> Pipe | F28: =IFERROR('Inward Register'!E114,"") -> Paras flow | G28: =IFERROR('Inward Register'!G114,"") -> Braded 13.5mm | H28: =IFERROR('Inward Register'!H114,"") -> 24 inch | I28: =IFERROR('Inward Register'!I114,"") -> 5 | J28: =IFERROR('Inward Register'!J114,"") -> Rolls | M28: =K28-L28 -> 0 | Q28: =IF(M28=0,"PASS","FAIL") -> PASS | R28: =AVERAGE(IF(L28=K28,1,0),IF(N28="PASS",1,0),IF(O28="PASS",1,0),IF(P28="PASS",1,0)) -> 0.25
A29: =IFERROR('Inward Register'!A115,"") -> 46293 | B29: =IFERROR('Inward Register'!M115,"") -> 46294 | C29: =IFERROR('Inward Register'!C115,"") -> 5M Moulding and Technologies | D29: =IFERROR('Inward Register'!B115,"") -> 5M-CM/0619/26-27 | E29: =IFERROR('Inward Register'!F115,"") -> Nutset | F29: =IFERROR('Inward Register'!E115,"") -> - | G29: =IFERROR('Inward Register'!G115,"") -> L-Round nut | H29: =IFERROR('Inward Register'!H115,"") -> 13mm | I29: =IFERROR('Inward Register'!I115,"") -> 50000 | J29: =IFERROR('Inward Register'!J115,"") -> Pcs | K29: 50 | L29: 50 | M29: =K29-L29 -> 0 | N29: PASS | O29: PASS | P29: PASS | Q29: =IF(M29=0,"PASS","FAIL") -> PASS | R29: =AVERAGE(IF(L29=K29,1,0),IF(N29="PASS",1,0),IF(O29="PASS",1,0),IF(P29="PASS",1,0)) -> 1
A30: =IFERROR('Inward Register'!A116,"") -> 46293 | B30: =IFERROR('Inward Register'!M116,"") -> 46294 | C30: =IFERROR('Inward Register'!C116,"") -> 5M Moulding and Technologies | D30: =IFERROR('Inward Register'!B116,"") -> 5M-CM/0619/26-27 | E30: =IFERROR('Inward Register'!F116,"") -> Nutset | F30: =IFERROR('Inward Register'!E116,"") -> - | G30: =IFERROR('Inward Register'!G116,"") -> M-Cap | H30: =IFERROR('Inward Register'!H116,"") -> 13.5mm | I30: =IFERROR('Inward Register'!I116,"") -> 180000 | J30: =IFERROR('Inward Register'!J116,"") -> Pcs | K30: 50 | L30: 50 | M30: =K30-L30 -> 0 | N30: PASS | O30: PASS | P30: PASS | Q30: =IF(M30=0,"PASS","FAIL") -> PASS | R30: =AVERAGE(IF(L30=K30,1,0),IF(N30="PASS",1,0),IF(O30="PASS",1,0),IF(P30="PASS",1,0)) -> 1
A31: =IFERROR('Inward Register'!A117,"") -> 46293 | B31: =IFERROR('Inward Register'!M117,"") -> 46294 | C31: =IFERROR('Inward Register'!C117,"") -> 5M Moulding and Technologies | D31: =IFERROR('Inward Register'!B117,"") -> 5M-CM/0619/26-27 | E31: =IFERROR('Inward Register'!F117,"") -> Nutset | F31: =IFERROR('Inward Register'!E117,"") -> - | G31: =IFERROR('Inward Register'!G117,"") -> Inner | H31: =IFERROR('Inward Register'!H117,"") | I31: =IFERROR('Inward Register'!I117,"") -> 500000 | J31: =IFERROR('Inward Register'!J117,"") -> Pcs | K31: 43 | L31: 42 | M31: =K31-L31 -> 1 | N31: FAIL | O31: PASS | P31: PASS | Q31: =IF(M31=0,"PASS","FAIL") -> FAIL | R31: =AVERAGE(IF(L31=K31,1,0),IF(N31="PASS",1,0),IF(O31="PASS",1,0),IF(P31="PASS",1,0)) -> 0.5
A32: =IFERROR('Inward Register'!A118,"") -> 46295 | B32: =IFERROR('Inward Register'!M118,"") | C32: =IFERROR('Inward Register'!C118,"") -> Enflow2 | D32: =IFERROR('Inward Register'!B118,"") -> 46270 | E32: =IFERROR('Inward Register'!F118,"") -> Pipe | F32: =IFERROR('Inward Register'!E118,"") -> CS | G32: =IFERROR('Inward Register'!G118,"") -> Non-Braded 13mm | H32: =IFERROR('Inward Register'!H118,"") -> 1mtr | I32: =IFERROR('Inward Register'!I118,"") -> 750 | J32: =IFERROR('Inward Register'!J118,"") -> Pcs | M32: =K32-L32 -> 0 | Q32: =IF(M32=0,"PASS","FAIL") -> PASS | R32: =AVERAGE(IF(L32=K32,1,0),IF(N32="PASS",1,0),IF(O32="PASS",1,0),IF(P32="PASS",1,0)) -> 0.25
A33: =IFERROR('Inward Register'!A119,"") -> 46295 | B33: =IFERROR('Inward Register'!M119,"") | C33: =IFERROR('Inward Register'!C119,"") -> Enflow2 | D33: =IFERROR('Inward Register'!B119,"") -> 46270 | E33: =IFERROR('Inward Register'!F119,"") -> Pipe | F33: =IFERROR('Inward Register'!E119,"") -> Enflow | G33: =IFERROR('Inward Register'!G119,"") -> Non-Braded 13mm | H33: =IFERROR('Inward Register'!H119,"") -> 24 inch | I33: =IFERROR('Inward Register'!I119,"") -> 500 | J33: =IFERROR('Inward Register'!J119,"") -> Pcs | M33: =K33-L33 -> 0 | Q33: =IF(M33=0,"PASS","FAIL") -> PASS | R33: =AVERAGE(IF(L33=K33,1,0),IF(N33="PASS",1,0),IF(O33="PASS",1,0),IF(P33="PASS",1,0)) -> 0.25
A34: =IFERROR('Inward Register'!A120,"") -> 46295 | B34: =IFERROR('Inward Register'!M120,"") | C34: =IFERROR('Inward Register'!C120,"") -> Enflow2 | D34: =IFERROR('Inward Register'!B120,"") -> 46270 | E34: =IFERROR('Inward Register'!F120,"") -> Pipe | F34: =IFERROR('Inward Register'!E120,"") -> Enflow | G34: =IFERROR('Inward Register'!G120,"") -> Non-Braded 13mm | H34: =IFERROR('Inward Register'!H120,"") -> 1mtr | I34: =IFERROR('Inward Register'!I120,"") -> 2000 | J34: =IFERROR('Inward Register'!J120,"") -> Pcs | M34: =K34-L34 -> 0 | Q34: =IF(M34=0,"PASS","FAIL") -> PASS | R34: =AVERAGE(IF(L34=K34,1,0),IF(N34="PASS",1,0),IF(O34="PASS",1,0),IF(P34="PASS",1,0)) -> 0.25
A35: =IFERROR('Inward Register'!A121,"") -> 46295 | B35: =IFERROR('Inward Register'!M121,"") | C35: =IFERROR('Inward Register'!C121,"") -> Enflow2 | D35: =IFERROR('Inward Register'!B121,"") -> 46270 | E35: =IFERROR('Inward Register'!F121,"") -> Pipe | F35: =IFERROR('Inward Register'!E121,"") -> Enflow | G35: =IFERROR('Inward Register'!G121,"") -> Non-Braded 13mm | H35: =IFERROR('Inward Register'!H121,"") -> 1.5mtr | I35: =IFERROR('Inward Register'!I121,"") -> 500 | J35: =IFERROR('Inward Register'!J121,"") -> Pcs | M35: =K35-L35 -> 0 | Q35: =IF(M35=0,"PASS","FAIL") -> PASS | R35: =AVERAGE(IF(L35=K35,1,0),IF(N35="PASS",1,0),IF(O35="PASS",1,0),IF(P35="PASS",1,0)) -> 0.25
A36: =IFERROR('Inward Register'!A122,"") -> 46295 | B36: =IFERROR('Inward Register'!M122,"") | C36: =IFERROR('Inward Register'!C122,"") -> Enflow2 | D36: =IFERROR('Inward Register'!B122,"") -> 46270 | E36: =IFERROR('Inward Register'!F122,"") -> Pipe | F36: =IFERROR('Inward Register'!E122,"") -> Enflow | G36: =IFERROR('Inward Register'!G122,"") -> Non-Braded 13mm | H36: =IFERROR('Inward Register'!H122,"") -> 2mtr | I36: =IFERROR('Inward Register'!I122,"") -> 500 | J36: =IFERROR('Inward Register'!J122,"") -> Pcs | M36: =K36-L36 -> 0 | Q36: =IF(M36=0,"PASS","FAIL") -> PASS | R36: =AVERAGE(IF(L36=K36,1,0),IF(N36="PASS",1,0),IF(O36="PASS",1,0),IF(P36="PASS",1,0)) -> 0.25
A37: =IFERROR('Inward Register'!A123,"") -> 46295 | B37: =IFERROR('Inward Register'!M123,"") | C37: =IFERROR('Inward Register'!C123,"") -> Enflow2 | D37: =IFERROR('Inward Register'!B123,"") -> 46270 | E37: =IFERROR('Inward Register'!F123,"") -> Pipe | F37: =IFERROR('Inward Register'!E123,"") -> Enflow | G37: =IFERROR('Inward Register'!G123,"") -> Non-Braded 13mm | H37: =IFERROR('Inward Register'!H123,"") -> 18 inch | I37: =IFERROR('Inward Register'!I123,"") -> 500 | J37: =IFERROR('Inward Register'!J123,"") -> Pcs | M37: =K37-L37 -> 0 | Q37: =IF(M37=0,"PASS","FAIL") -> PASS | R37: =AVERAGE(IF(L37=K37,1,0),IF(N37="PASS",1,0),IF(O37="PASS",1,0),IF(P37="PASS",1,0)) -> 0.25
A38: =IFERROR('Inward Register'!A124,"") -> 46295 | B38: =IFERROR('Inward Register'!M124,"") -> 46300 | C38: =IFERROR('Inward Register'!C124,"") -> Enflow2 | D38: =IFERROR('Inward Register'!B124,"") -> 46270 | E38: =IFERROR('Inward Register'!F124,"") -> Pipe | F38: =IFERROR('Inward Register'!E124,"") -> Waterflo | G38: =IFERROR('Inward Register'!G124,"") -> Braded 13.5mm | H38: =IFERROR('Inward Register'!H124,"") -> 18 inch | I38: =IFERROR('Inward Register'!I124,"") -> 4000 | J38: =IFERROR('Inward Register'!J124,"") -> Pcs | K38: 40 | L38: 35 | M38: =K38-L38 -> 5 | N38: PASS | O38: PASS | P38: FAIL | Q38: =IF(M38=0,"PASS","FAIL") -> FAIL | R38: =AVERAGE(IF(L38=K38,1,0),IF(N38="PASS",1,0),IF(O38="PASS",1,0),IF(P38="PASS",1,0)) -> 0.5 | S38: Some Pipes are getting cap tight
A39: =IFERROR('Inward Register'!A125,"") -> 46295 | B39: =IFERROR('Inward Register'!M125,"") -> 46296 | C39: =IFERROR('Inward Register'!C125,"") -> Enflow2 | D39: =IFERROR('Inward Register'!B125,"") -> 46270 | E39: =IFERROR('Inward Register'!F125,"") -> Pipe | F39: =IFERROR('Inward Register'!E125,"") -> Waterflo | G39: =IFERROR('Inward Register'!G125,"") -> Braded 13.5mm | H39: =IFERROR('Inward Register'!H125,"") -> 24 inch | I39: =IFERROR('Inward Register'!I125,"") -> 9960 | J39: =IFERROR('Inward Register'!J125,"") -> Pcs | K39: 50 | L39: 40 | M39: =K39-L39 -> 10 | N39: FAIL | O39: PASS | P39: FAIL | Q39: =IF(M39=0,"PASS","FAIL") -> FAIL | R39: =AVERAGE(IF(L39=K39,1,0),IF(N39="PASS",1,0),IF(O39="PASS",1,0),IF(P39="PASS",1,0)) -> 0.25 | S39: Some Pipes are getting cap tight
A40: =IFERROR('Inward Register'!A126,"") -> 46295 | B40: =IFERROR('Inward Register'!M126,"") -> 46298 | C40: =IFERROR('Inward Register'!C126,"") -> Enflow2 | D40: =IFERROR('Inward Register'!B126,"") -> 46270 | E40: =IFERROR('Inward Register'!F126,"") -> Pipe | F40: =IFERROR('Inward Register'!E126,"") -> Waterflo | G40: =IFERROR('Inward Register'!G126,"") -> Braded 13.5mm | H40: =IFERROR('Inward Register'!H126,"") -> 1mtr | I40: =IFERROR('Inward Register'!I126,"") -> 2000 | J40: =IFERROR('Inward Register'!J126,"") -> Pcs | K40: 50 | L40: 40 | M40: =K40-L40 -> 10 | N40: FAIL | O40: PASS | P40: PASS | Q40: =IF(M40=0,"PASS","FAIL") -> FAIL | R40: =AVERAGE(IF(L40=K40,1,0),IF(N40="PASS",1,0),IF(O40="PASS",1,0),IF(P40="PASS",1,0)) -> 0.5 | S40: Some Pipes are getting cap tight
A41: =IFERROR('Inward Register'!A127,"") -> 46296 | B41: =IFERROR('Inward Register'!M127,"") -> 46300 | C41: =IFERROR('Inward Register'!C127,"") -> Sri Tex Engineers | D41: =IFERROR('Inward Register'!B127,"") -> 46296 | E41: =IFERROR('Inward Register'!F127,"") -> Nutset | F41: =IFERROR('Inward Register'!E127,"") -> - | G41: =IFERROR('Inward Register'!G127,"") -> L-Cap | H41: =IFERROR('Inward Register'!H127,"") -> 13mm | I41: =IFERROR('Inward Register'!I127,"") -> 100000 | J41: =IFERROR('Inward Register'!J127,"") -> Pcs | M41: =K41-L41 -> 0 | N41: PASS | O41: PASS | P41: PASS | Q41: =IF(M41=0,"PASS","FAIL") -> PASS | R41: =AVERAGE(IF(L41=K41,1,0),IF(N41="PASS",1,0),IF(O41="PASS",1,0),IF(P41="PASS",1,0)) -> 1

Sheet Data
A2: Vender | B2: Product | C2: Product type | D2: Size | E2: UOM
A3: 5M Moulding and Technologies | B3: Nutset | C3: Braded 13.5mm | D3: 12 inch | E3: Kgs
A4: Punith packaging | B4: Cover | C4: Non-Braded 13mm | D4: 18 inch | E4: Rolls
A5: Mak flexible | B5: Pipe | C5: Nutset | D5: 24 inch | E5: Pcs
A6: Enflow2 | B6: Tread | C6: L-Round nut | D6: 30 inch | E6: Bags
A7: Technotube | B7: Washer | C7: L-Hex nut | D7: 36 inch
A8: Gp flex | B8: Poly bags | C8: L-Key | D8: 1mtr
A9: Niar and sons | B9: Label | C9: L-Cap | D9: 1.5mtr
A10: Eva rubber | B10: Inner | C10: Inner | D10: 2mtr
A11: Polt sack | C11: M-Round nut
A12: Kolorkode | C12: M-Hex nut | D12: 13mm
A13: Holosucrity | C13: M-Key | D13: 13.5mm
A14: Sri Tex Engineers | C14: M-Cap | D14: 3x21
C15: Label | D15: 3x26
C16: Cover | D16: 8x10
C17: Washer
