Workbook

Sheet Dashboard
A1: FINISHED GOODS OUTWARD INSPECTION
A3: Category | B3: Entries | C3: Outward Qty | D3: Items Checked | E3: Un checked | G3: Result | H3: Count
A4: Connection pipe with label | B4: =COUNTIF(Table1[Product],"Connection pipe with label") -> 12 | C4: =IF(A4="","",SUMIF(Table1[Product],A4,Table1[Packed qty])) -> 88585 | D4: =COUNTIFS(Table1[Product],"Connection pipe with label",Table1[QC check],"TRUE") -> 9 | E4: =COUNTIFS(Table1[Product],"Connection pipe with label",Table1[QC check],"FALSE") -> 3
A5: Connection pipe with cover | B5: =COUNTIF(Table1[Product],"Connection pipe with cover") -> 5 | C5: =IF(A5="","",SUMIF(Table1[Product],A5,Table1[Packed qty])) -> 4898 | D5: =COUNTIFS(Table1[Product],"Connection pipe with cover",Table1[QC check],"TRUE") -> 5 | E5: =COUNTIFS(Table1[Product],"Connection pipe with cover",Table1[QC check],"FALSE") -> 0
A6: Connection pipe with nut | B6: =COUNTIF(Table1[Product],"Connection pipe with nut") -> 10 | C6: =IF(A6="","",SUMIF(Table1[Product],A6,Table1[Packed qty])) -> 71911 | D6: =COUNTIFS(Table1[Product],"Connection pipe with nut",Table1[QC check],"TRUE") -> 10 | E6: =COUNTIFS(Table1[Product],"Connection pipe with nut",Table1[QC check],"FALSE") -> 0
A7: Connection pipe | B7: =COUNTIF(Table1[Product],"Connection pipe") -> 7 | C7: =IF(A7="","",SUMIF(Table1[Product],A7,Table1[Packed qty])) -> 8455 | D7: =COUNTIFS(Table1[Product],"Connection pipe",Table1[QC check],"TRUE") -> 7 | E7: =COUNTIFS(Table1[Product],"Connection pipe",Table1[QC check],"FALSE") -> 0
A8: Nutset | B8: =COUNTIF(Table1[Product],"Nutset") -> 20 | C8: =IF(A8="","",SUMIF(Table1[Product],A8,Table1[Packed qty])) -> 253924 | D8: =COUNTIFS(Table1[Product],"Nutset",Table1[QC check],"TRUE") -> 15 | E8: =COUNTIFS(Table1[Product],"Nutset",Table1[QC check],"FALSE") -> 5
A10: Total | B10: =sum(B4:B9) -> 54 | C10: =sum(C4:C9) -> 427773
A43: MATERIAL OUTWARD & DISPATCH QC DASHBOARD
A45: Total Dispatch Entries | B45: =COUNTA('Finished Goods Outward'!B3:B102) -> 1
A46: Approved Dispatches | B46: =COUNTIF('Finished Goods Outward'!K3:K102,"APPROVED") -> #REF! | E46: On Hold | F46: =COUNTIF('Finished Goods Outward'!K3:K102,"HOLD") -> #REF! | I46: On REJECTED | J46: =COUNTIF('Finished Goods Outward'!K3:K102,"REJECTED") -> #REF!
A47: Total Quantity Dispatched Cp | B47: =SUMIFS('Finished Goods Outward'!H:H,'Finished Goods Outward'!E:E,"CP",'Finished Goods Outward'!K:K,"APPROVED") -> #N/A | E47: Total Quantity Dispatched Cp | F47: =SUMIFS('Finished Goods Outward'!H:H,'Finished Goods Outward'!E:E,"CP",'Finished Goods Outward'!K:K,"HOLD") -> #N/A | I47: Total Quantity Dispatched Cp | J47: =SUMIFS('Finished Goods Outward'!H:H,'Finished Goods Outward'!E:E,"CP",'Finished Goods Outward'!K:K,"REJECTED") -> #N/A
A48: Total Quantity Dispatched Pipe rolls | B48: =SUMIFS('Finished Goods Outward'!H:H,'Finished Goods Outward'!E:E,"Pipe rolls",'Finished Goods Outward'!K:K,"APPROVED") -> #N/A | E48: Total Quantity Dispatched Pipe rolls | F48: =SUMIFS('Finished Goods Outward'!H:H,'Finished Goods Outward'!E:E,"Pipe rolls",'Finished Goods Outward'!K:K,"HOLD") -> #N/A | I48: Total Quantity Dispatched Pipe rolls | J48: =SUMIFS('Finished Goods Outward'!H:H,'Finished Goods Outward'!E:E,"Pipe rolls",'Finished Goods Outward'!K:K,"REJECTED") -> #N/A
A49: Total Quantity Dispatched Pipe in pcs | B49: =SUMIFS('Finished Goods Outward'!H:H,'Finished Goods Outward'!E:E,"Pipe in pcs",'Finished Goods Outward'!K:K,"APPROVED") -> #N/A | E49: Total Quantity Dispatched Pipe in pcs | F49: =SUMIFS('Finished Goods Outward'!H:H,'Finished Goods Outward'!E:E,"Pipe in pcs",'Finished Goods Outward'!K:K,"HOLD") -> #N/A | I49: Total Quantity Dispatched Pipe in pcs | J49: =SUMIFS('Finished Goods Outward'!H:H,'Finished Goods Outward'!E:E,"Pipe in pcs",'Finished Goods Outward'!K:K,"REJECTED") -> #N/A
A50: Total Quantity Dispatched Nut set | B50: =SUMIFS('Finished Goods Outward'!H:H,'Finished Goods Outward'!E:E,"Nut set",'Finished Goods Outward'!K:K,"APPROVED") -> #N/A | E50: Total Quantity Dispatched Nut set | F50: =SUMIFS('Finished Goods Outward'!H:H,'Finished Goods Outward'!E:E,"Nut set",'Finished Goods Outward'!K:K,"HOLD") -> #N/A | I50: Total Quantity Dispatched Nut set | J50: =SUMIFS('Finished Goods Outward'!H:H,'Finished Goods Outward'!E:E,"Nut set",'Finished Goods Outward'!K:K,"REJECTED") -> #N/A

Sheet Finished Goods Outward
A1: Date | B1: Customer name | C1: Brand | D1: Invoice no | E1: Product | F1: Product type | G1: Size | H1: Packed qty | I1: Unit (Pcs/Kgs) | J1: Packing | K1: QC check | L1: Weight check | M1: Dispatched | N1: Dispatched Date | O1: Dispatched days | P1: Dispatched Qty | Q1: Yet to Dispatched | R1: No. bags | S1: Column 19 | T1: Transporter | U1: Vehicle No. | V1: Remark
A2: 46234 | B2: JJ Marketing | D2: INV-0720 | E2: Nutset | F2: L-Round nut, L-Hex nut | G2: 13mm | H2: 10000 | I2: Set | J2: TRUE | K2: TRUE | L2: FALSE | M2: TRUE | N2: 46239 | O2: =IF(A2="","",IF(N2="",TODAY()-A2,N2-A2)) -> 5 | P2: 10000 | Q2: =max(Table1[Packed qty]-Table1[Dispatched Qty],0) -> 0 | R2: 5 | S2: Bags | U2: KA01AF1037
A3: 46237 | B3: Alpha Sanitary | D3: INV-0718 | E3: Nutset | F3: L-Hex nut | G3: 13mm | H3: 2000 | I3: Set | J3: TRUE | K3: TRUE | L3: TRUE | M3: TRUE | N3: 46239 | O3: =IF(A3="","",IF(N3="",TODAY()-A3,N3-A3)) -> 2 | P3: 2000 | Q3: =max(Table1[Packed qty]-Table1[Dispatched Qty],0) -> 0 | R3: 1 | S3: Bags | T3: VRL Attibele | U3: KA01AF1037
A4: 46237 | B4: EZIYFLO POLYPLAST INDUSTRIES | D4: INV-0721 | E4: Nutset | F4: Washer | H4: 20000 | I4: Pcs | J4: TRUE | K4: TRUE | L4: FALSE | M4: TRUE | N4: 46239 | O4: =IF(A4="","",IF(N4="",TODAY()-A4,N4-A4)) -> 2 | P4: 20000 | Q4: =max(Table1[Packed qty]-Table1[Dispatched Qty],0) -> 0 | R4: 1 | S4: Bags | U4: KA01AF1037
A5: 46225 | B5: Aura industries | D5: INV-0722 | E5: Connection pipe with label | F5: Braded 13.5mm | G5: 18 inch, 24 inch, 1mtr, 1.5mtr | H5: 27373 | I5: Pcs | J5: TRUE | K5: TRUE | L5: TRUE | M5: TRUE | N5: 46244 | O5: =IF(A5="","",IF(N5="",TODAY()-A5,N5-A5)) -> 19 | P5: 27373 | Q5: =max(Table1[Packed qty]-Table1[Dispatched Qty],0) -> 0 | R5: 96 | S5: Bags | U5: GJ03BV9118
A6: 46225 | B6: Aura industries | D6: INV-0723 | E6: Connection pipe with nut | F6: Non-Braded 13mm | G6: 1mtr, 1.5mtr | H6: 10675 | I6: Pcs | J6: TRUE | K6: TRUE | L6: TRUE | M6: TRUE | N6: 46244 | O6: =IF(A6="","",IF(N6="",TODAY()-A6,N6-A6)) -> 19 | P6: 10675 | Q6: =max(Table1[Packed qty]-Table1[Dispatched Qty],0) -> 0 | R6: 21 | S6: Bags | U6: GJ03BV9118
B7: Vojal engineering | D7: INV-0719 | E7: Nutset | H7: 2204 | I7: Pcs | J7: FALSE | K7: FALSE | L7: FALSE | M7: FALSE | N7: 46247 | O7: =IF(A7="","",IF(N7="",TODAY()-A7,N7-A7)) | P7: 2204 | Q7: =max(Table1[Packed qty]-Table1[Dispatched Qty],0) -> 0 | R7: 10 | S7: Bags | T7: VRL Attibele | U7: KA51C6596
B8: Schintler Glassware Pvt Ltd | D8: INV-0724 | E8: Nutset | H8: 10720 | I8: Pcs | J8: FALSE | K8: FALSE | L8: FALSE | M8: FALSE | N8: 46254 | O8: =IF(A8="","",IF(N8="",TODAY()-A8,N8-A8)) | P8: 10720 | Q8: =max(Table1[Packed qty]-Table1[Dispatched Qty],0) -> 0 | R8: 23 | S8: Bags | U8: KL17Y9957
B9: MAHALAKSHMI ENTERPRISES | D9: INV-0725 | E9: Connection pipe with label | H9: 1600 | I9: Pcs | J9: FALSE | K9: FALSE | L9: FALSE | M9: FALSE | N9: 46255 | O9: =IF(A9="","",IF(N9="",TODAY()-A9,N9-A9)) | P9: 1600 | Q9: =max(Table1[Packed qty]-Table1[Dispatched Qty],0) -> 0 | R9: 7 | S9: Bags | U9: KA01AF1037
B10: ZERA COATS | D10: INV-0726 | E10: Nutset | H10: 26000 | I10: Set | J10: FALSE | K10: FALSE | L10: FALSE | M10: FALSE | N10: 46255 | O10: =IF(A10="","",IF(N10="",TODAY()-A10,N10-A10)) | P10: 26000 | Q10: =max(Table1[Packed qty]-Table1[Dispatched Qty],0) -> 0 | R10: 13 | S10: Bags | U10: KA01AF1037
B11: Mathaji electrical hardware | D11: INV-0728 | E11: Connection pipe with label | H11: 1500 | I11: Pcs | J11: FALSE | K11: FALSE | L11: FALSE | M11: FALSE | N11: 46259 | O11: =IF(A11="","",IF(N11="",TODAY()-A11,N11-A11)) | P11: 1500 | Q11: =max(Table1[Packed qty]-Table1[Dispatched Qty],0) -> 0 | R11: 8 | S11: Bags | U11: KA51AG3979
B12: Sri Ashapura Industries | D12: INV-0730 | E12: Nutset | H12: 50000 | I12: Set | J12: FALSE | K12: FALSE | L12: FALSE | M12: FALSE | N12: 46261 | O12: =IF(A12="","",IF(N12="",TODAY()-A12,N12-A12)) | P12: 50000 | Q12: =max(Table1[Packed qty]-Table1[Dispatched Qty],0) -> 0 | R12: 25 | S12: Bags | U12: KA05AL3733
B13: Bharuchi Industries | D13: INV-0729 | E13: Nutset | H13: 5000 | I13: Set | J13: FALSE | K13: FALSE | L13: FALSE | M13: FALSE | N13: 46261 | O13: =IF(A13="","",IF(N13="",TODAY()-A13,N13-A13)) | P13: 5000 | Q13: =max(Table1[Packed qty]-Table1[Dispatched Qty],0) -> 0 | R13: 3 | S13: Bags | U13: KA01AF1037
B14: SK Trader | D14: INV-0731 | E14: Connection pipe with label | H14: 580 | I14: Pcs | J14: FALSE | K14: FALSE | L14: FALSE | M14: FALSE | N14: 46262 | O14: =IF(A14="","",IF(N14="",TODAY()-A14,N14-A14)) | P14: 580 | Q14: =max(Table1[Packed qty]-Table1[Dispatched Qty],0) -> 0 | R14: 2 | S14: Bags | T14: -
A15: 46244 | B15: IDOL PLASTO PRIVATE LIMITED | C15: Idol | D15: INV-0732 | E15: Connection pipe with label | F15: Non-Braded 13mm | G15: 30 inch, 36 inch | H15: 10102 | I15: Pcs | J15: TRUE | K15: TRUE | L15: TRUE | M15: TRUE | N15: 46267 | O15: =IF(A15="","",IF(N15="",TODAY()-A15,N15-A15)) -> 23 | P15: 10102 | Q15: =max(Table1[Packed qty]-Table1[Dispatched Qty],0) -> 0 | R15: 51 | S15: Bags | U15: KA02AH9326
A16: 46261 | B16: CS WATER TAP | C16: CS Watertap | D16: INV-0734 | E16: Connection pipe with label | F16: Non-Braded 13mm | G16: 1mtr | H16: 2400 | I16: Pcs | J16: TRUE | K16: TRUE | L16: TRUE | M16: TRUE | N16: 46270 | O16: =IF(A16="","",IF(N16="",TODAY()-A16,N16-A16)) -> 9 | P16: 2400 | Q16: =max(Table1[Packed qty]-Table1[Dispatched Qty],0) -> 0 | R16: 8 | S16: Bags | U16: KA51AG6880
A17: 46261 | B17: SK Trader | C17: Enflow | D17: INV-0732 | E17: Connection pipe with label | F17: Non-Braded 13mm | G17: 24 inch, 1mtr, 2mtr | H17: 4100 | I17: Pcs | J17: TRUE | K17: TRUE | L17: FALSE | M17: TRUE | N17: 46272 | O17: =IF(A17="","",IF(N17="",TODAY()-A17,N17-A17)) -> 11 | P17: 4100 | Q17: =max(Table1[Packed qty]-Table1[Dispatched Qty],0) -> 0 | R17: 10 | S17: Bags | U17: KA01AF1037 | V17: Previous 18" 50pcs sent
A18: 46265 | B18: Hari Enterprises | C18: Enflow | D18: INV-0735 | E18: Connection pipe with label | F18: Non-Braded 13mm | G18: 18 inch, 24 inch, 1mtr, 1.5mtr, 2mtr | H18: 1000 | I18: Pcs | J18: TRUE | K18: TRUE | L18: FALSE | M18: TRUE | N18: 46272 | O18: =IF(A18="","",IF(N18="",TODAY()-A18,N18-A18)) -> 7 | P18: 1000 | Q18: =max(Table1[Packed qty]-Table1[Dispatched Qty],0) -> 0 | R18: 5 | S18: Bags | U18: KA01AF1037
A19: 46265 | B19: Alpha Sanitary | D19: INV-0736 | E19: Connection pipe | F19: Non-Braded 13mm | G19: 24 inch | H19: 500 | I19: Pcs | J19: TRUE | K19: TRUE | L19: TRUE | M19: TRUE | N19: 46273 | O19: =IF(A19="","",IF(N19="",TODAY()-A19,N19-A19)) -> 8 | P19: 500 | Q19: =max(Table1[Packed qty]-Table1[Dispatched Qty],0) -> 0 | R19: 1 | S19: Bags | T19: VRL Attibele | U19: KA01AF1037
A20: 46265 | B20: Alpha Sanitary | D20: INV-0736 | E20: Connection pipe | F20: Braded 13.5mm | G20: 24 inch | H20: 500 | I20: Pcs | J20: TRUE | K20: TRUE | L20: TRUE | M20: TRUE | N20: 46273 | O20: =IF(A20="","",IF(N20="",TODAY()-A20,N20-A20)) -> 8 | P20: 500 | Q20: =max(Table1[Packed qty]-Table1[Dispatched Qty],0) -> 0 | R20: 1 | S20: Bags | T20: VRL Attibele | U20: KA01AF1037
A21: 46269 | B21: Alpha Sanitary | C21: Misri superior | D21: INV-0736 | E21: Connection pipe | F21: Non-Braded 13mm | G21: 24 inch | H21: 500 | I21: Pcs | J21: TRUE | K21: TRUE | L21: TRUE | M21: TRUE | N21: 46273 | O21: =IF(A21="","",IF(N21="",TODAY()-A21,N21-A21)) -> 4 | P21: 500 | Q21: =max(Table1[Packed qty]-Table1[Dispatched Qty],0) -> 0 | R21: 1 | S21: Bags | T21: VRL Attibele | U21: KA01AF1037
A22: 46265 | B22: Alpha Sanitary | C22: - | D22: INV-0736 | E22: Nutset | F22: M-Hex nut | G22: 13.5mm | H22: 1000 | I22: Set | J22: TRUE | K22: TRUE | L22: FALSE | M22: TRUE | N22: 46273 | O22: =IF(A22="","",IF(N22="",TODAY()-A22,N22-A22)) -> 8 | P22: 1000 | Q22: =max(Table1[Packed qty]-Table1[Dispatched Qty],0) -> 0 | R22: 1 | S22: Bags | T22: VRL Attibele | U22: KA01AF1037
A23: 46254 | B23: Vojal | C23: Vojal, Artimis | D23: INV-0738 | E23: Connection pipe with nut | F23: Non-Braded 13mm | G23: 12 inch, 18 inch, 24 inch, 1mtr, 1.5mtr | H23: 2315 | I23: Pcs | J23: TRUE | K23: TRUE | L23: TRUE | M23: TRUE | N23: 46273 | O23: =IF(A23="","",IF(N23="",TODAY()-A23,N23-A23)) -> 19 | P23: 2315 | Q23: =max(Table1[Packed qty]-Table1[Dispatched Qty],0) -> 0 | R23: 8 | S23: Bags
A24: 46272 | B24: EZIYFLO POLYPLAST INDUSTRIES | C24: - | D24: INV-0739 | E24: Nutset | F24: Washer | H24: 20000 | I24: Pcs | J24: TRUE | K24: TRUE | L24: FALSE | M24: TRUE | N24: 46273 | O24: =IF(A24="","",IF(N24="",TODAY()-A24,N24-A24)) -> 1 | P24: 20000 | Q24: =max(Table1[Packed qty]-Table1[Dispatched Qty],0) -> 0 | R24: 1 | S24: Bags
A25: 46254 | B25: SHRI SAI SAMARTH ENTERPRISES | C25: SSS | D25: INV-0737 | E25: Connection pipe | F25: Non-Braded 13mm | G25: 24 inch, 1mtr | H25: 2350 | I25: Pcs | J25: TRUE | K25: TRUE | L25: TRUE | M25: TRUE | N25: 46273 | O25: =IF(A25="","",IF(N25="",TODAY()-A25,N25-A25)) -> 19 | P25: 2350 | Q25: =max(Table1[Packed qty]-Table1[Dispatched Qty],0) -> 0 | R25: 5 | S25: Bags
A26: 46251 | B26: Schintler Glassware Pvt Ltd | C26: Schintler | D26: INV-0740 | E26: Connection pipe with nut | F26: Non-Braded 13mm | G26: 18 inch, 24 inch | H26: 9345 | I26: Pcs | J26: TRUE | K26: TRUE | L26: TRUE | M26: TRUE | N26: 46274 | O26: =IF(A26="","",IF(N26="",TODAY()-A26,N26-A26)) -> 23 | P26: 9345 | Q26: =max(Table1[Packed qty]-Table1[Dispatched Qty],0) -> 0 | R26: 19 | S26: Bags | T26: Kerala Roadways | U26: KA01AF1037
B27: Schintler Glassware Pvt Ltd | C27: Schintler | D27: INV-0760 | E27: Connection pipe with nut | F27: Non-Braded 13mm | G27: 1mtr | H27: 1400 | I27: Pcs | J27: TRUE | K27: TRUE | L27: TRUE | M27: TRUE | N27: 46274 | O27: =IF(A27="","",IF(N27="",TODAY()-A27,N27-A27)) | P27: 1400 | Q27: =max(Table1[Packed qty]-Table1[Dispatched Qty],0) -> 0 | R27: 7 | S27: Bags | T27: Kerala Roadways | U27: KA01AF1037 | V27: Rework
A28: 46277 | B28: Laxmi Metaplast Industries | C28: - | D28: INV-0741 | E28: Nutset | F28: L-Hex nut | G28: 13mm | H28: 6000 | I28: Set | J28: TRUE | K28: TRUE | L28: FALSE | M28: TRUE | N28: 46281 | O28: =IF(A28="","",IF(N28="",TODAY()-A28,N28-A28)) -> 4 | P28: 6000 | Q28: =max(Table1[Packed qty]-Table1[Dispatched Qty],0) -> 0 | R28: 3 | S28: Bags
A29: 46275 | B29: ZERA COATS | C29: - | D29: INV-0742 | E29: Nutset | F29: M-Hex nut | G29: 13.5mm | H29: 2000 | I29: Set | J29: TRUE | K29: TRUE | L29: FALSE | M29: TRUE | N29: 46281 | O29: =IF(A29="","",IF(N29="",TODAY()-A29,N29-A29)) -> 6 | P29: 2000 | Q29: =max(Table1[Packed qty]-Table1[Dispatched Qty],0) -> 0 | R29: 1 | S29: Bags | T29: VRL Attibele
A30: 46275 | B30: ZERA COATS | C30: Bluemount | D30: INV-0742 | E30: Connection pipe | F30: Braded 13.5mm | G30: 18 inch, 24 inch | H30: 2000 | I30: Pcs | J30: TRUE | K30: TRUE | L30: FALSE | M30: TRUE | N30: 46281 | O30: =IF(A30="","",IF(N30="",TODAY()-A30,N30-A30)) -> 6 | P30: 2000 | Q30: =max(Table1[Packed qty]-Table1[Dispatched Qty],0) -> 0 | R30: 4 | S30: Bags | T30: VRL Attibele
A31: 46251 | B31: Aura industries | C31: Waterflo, Marino | D31: INV-0743 | E31: Connection pipe with label | F31: Braded 13.5mm | G31: 18 inch, 24 inch, 1mtr, 1.5mtr, 2mtr | H31: 29530 | I31: Pcs | J31: TRUE | K31: TRUE | L31: TRUE | M31: TRUE | N31: 46281 | O31: =IF(A31="","",IF(N31="",TODAY()-A31,N31-A31)) -> 30 | P31: 29530 | Q31: =max(Table1[Packed qty]-Table1[Dispatched Qty],0) -> 0 | R31: 104 | S31: Bags | T31: - | U31: GJ03CU8508
A32: 46251 | B32: Aura industries | C32: Waterflo, Marino, Plain | D32: INV-0744 | E32: Connection pipe with nut | F32: Non-Braded 13mm | G32: 1mtr, 1.5mtr | H32: 17104 | I32: Pcs | J32: TRUE | K32: TRUE | L32: TRUE | M32: TRUE | N32: 46281 | O32: =IF(A32="","",IF(N32="",TODAY()-A32,N32-A32)) -> 30 | P32: 17104 | Q32: =max(Table1[Packed qty]-Table1[Dispatched Qty],0) -> 0 | R32: 62 | S32: Bags | T32: - | U32: GJ03CU8508
A33: 46261 | B33: CS WATER TAP | C33: CS Watertap | D33: INV-0745 | E33: Connection pipe with nut | F33: Non-Braded 13mm | G33: 24 inch | H33: 5850 | I33: Pcs | J33: TRUE | K33: TRUE | L33: TRUE | M33: TRUE | N33: 46282 | O33: =IF(A33="","",IF(N33="",TODAY()-A33,N33-A33)) -> 21 | P33: 5850 | Q33: =max(Table1[Packed qty]-Table1[Dispatched Qty],0) -> 0 | R33: 12 | S33: Bags | T33: Porter | U33: KA01AB7118
A34: 46282 | B34: Gupta sales corporation | C34: - | D34: INV-0746 | E34: Nutset | F34: L-Round nut | G34: 13mm | H34: 10000 | I34: Set | J34: TRUE | K34: TRUE | L34: FALSE | M34: TRUE | N34: 46284 | O34: =IF(A34="","",IF(N34="",TODAY()-A34,N34-A34)) -> 2 | P34: 10000 | Q34: =max(Table1[Packed qty]-Table1[Dispatched Qty],0) -> 0 | R34: 5 | S34: Bags | T34: VRL Attibele | U34: KA51C6596
A35: 46282 | B35: Gupta sales corporation | C35: - | D35: INV-0746 | E35: Nutset | F35: L-Hex nut | G35: 13mm | H35: 10000 | I35: Set | J35: TRUE | K35: TRUE | L35: FALSE | M35: TRUE | N35: 46284 | O35: =IF(A35="","",IF(N35="",TODAY()-A35,N35-A35)) -> 2 | P35: 10000 | Q35: =max(Table1[Packed qty]-Table1[Dispatched Qty],0) -> 0 | R35: 3 | S35: Bags | T35: VRL Attibele | U35: KA51C6596
A36: 46281 | B36: PIPEART BATHWARE | C36: - | D36: INV-0747 | E36: Nutset | F36: L-Hex nut | G36: 13mm | H36: 5000 | I36: Set | J36: TRUE | K36: TRUE | L36: FALSE | M36: TRUE | N36: 46284 | O36: =IF(A36="","",IF(N36="",TODAY()-A36,N36-A36)) -> 3 | P36: 5000 | Q36: =max(Table1[Packed qty]-Table1[Dispatched Qty],0) -> 0 | R36: 3 | S36: Bags | T36: VRL Attibele | U36: KA51C6596
A37: 46281 | B37: Shri Ambika Plast | C37: Enflow | D37: INV-0748 | E37: Connection pipe with cover | F37: Non-Braded 13mm | G37: 18 inch, 24 inch, 1mtr, 1.5mtr, 2mtr, 3mtr | H37: 310 | I37: Pcs | J37: TRUE | K37: TRUE | L37: TRUE | M37: TRUE | N37: 46286 | O37: =IF(A37="","",IF(N37="",TODAY()-A37,N37-A37)) -> 5 | P37: 310 | Q37: =max(Table1[Packed qty]-Table1[Dispatched Qty],0) -> 0 | R37: 2 | S37: Bags | T37: Porter | U37: -
A38: 46261 | B38: SK Trader | C38: Enflow | D38: INV-0732 | E38: Connection pipe with label | F38: Non-Braded 13mm | G38: 24 inch, 1mtr | H38: 1000 | I38: Pcs | J38: TRUE | K38: TRUE | L38: TRUE | M38: TRUE | N38: 46287 | O38: =IF(A38="","",IF(N38="",TODAY()-A38,N38-A38)) -> 26 | P38: 1000 | Q38: =max(Table1[Packed qty]-Table1[Dispatched Qty],0) -> 0 | R38: 4 | S38: Bags | T38: - | U38: - | V38: 51 kgs
A39: 46282 | B39: Futura Kitchen Sinks India Pvt Ltd | C39: Futura | D39: INV-0749 | E39: Connection pipe with nut | F39: Non-Braded 13mm | G39: 18 inch, 36 inch | H39: 3021 | I39: Pcs | J39: TRUE | K39: TRUE | L39: TRUE | M39: TRUE | N39: 46287 | O39: =IF(A39="","",IF(N39="",TODAY()-A39,N39-A39)) -> 5 | P39: 3021 | Q39: =max(Table1[Packed qty]-Table1[Dispatched Qty],0) -> 0 | R39: 7 | S39: Bags | T39: - | U39: KA51C6596
A40: 46276 | B40: Vojal engineering | C40: Vojal | D40: INV-0753 | E40: Connection pipe with nut | F40: Non-Braded 13mm | G40: 18 inch, 24 inch, 1mtr, 1.5mtr, 2mtr | H40: 2107 | I40: Pcs | J40: TRUE | K40: TRUE | L40: TRUE | M40: TRUE | N40: 46288 | O40: =IF(A40="","",IF(N40="",TODAY()-A40,N40-A40)) -> 12 | P40: 2107 | Q40: =max(Table1[Packed qty]-Table1[Dispatched Qty],0) -> 0 | R40: 8 | S40: Bags | T40: VRL Attibele | U40: KA51C6596
...

Sheet Data
A1: Customer | B1: Product | C1: Product type | D1: Size | E1: UOM | F1: Transporter
B2: Connection pipe with label | C2: Braded 13.5mm | D2: 12 inch | E2: Kgs | F2: VRL Attibele
B3: Connection pipe with cover | C3: Non-Braded 13mm | D3: 18 inch | E3: Rolls | F3: Porter
B4: Connection pipe with nut | C4: Nutset | D4: 24 inch | E4: Pcs | F4: -
B5: Connection pipe | C5: L-Round nut | D5: 30 inch | E5: Bags | F5: Kerala Roadways
B6: Nutset | C6: L-Hex nut | D6: 36 inch | E6: Set
C7: L-Key | D7: 40 inch
C8: L-Cap | D8: 1mtr
C9: Inner | D9: 1.5mtr
C10: M-Round nut | D10: 2mtr
C11: M-Hex nut | D11: 3mtr
C12: M-Key | D12: 13mm
C13: M-Cap | D13: 13.5mm
C14: Label | D14: 3x21
C15: Cover | D15: 3x26
C16: Washer | D16: 8x10
